Workbook

Sheet 사업비 구분(안)
A1: 이설, 복합시설 구분
F4: (면적단위: M2)
A5: 구 분 | B5: 이설 | D5: 복합시설 | E5: 계 | F5: 비고
B6: 본관동 | C6: 연립사택
A7: 연면적 | B7: ='도초초 이설 소요예상액'!G33 -> 2444.4 | C7: ='도초초 이설 소요예상액'!G35 -> 1100 | D7: ='도초초 이설 소요예상액'!G48 -> 2951.2 | E7: =B7+D7 -> 5395.6
A8: 건축면적 | B8: =B7/2 -> 1222.2 | C8: =C7/3 -> 366.66667 | D8: =D7/3 -> 983.73333 | E8: =B8+D8 -> 2205.9333 | F8: 이설: 2층, 연립사택: 3층 복합시설: 3층
A9: 비율 | B9: =(B7+C7)/(B7+C7+D7) -> 0.54566168 | D9: =D7/(D7+C7+B7) -> 0.45433832
F12: (면적단위: M2)
A13: 구 분 | B13: 이설 | C13: 연립사택 | D13: 복합시설 | E13: 계 | F13: 비고
A14: 건축공사비 | B14: ='도초초 이설 소요예상액'!I33 -> 7134696 | C14: ='도초초 이설 소요예상액'!I35 -> 3928125 | D14: ='도초초 이설 소요예상액'!I48 -> 11405714 | E14: =B14+C14+D14 -> 22468535
A15: 기타시설비 | B15: ='도초초 이설 소요예상액'!I61 -> 2166501.1 | D15: ='도초초 이설 소요예상액'!I65 -> 727527 | E15: =B15+D15 -> 2894028.1
A16: 토목공사비 | B16: ='도초초 이설 소요예상액'!I74 -> 2643544.1 | D16: ='도초초 이설 소요예상액'!I76 -> 462500 | E16: =B16+C16+D16 -> 3106044.1
A17: 용역비 | B17: ='도초초 이설 소요예상액'!I90*B9 -> 2244568.6 | D17: ='도초초 이설 소요예상액'!I90*D9 -> 1868911.7 | E17: =B17+D17 -> 4113480.3
A18: 부대비 | B18: ='도초초 이설 소요예상액'!I92*B9 -> 35728.724 | D18: ='도초초 이설 소요예상액'!I92*D9 -> 29749.072 | E18: =B18+D18 -> 65477.797
A19: 수수료 | B19: ='도초초 이설 소요예상액'!I83*B9 -> 65479.401 | D19: ='도초초 이설 소요예상액'!I83*D9 -> 54520.599 | E19: =B19+D19 -> 120000
A20: 철거비
A21: 이전비
A22: 교재교구비 | B22: 541890 | D22: 230000 | E22: =B22+D22 -> 771890 | F22: 7학급 448,516천원 / 병설유2학급 93,374천원
A23: 예비비 | B23: =('도초초 이설 소요예상액'!I97+'도초초 이설 소요예상액'!I100)*10% -> 3353945.5 | E23: =B23+D23 -> 3353945.5 | F23: 예비비 10%
A24: 합계 | B24: =SUM(B14:B23) -> 18186353 | C24: =SUM(C14:C23) -> 3928125 | D24: =SUM(D14:D23) -> 14778922 | E24: =SUM(E14:E23) -> 36893401
E25: (면적단위: M2)
A26: 재원구분 | B26: 이설+연립사택 | C26: 복합시설 | D26: 계 | E26: 비고
A27: 교육부 | C27: =E35 -> 9743541.3 | D27: =B27+C27 -> 9743541.3 | E27: 지원비 산정 단가 기준 상 총사업비의 70%(인구감소지역, 150억 미만)
A28: 신안군 | B28: 3000000 | C28: =(D24-C27)*50% -> 2517690.6 | D28: =B28+C28 -> 5517690.6 | E28: 이설(30억), 복합시설(교육부 지원비 제외 50%)
A29: 도교육청 | B29: =B24-B28+C24 -> 19114478 | C29: =(D24-C27)*50% -> 2517690.6 | D29: =B29+C29 -> 21632169 | E29: 이설(30억 제외한 나머지 금액), 복합시설(교육부 지원비 제외 50%)
A30: 합계 | B30: =SUM(B27:B29) -> 22114478 | C30: =SUM(C27:C29) -> 14778922 | D30: =SUM(D27:D29) -> 36893401
A32: 복합시설 교육부 지원비 기준 단가(2026년 지침)
E33: (금액단위: 천원, 면적단위: M2)
A34: 시설용도 | B34: 지원비 기준단가 | C34: 면적 | D34: 금액 | E34: 교육부 지원금액 산출
A35: 수영장 | B35: 6076 | D35: =B35*C35 -> 0 | E35: =D42*70% -> 9743541.3
A36: 체육관 | B36: 4987 | C36: ='도초초 이설 소요예상액'!G47 -> 1360 | D36: =B36*C36 -> 6782320
A37: 도서관 | B37: 4457 | C37: ='도초초 이설 소요예상액'!G37+'도초초 이설 소요예상액'!G38+'도초초 이설 소요예상액'!G39 -> 544.95 | D37: =B37*C37 -> 2428842.2
A38: 교육 및 기타시설 | B38: 4058 | C38: ='도초초 이설 소요예상액'!G36+'도초초 이설 소요예상액'!G41+'도초초 이설 소요예상액'!G42+'도초초 이설 소요예상액'!G43 -> 1046.25 | D38: =B38*C38 -> 4245682.5
A39: (지하)주차장 | B39: 3883 | D39: =B39*C39 -> 0
A40: 리모델링 | B40: 용도별 기준 60%이내
A41: 옥외공간 | B41: 실소요액 | D41: ='도초초 이설 소요예상액'!I76 -> 462500
A42: 합계 | C42: =SUM(C35:C41) -> 2951.2 | D42: =SUM(D35:D41) -> 13919345
A43: ※ 시설용도별 지원비 산정 기준 단가 기준으로 사업비 총액에 지원비율을 적용하여 교부
A44: (총사업비 = 시설용도별 지원비 산정 기준 단가 × 용도별 면적)

Sheet 도초초 이설 소요예상액
A1: 도초초 이설 소요예상액
A2: ∙ 초등학교 7학급(62명, 특수 1학급 포함), 병설유치원 2학급
A3: ∙ 2026년도 시설단가 적용 (도서할증 25% 반영)
A4: ∙ 비품비, 이사비 등 제외 | J4: (금액단위: 천원)
A5: 구 분 | D5: 단위 | E5: 소요면적 | H5: 소요예상액 | J5: 비고
E6: 실수 | F6: 단위면적 | G6: 면적(㎡) | H6: 단가 | I6: 금액
A7: 부지매입비
A8: 교실영역 | B8: 일반교실 | C8: 보통교실 | D8: 실 | E8: 6 | F8: 60.75 | G8: 364.5 | H8: =시설단가!E104*1.25 -> 2808.75 | I8: =G8*H8 -> 1023789.4 | J8: 신축, 도서할증 25% 적용
C9: 유치원교실 | D9: 실 | E9: 2 | F9: 60.75 | G9: 121.5 | H9: =H8 -> 2808.75 | I9: =G9*H9 -> 341263.12
C10: 특수교실 | D10: 실 | E10: 1 | F10: 60.75 | G10: 60.75 | H10: =H8 -> 2808.75 | I10: =G10*H10 -> 170631.56
C11: 소계 | E11: =SUM(E8:E10) -> 9 | F11: 182.25 | G11: =SUM(G8:G10) -> 546.75 | I11: =SUM(I8:I10) -> 1535684.1
C12: 과학실 | D12: 실 | E12: 1 | F12: 135 | G12: 135 | H12: =H8 -> 2808.75 | I12: =G12*H12 -> 379181.25
C13: 교사연구실 | D13: 실 | E13: 2 | F13: 60.75 | G13: 121.5 | H13: =H8 -> 2808.75 | I13: =G13*H13 -> 341263.12 | J13: 유·초
C14: 소계 | E14: =SUM(E12:E13) -> 3 | G14: =SUM(G12:G13) -> 256.5 | I14: =SUM(I12:I13) -> 720444.38
B15: 교실영역 계(A) | E15: =E11+E14 -> 12 | G15: =G11+G14 -> 803.25 | I15: =I11+I14 -> 2256128.4
A16: 지원영역 | B16: 휴게시설 | C16: 교직원휴게실 | D16: 실 | E16: 2 | F16: 30 | G16: =E16*F16 -> 60 | H16: =H8 -> 2808.75 | I16: =G16*H16 -> 168525 | J16: 남·여
C17: 학생탈의/샤워실 | D17: 실 | E17: 2 | F17: 30 | G17: =E17*F17 -> 60 | H17: =H8 -> 2808.75 | I17: =G17*H17 -> 168525 | J17: 남·여
C18: 소계 | E18: =SUM(E16:E17) -> 4 | G18: =SUM(G16:G17) -> 120 | I18: =SUM(I16:I17) -> 337050
B19: 급식시설 | C19: 급식실(식당) | D19: 실 | E19: 1 | F19: 120 | G19: 120 | H19: =시설단가!E22*1.25 -> 3112.5 | I19: =G19*H19 -> 373500
C20: 급식실(조리실) | D20: 실 | E20: 1 | F20: 90 | G20: 90 | H20: =시설단가!E23*1.25 -> 5392.5 | I20: =G20*H20 -> 485325
C21: 소계 | E21: =SUM(E19:E20) -> 2 | G21: =SUM(G19:G20) -> 210 | I21: =SUM(I19:I20) -> 858825
B22: 관리·행정시설 | C22: 교장실 | D22: 실 | E22: 1 | F22: 60.75 | G22: 60.75 | H22: =H8 -> 2808.75 | I22: =G22*H22 -> 170631.56
C23: 교무실 | D23: 실 | E23: 1 | F23: 60.75 | G23: 60.75 | H23: =H8 -> 2808.75 | I23: =G23*H23 -> 170631.56
C24: 행정실 | D24: 실 | E24: 1 | F24: 60.75 | G24: 60.75 | H24: =H8 -> 2808.75 | I24: =G24*H24 -> 170631.56
C25: 문서(보관)실 | D25: 실 | E25: 1 | F25: 60.75 | G25: 60.75 | H25: =H8 -> 2808.75 | I25: =G25*H25 -> 170631.56
C26: 상담실(Wee) | D26: 실 | E26: 1 | F26: 60.75 | G26: 60.75 | H26: =H8 -> 2808.75 | I26: =G26*H26 -> 170631.56
C27: 방송실 | D27: 실 | E27: 1 | F27: 30 | G27: 30 | H27: =H8 -> 2808.75 | I27: =G27*H27 -> 84262.5
C28: 보건실 | D28: 실 | E28: 1 | F28: 60.75 | G28: 60.75 | H28: =H8 -> 2808.75 | I28: =G28*H28 -> 170631.56
C29: 소계 | E29: =SUM(E22:E28) -> 7 | G29: =SUM(G22:G28) -> 394.5 | I29: =SUM(I22:I28) -> 1108051.9
B30: 지원영역 계(B) | E30: =E18+E21+E29 -> 13 | G30: =G18+G21+G29 -> 724.5 | I30: =I18+I21+I29 -> 2303926.9
A31: 교사동 집계 | B31: 교사동 순면적 계(C=A+B) | E31: 23 | G31: =G15+G30 -> 1527.75 | I31: =I15+I30 -> 4560055.3
B32: 공유면적(D) | D32: % | F32: 60% | G32: =G31*F32 -> 916.65 | H32: =H8 -> 2808.75 | I32: =G32*H32 -> 2574640.7
B33: 교사동 연면적 계(E=C+D) | E33: =E31 -> 23 | G33: =G31+G32 -> 2444.4 | I33: =I31+I32 -> 7134696
A34: 부속시설 | B34: 사택 | C34: 연립사택 | D34: 세대 | E34: 20 | F34: 55 | G34: =E34*F34 -> 1100 | H34: =시설단가!E87*1.25 -> 196406.25 | I34: =E34*H34 -> 3928125
B35: 부속시설 연면적 계(F) | E35: =E34 -> 20 | G35: =G34 -> 1100 | I35: =I34 -> 3928125
A36: 복합시설 | B36: 늘봄시설 | C36: 돌봄교실 | D36: 실 | E36: 3 | F36: 60.75 | G36: =E36*F36 -> 182.25 | H36: 3382 | I36: =ROUNDDOWN(G36*H36,0) -> 616369 | J36: 교육부 지원단가 적용
C37: 도서실 | D37: 실 | E37: 3 | F37: 60.75 | G37: =E37*F37 -> 182.25 | H37: 3714 | I37: =ROUNDDOWN(G37*H37,0) -> 676876 | J37: 기초파일, 냉난방 등 포함
C38: 자료실 | D38: 실 | E38: 3 | F38: 30 | G38: =E38*F38 -> 90 | H38: 3382 | I38: =ROUNDDOWN(G38*H38,0) -> 304380
C39: 공용면적 | D39: 식 | E39: 1 | F39: 0.6 | G39: =SUM(G36:G38)*F39 -> 272.7 | H39: =H36 -> 3382 | I39: =ROUNDDOWN(G39*H39,0) -> 922271
C40: 소계 | E40: 10 | G40: =SUM(G36:G39) -> 727.2 | I40: =SUM(I36:I39) -> 2519896
...

Sheet 시설단가
A1: (단위: 천원)
A2: 품명 | B2: 규격 | C2: 단위 | D2: 기준면적 | E2: 단가 | F2: 환산 | G2: 비고
A3: ■ 개축 및 보수
A4: ○ 교실개축 | B4: 90㎡기준(철거포함), 석면철거 제외 | C4: ㎡ | E4: 183189
A5: ○ 건물철거(일반) | B5: 90㎡기준 | C5: ㎡ | E5: 15846
A6: ○ 건물철거(석면) | B6: 90㎡기준 | C6: ㎡ | E6: 9176
A7: ○ 노후교실중수 | B7: 90㎡기준 [바닥, 창호(내·외부), 천장, 도장(내·외부) 포함] | C7: ㎡ | E7: 57665
A8: ○ 화장실중수 | B8: 45㎡(10칸)기준 | C8: ㎡ | E8: 96282
A9: ○ 화장실보수 | B9: 45㎡(10칸)기준(배관, 위생기구 제외) | C9: ㎡ | E9: 62327
A10: ○ 사택중수 | B10: 45㎡기준 | C10: ㎡ | E10: 44444
B11: 33㎡기준 | C11: ㎡ | E11: 28617
A12: ○ 교실누수보수 | B12: 지붕(실당90㎡기준) | C12: ㎡ | E12: 13928
B13: 벽체(실당90㎡기준) | C13: ㎡ | E13: 1990
A14: ○ 창고중수 | B14: 33㎡기준 | C14: ㎡ | E14: 9552
A15: ○ 숙직실중수 | B15: 33㎡기준 | C15: ㎡ | E15: 19923
A16: ○ 창호보수(90㎡기준) | B16: 교실출입문 2개소 | C16: ㎡ | E16: 4919
A17: [에너지 소비 효율 제품 적용] | B17: 교실출입문 2개소, 복도창 2개소 | C17: ㎡ | E17: 8591
B18: 외부창(이중창) | C18: ㎡ | E18: 25838
B19: 교실전체창(출입문, 복도, 외부 이중창) | C19: ㎡ | E19: 32928
A20: ○ 교실도장(90㎡기준) | B20: 내부(2회칠 기준) | C20: ㎡ | E20: 1839
B21: 외부(방수 제외, 2회칠 기준) | C21: ㎡ | E21: 1687
A22: ○ 급식실개축(㎡당) | B22: 식당(철거 제외) | C22: ㎡ | E22: 2490
B23: 조리실(철거 제외) | C23: ㎡ | E23: 4314
A24: ○ 급식실중수(㎡당) | B24: 식당 | C24: ㎡ | E24: 677
B25: 조리실 | C25: ㎡ | E25: 1529
A26: ○ 교실벽체보수(90㎡기준) | B26: 페인트외 타재료 마감(적벽돌, 복합패널 등) | C26: ㎡ | E26: 24616
A27: ○ 교실바닥보수(90㎡기준) | B27: 동바리기초, 교실 및 복도 후로링 | C27: ㎡ | E27: 22895
B28: 동바리기초, 교실 및 복도 PVC 타일 | C28: ㎡ | E28: 17085
B29: 콘크리트바닥, 교실 후로링, 복도 PVC 타일 | C29: ㎡ | E29: 15590
B30: 콘크리트바닥, 교실 및 복도 PVC 타일 | C30: ㎡ | E30: 13412
B31: 콘크리트바닥, 교실 이중 바닥재, 복도 PVC 타일 | C31: ㎡ | E31: 23232
B32: 1층 1개소 계단실, 고무타일 40㎡ 기준 | C32: ㎡ | E32: 5255
A33: ○ 천장보수(90㎡기준) | B33: 마감층, 단열재 교체 포함 | C33: ㎡ | E33: 12821
B34: 일반층 | C34: ㎡ | E34: 8658
B35: 일반층, 석면철거 포함 | C35: ㎡ | E35: 16613
B36: 일반층, 석면철거 및 전기시설 포함 | C36: ㎡ | E36: 21574
A37: ■ 토목·설비
A38: ○ 배수로시설, 콘크리트(m당) | B38: 0.3 × 0.3m | C38: m | E38: 315
B39: 0.4 × 0.4m | C39: m | E39: 367
B40: 0.4 × 0.4m, 스틸그레이팅 | C40: m | E40: 504
...
