Workbook

Sheet 원가계산서
B1: 공 사 원 가 계 산 서
B2: 공사명 : 하의중고 기숙사 출입문 교체공사
B3: 비 목 | E3: 금 액 | F3: 구 성 비 | G3: 비 고
A4: A1 | B4: 순 공 사 원 가 | C4: 재 료 비 | D4: 직 접 재 료 비 | E4: =TRUNC(공종별집계표!F5, 0) -> 9007938
A5: A2 | D5: 간 접 재 료 비 | E5: 0
A6: A3 | D6: 작업설, 부산물(△) | E6: 0
A7: AS | D7: [ 소 계 ] | E7: =TRUNC(E4+E5-E6, 0) -> 9007938
A8: B1 | C8: 노 무 비 | D8: 직 접 노 무 비 | E8: =TRUNC(공종별집계표!H5, 0) -> 4498668
A9: B2 | D9: 간 접 노 무 비 | E9: =TRUNC(E8*0.126, 0) -> 566832 | F9: 직접노무비 * 12.6%
A10: BS | D10: [ 소 계 ] | E10: =TRUNC(E8+E9, 0) -> 5065500
A11: C2 | C11: 경 비 | D11: 경 비 | E11: =TRUNC(공종별집계표!J5, 0) -> 49770
A12: C4 | D12: 산 재 보 험 료 | E12: =TRUNC(E10*0.0356, 0) -> 180331 | F12: 노무비 * 3.56%
A13: C5 | D13: 고 용 보 험 료 | E13: =TRUNC(E10*0.0101, 0) -> 51161 | F13: 노무비 * 1.01%
A14: C6 | D14: 국민 건강 보험료 | F14: 직접노무비 * 3.545%
A15: C7 | D15: 국민 연금 보험료 | F15: 직접노무비 * 4.5%
A16: CB | D16: 노인장기요양보험료 | F16: 건강보험료 * 12.95%
A17: CA | D17: 산업안전보건관리비 | E17: =TRUNC((E7+E8)*0.0293, 0) -> 395743 | F17: (재료비+직접노무비) * 2.93%
A18: CG | D18: 기 타 경 비 | E18: =TRUNC((E7+E10)*0.05024, 0) -> 707049 | F18: (재료비+노무비) * 5.024%
A19: CJ | D19: 수 도 광 열 비 | E19: =TRUNC((E7+E10)*0.00176, 0) -> 24769 | F19: (재료비+노무비) * 0.176%
D20: 건설폐기물처리비
A21: CS | D21: [ 소 계 ] | E21: =TRUNC(E11+E12+E13+E14+E15+E17+E16+E18+E19+E20, 0) -> 1408823
A22: S1 | B22: 계 | E22: =TRUNC(E7+E10+E21, 0) -> 15482261
A23: D1 | B23: 일 반 관 리 비 | E23: =TRUNC(E22*0.06, 0) -> 928935 | F23: 계 * 6%
A24: D2 | B24: 이 윤 | E24: =TRUNC((E10+E21+E23)*0.15, 0)-5750/1.1 -> 1105260.7 | F24: (노무비+경비+일반관리비) * 15%
A25: D9 | B25: 공 급 가 액 | E25: =TRUNC(E22+E23+E24, 0) -> 17516456
A26: DB | B26: 부 가 가 치 세 | E26: =TRUNC(E25*0.1, 0) -> 1751645 | F26: 공급가액 * 10%
A27: DH | B27: 도 급 액 | E27: =TRUNC(E25+E26, -3) -> 19268000
A28: S2 | B28: 총 공 사 비 | E28: =TRUNC(E27+0, 0) -> 19268000

Sheet 공종별집계표
A1: 공 종 별 집 계 표
A2: [ 하의중고 기숙사 출입문 교체공사 ]
A3: 품 명 | B3: 규 격 | C3: 단위 | D3: 수량 | E3: 재 료 비 | G3: 노 무 비 | I3: 경 비 | K3: 합 계 | M3: 비 고 | N3: 공종코드 | O3: 변수 | P3: 상위공종 | Q3: 공종구분 | R3: 공종레벨 | S3: 공종소계 | T3: 원가계산서 연결금액
E4: 단 가 | F4: 금 액 | G4: 단 가 | H4: 금 액 | I4: 단 가 | J4: 금 액 | K4: 단 가 | L4: 금 액
A5: 01 신안교육지원청 관사 보수공사 | D5: 1 | E5: =F6 -> 9007938 | F5: =E5*D5 -> 9007938 | G5: =H6 -> 4498668 | H5: =G5*D5 -> 4498668 | I5: =J6 -> 49770 | J5: =I5*D5 -> 49770 | K5: =E5+G5+I5 -> 13556376 | L5: =F5+H5+J5 -> 13556376 | N5: 01 | R5: 1
A6: 0101 A1.건축공사 | D6: 1 | E6: =F7+F8+F9+F10 -> 9007938 | F6: =E6*D6 -> 9007938 | G6: =H7+H8+H9+H10 -> 4498668 | H6: =G6*D6 -> 4498668 | I6: =J7+J8+J9+J10 -> 49770 | J6: =I6*D6 -> 49770 | K6: =E6+G6+I6 -> 13556376 | L6: =F6+H6+J6 -> 13556376 | N6: 0101 | P6: 01 | R6: 2 | S6: <
A7: 010101 01.가설공사 | D7: 1 | E7: =공종별내역서!F28 -> 0 | F7: =E7*D7 -> 0 | G7: =공종별내역서!H28 -> 626553 | H7: =G7*D7 -> 626553 | I7: =공종별내역서!J28 -> 0 | J7: =I7*D7 -> 0 | K7: =E7+G7+I7 -> 626553 | L7: =F7+H7+J7 -> 626553 | N7: 010101 | P7: 0101 | R7: 3
A8: 010101 02.방수공사 | D8: 1 | E8: =공종별내역서!F53 -> 0 | F8: =E8*D8 -> 0 | G8: =공종별내역서!H53 -> 1128960 | H8: =G8*D8 -> 1128960 | I8: =공종별내역서!J53 -> 0 | J8: =I8*D8 -> 0 | K8: =E8+G8+I8 -> 1128960 | L8: =F8+H8+J8 -> 1128960 | N8: 010103 | P8: 0101 | R8: 3
A9: 010101 03.창호공사 | D9: 1 | E9: =공종별내역서!F78 -> 9216900 | F9: =E9*D9 -> 9216900 | G9: =공종별내역서!H78 -> 2269485 | H9: =G9*D9 -> 2269485 | I9: =공종별내역서!J78 -> 49770 | J9: =I9*D9 -> 49770 | K9: =E9+G9+I9 -> 11536155 | L9: =F9+H9+J9 -> 11536155 | N9: 010107 | P9: 0101 | R9: 3
A10: 010101 04.철거공사 | D10: 1 | E10: =공종별내역서!F103 -> -208962 | F10: =E10*D10 -> -208962 | G10: =공종별내역서!H103 -> 473670 | H10: =G10*D10 -> 473670 | I10: =공종별내역서!J103 -> 0 | J10: =I10*D10 -> 0 | K10: =E10+G10+I10 -> 264708 | L10: =F10+H10+J10 -> 264708 | N10: 010110 | P10: 0101 | R10: 3
A17: [ 합 계 ] | F17: =F5 -> 9007938 | H17: =H5 -> 4498668 | J17: =J5 -> 49770 | L17: =L5 -> 13556376

Sheet 공종별내역서
A1: [ 하의중고 기숙사 출입문 교체공사 ]
A2: 품 명 | B2: 규 격 | C2: 단위 | D2: 수량 | E2: 재 료 비 | G2: 노 무 비 | I2: 경 비 | K2: 합 계 | M2: 비 고 | N2: 품목코드 | O2: 변수 | P2: 설정 | Q2: 공종코드 | R2: 일위 | S2: 단산 | T2: 자재 | U2: 손료적용 | V2: 손료저장 | W2: 적용율 | X2: JUK1 | Y2: JUK2 | Z2: JUK3 | AA2: JUK4 | AB2: JUK5 | AC2: JUK6 | AD2: JUK7 | AE2: JUK8 | AF2: JUK9 | AG2: JUK10 | AH2: JUK11 | AI2: JUK12 | AJ2: JUK13 | AK2: JUK14 | AL2: JUK15 | AM2: JUK16 | AN2: JUK17 | AO2: JUK18 | AP2: JUK19 | AQ2: JUK20 | AR2: 자재구분 | AS2: 공종구분 | AT2: 공종레벨 | AU2: 공종+자재 | AV2: 고유번호
E3: 단 가 | F3: 금 액 | G3: 단 가 | H3: 금 액 | I3: 단 가 | J3: 금 액 | K3: 단 가 | L3: 금 액
A4: 010101 01.가설공사 | Q4: 010101
A5: 건축물현장정리 | B5: 보통인부 (비품정리 및 준공청소 포함) | C5: 인 | D5: 3 | E5: =TRUNC(일위대가목록!E4,0) -> 0 | F5: =TRUNC(E5*D5, 0) -> 0 | G5: =TRUNC(일위대가목록!F4,0) -> 167081 | H5: =TRUNC(G5*D5, 0) -> 501243 | I5: =TRUNC(일위대가목록!G4,0) -> 0 | J5: =TRUNC(I5*D5, 0) -> 0 | K5: =TRUNC(E5+G5+I5, 0) -> 167081 | L5: =TRUNC(F5+H5+J5, 0) -> 501243 | N5: 533182090671827945B82E8C8D8A3D | Q5: 010101 | R5: T | S5: F | T5: F | AU5: 010101533182090671827945B82E8C8D8A3D | AV5: 2578
A6: 도서지역 노임할증 | B6: 인력품의 25% | C6: 식 | D6: 1 | G6: =H5*0.25 -> 125310.75 | H6: =TRUNC(G6*D6, 0) -> 125310 | K6: =TRUNC(E6+G6+I6, 0) -> 125310 | L6: =TRUNC(F6+H6+J6, 0) -> 125310
A28: [ 합 계 ] | F28: =SUM(F5:F27) -> 0 | H28: =SUM(H5:H27) -> 626553 | J28: =SUM(J5:J27) -> 0 | L28: =SUM(L5:L27) -> 626553 | N28: TOTAL
A29: 010102 02.방수공사 | Q29: 010103
A30: 수밀코킹(실리콘) | B30: 삼각, 10mm, 창호주위 | C30: M | D30: =9.8*18 -> 176.4 | E30: =TRUNC(일위대가목록!E5,0) -> 0 | F30: =TRUNC(E30*D30, 0) -> 0 | G30: =TRUNC(일위대가목록!F5,0) -> 5120 | H30: =TRUNC(G30*D30, 0) -> 903168 | I30: =TRUNC(일위대가목록!G5,0) -> 0 | J30: =TRUNC(I30*D30, 0) -> 0 | K30: =TRUNC(E30+G30+I30, 0) -> 5120 | L30: =TRUNC(F30+H30+J30, 0) -> 903168 | N30: 533112B936F749F5483B2487DF049B | Q30: 010103 | R30: T | S30: F | T30: F | AU30: 010103533112B936F749F5483B2487DF049B | AV30: 2876
A31: 도서지역 노임할증 | B31: 인력품의 25% | C31: 식 | D31: 1 | G31: =H30*0.25 -> 225792 | H31: =TRUNC(G31*D31, 0) -> 225792 | K31: =TRUNC(E31+G31+I31, 0) -> 225792 | L31: =TRUNC(F31+H31+J31, 0) -> 225792
A53: [ 합 계 ] | F53: =SUM(F30:F52) -> 0 | H53: =SUM(H30:H52) -> 1128960 | J53: =SUMIF(Q30:Q52,"010103",J30:J52) -> 0 | K53: =SUM(K30:K52) -> 230912 | L53: =SUM(L30:L52) -> 1128960 | N53: TOTAL
A54: 010103 03.창호공사 | Q54: 010107
A55: FSD-1 제작설치(단열제품,기존문틀) | B55: 0.9 Χ 2.1, 기성품(방화문) | C55: 개소 | D55: 9 | E55: =TRUNC(일위대가목록!E6,0) -> 474000 | F55: =TRUNC(E55*D55, 0) -> 4266000 | G55: =TRUNC(일위대가목록!F6,0) -> 74889 | H55: =TRUNC(G55*D55, 0) -> 674001 | I55: =TRUNC(일위대가목록!G6,0) -> 2246 | J55: =TRUNC(I55*D55, 0) -> 20214 | K55: =TRUNC(E55+G55+I55, 0) -> 551135 | L55: =TRUNC(F55+H55+J55, 0) -> 4960215 | N55: 533152D9F3EABE064B9C2F8D2A6318 | Q55: 010107 | R55: T | S55: F | T55: F | AU55: 010107533152D9F3EABE064B9C2F8D2A6318 | AV55: 2940
A56: 도어클로저 | B56: 도어클로저, K-2840, KS4호, 고급방화, 60∼85kg | C56: 조 | D56: 9 | E56: =TRUNC(단가대비표!O6,0) -> 100000 | F56: =TRUNC(E56*D56, 0) -> 900000 | G56: =TRUNC(단가대비표!P6,0) -> 0 | H56: =TRUNC(G56*D56, 0) -> 0 | I56: =TRUNC(단가대비표!V6,0) -> 0 | J56: =TRUNC(I56*D56, 0) -> 0 | K56: =TRUNC(E56+G56+I56, 0) -> 100000 | L56: =TRUNC(F56+H56+J56, 0) -> 900000 | N56: 541C82B9BEFB8B3148BB248E0D99716D880B55 | Q56: 010107 | R56: F | S56: F | T56: T | AU56: 010107541C82B9BEFB8B3148BB248E0D99716D880B55 | AV56: 2936
A57: 도어체크 설치 | B57: 재료비 별도 | C57: 개소 | D57: 18 | E57: =TRUNC(일위대가목록!E8,0) -> 0 | F57: =TRUNC(E57*D57, 0) -> 0 | G57: =TRUNC(일위대가목록!F8,0) -> 20622 | H57: =TRUNC(G57*D57, 0) -> 371196 | I57: =TRUNC(일위대가목록!G8,0) -> 412 | J57: =TRUNC(I57*D57, 0) -> 7416 | K57: =TRUNC(E57+G57+I57, 0) -> 21034 | L57: =TRUNC(F57+H57+J57, 0) -> 378612 | N57: 533152D96C39054D4D37278CED10A5 | Q57: 010107 | R57: T | S57: F | T57: F | AU57: 010107533152D96C39054D4D37278CED10A5 | AV57: 2888
A58: 피벗힌지 | B58: 피벗힌지, 100kg, 방화문용 | C58: 조 | D58: 9 | E58: =TRUNC(단가대비표!O9,0) -> 70000 | F58: =TRUNC(E58*D58, 0) -> 630000 | G58: =TRUNC(단가대비표!P9,0) -> 0 | H58: =TRUNC(G58*D58, 0) -> 0 | I58: =TRUNC(단가대비표!V9,0) -> 0 | J58: =TRUNC(I58*D58, 0) -> 0 | K58: =TRUNC(E58+G58+I58, 0) -> 70000 | L58: =TRUNC(F58+H58+J58, 0) -> 630000 | N58: 541C924908A2264B4ADA2A8B9E4D22482DFBB4 | Q58: 010107 | R58: F | S58: F | T58: T | AU58: 010107541C924908A2264B4ADA2A8B9E4D22482DFBB4 | AV58: 2937
A59: 디지털도어록 | B59: 디지털도어록, 터치패드+카드키 | C59: 조 | D59: 9 | E59: =TRUNC(단가대비표!O12,0) -> 194000 | F59: =TRUNC(E59*D59, 0) -> 1746000 | G59: =TRUNC(단가대비표!P12,0) -> 0 | H59: =TRUNC(G59*D59, 0) -> 0 | I59: =TRUNC(단가대비표!V12,0) -> 0 | J59: =TRUNC(I59*D59, 0) -> 0 | K59: =TRUNC(E59+G59+I59, 0) -> 194000 | L59: =TRUNC(F59+H59+J59, 0) -> 1746000 | N59: 541C924908A22681450B288A3171484439408B | Q59: 010107 | R59: F | S59: F | T59: T | AU59: 010107541C924908A22681450B288A3171484439408B | AV59: 2938
A60: 도어록 설치 / 디지탈도어록 강재창호 | B60: 재료비 별도 | C60: 개소 | D60: 9 | E60: =TRUNC(일위대가목록!E9,0) -> 0 | F60: =TRUNC(E60*D60, 0) -> 0 | G60: =TRUNC(일위대가목록!F9,0) -> 10710 | H60: =TRUNC(G60*D60, 0) -> 96390 | I60: =TRUNC(일위대가목록!G9,0) -> 214 | J60: =TRUNC(I60*D60, 0) -> 1926 | K60: =TRUNC(E60+G60+I60, 0) -> 10924 | L60: =TRUNC(F60+H60+J60, 0) -> 98316 | N60: 533152D96C395D7F4F792983B7EAB7 | Q60: 010107 | R60: T | S60: F | T60: F | AU60: 010107533152D96C395D7F4F792983B7EAB7 | AV60: 2939
A61: SD01[100*45*F1.6t,D1.2t] | B61: 1.800 x 2.100 = 3.780 | C61: EA | D61: 9 | E61: =일위대가목록!E7 -> 186100 | F61: =TRUNC(E61*D61, 0) -> 1674900 | G61: =일위대가목록!F13 -> 74889 | H61: =TRUNC(G61*D61, 0) -> 674001 | I61: =일위대가목록!G13 -> 2246 | J61: =TRUNC(I61*D61, 0) -> 20214 | K61: =TRUNC(E61+G61+I61, 0) -> 263235 | L61: =TRUNC(F61+H61+J61, 0) -> 2369115
A62: 도서지역 노임할증 | B62: 인력품의 25% | C62: 식 | D62: 1 | G62: =SUM(H55:H61)*0.25 -> 453897 | H62: =TRUNC(G62*D62, 0) -> 453897 | K62: =TRUNC(E62+G62+I62, 0) -> 453897 | L62: =TRUNC(F62+H62+J62, 0) -> 453897
A78: [ 합 계 ] | F78: =SUM(F55:F77) -> 9216900 | H78: =SUM(H55:H77) -> 2269485 | J78: =SUM(J55:J77) -> 49770 | L78: =SUM(L55:L77) -> 11536155 | N78: TOTAL
A79: 010104 4.철거공사 | Q79: 010110
A80: 강제문 철거 | B80: 외여닫이문(기존문틀재사용) | C80: 개소 | D80: 18 | E80: =TRUNC(일위대가목록!E11,0) -> 631 | F80: =TRUNC(E80*D80, 0) -> 11358 | G80: =TRUNC(일위대가목록!F11,0) -> 21052 | H80: =TRUNC(G80*D80, 0) -> 378936 | I80: =TRUNC(일위대가목록!G11,0) -> 0 | J80: =TRUNC(I80*D80, 0) -> 0 | K80: =TRUNC(E80+G80+I80, 0) -> 21683 | L80: =TRUNC(F80+H80+J80, 0) -> 390294 | N80: 53308299ACCC42A2484D2986CAE024 | Q80: 010110 | R80: T | S80: F | T80: F | AU80: 01011053308299ACCC42A2484D2986CAE024 | AV80: 2965
A81: 철강설(철거발생,경량A) | B81: 철강설, 강설, 작업설부산물 | C81: kg | D81: =-34*18 -> -612 | E81: =TRUNC(단가대비표!O5,0) -> 360 | F81: =TRUNC(E81*D81, 0) -> -220320 | G81: =TRUNC(단가대비표!P5,0) -> 0 | H81: =TRUNC(G81*D81, 0) -> 0 | I81: =TRUNC(단가대비표!V5,0) -> 0 | J81: =TRUNC(I81*D81, 0) -> 0 | K81: =TRUNC(E81+G81+I81, 0) -> 360 | L81: =TRUNC(F81+H81+J81, 0) -> -220320 | M81: 수집상차도 | N81: 543F4289904CEAFF41E6208EE9DF3AB89A3E18 | Q81: 010110 | R81: F | S81: F | T81: T | AU81: 010110543F4289904CEAFF41E6208EE9DF3AB89A3E18 | AV81: 2971
A82: 도서지역 노임할증 | B82: 인력품의 25% | C82: 식 | D82: 1 | G82: =SUM(H80:H81)*0.25 -> 94734 | H82: =TRUNC(G82*D82, 0) -> 94734 | K82: =TRUNC(E82+G82+I82, 0) -> 94734 | L82: =TRUNC(F82+H82+J82, 0) -> 94734
A103: [ 합 계 ] | F103: =SUM(F80:F102) -> -208962 | H103: =SUM(H80:H102) -> 473670 | J103: =SUM(J80:J102) -> 0 | L103: =SUM(L80:L102) -> 264708 | N103: TOTAL

Sheet 일위대가목록
B1: 일 위 대 가 목 록
B2: [ 하의중고 기숙사 출입문 교체공사 ]
A3: 코 드 | B3: 품 명 | C3: 규 격 | D3: 단위 | E3: 재 료 비 | F3: 노 무 비 | G3: 경 비 | H3: 합 계 | I3: 번 호 | J3: 비 고 | K3: 노임계수 | L3: 할증 | M3: 품셈개요 | N3: 장비일위
A4: 533182090671827945B82E8C8D8A3D | B4: 건축물현장정리 | C4: 보통인부 (비품정리 및 준공청소 포함) | D4: 인 | E4: =일위대가!F6 -> 0 | F4: =일위대가!H6 -> 167081 | G4: =일위대가!J6 -> 0 | H4: =E4+F4+G4 -> 167081 | I4: 호표 1
A5: 533112B936F749F5483B2487DF049B | B5: 수밀코킹(실리콘) | C5: 삼각, 10mm, 창호주위 | D5: M | E5: =일위대가!F55 -> 0 | F5: =일위대가!H55 -> 5120 | G5: =일위대가!J55 -> 0 | H5: =E5+F5+G5 -> 5120 | I5: 호표 2
A6: 533152D9F3EABE064B9C2F8D2A6318 | B6: FSD-1 제작설치(단열제품,기존문틀) | C6: 0.9 Χ 2.1, 기성품 | D6: 개소 | E6: =일위대가!F11 -> 474000 | F6: =일위대가!H11 -> 74889 | G6: =일위대가!J11 -> 2246 | H6: =E6+F6+G6 -> 551135 | I6: 호표 3
A7: 533152D9F3EABE064B9C2F8D2A6318 | B7: SD-1 제작설치(기존문틀) | C7: 0.9 Χ 2.1, 기성품 | D7: 개소 | E7: =일위대가!F66 -> 186100 | F7: =F6 -> 74889 | G7: =G6 -> 2246 | H7: =E7+F7+G7 -> 263235 | I7: 호표 4
A8: 533152D96C39054D4D37278CED10A5 | B8: 도어체크 설치 | C8: 재료비 별도 | D8: 개소 | E8: =일위대가!F16 -> 0 | F8: =일위대가!H16 -> 20622 | G8: =일위대가!J16 -> 412 | H8: =E8+F8+G8 -> 21034 | I8: 호표 5
A9: 533152D96C395D7F4F792983B7EAB7 | B9: 도어록 설치 / 디지탈도어록 강재창호 | C9: 재료비 별도 | D9: 개소 | E9: =일위대가!F21 -> 0 | F9: =일위대가!H21 -> 10710 | G9: =일위대가!J21 -> 214 | H9: =E9+F9+G9 -> 10924 | I9: 호표 6
A10: 533152D96C395D7F4F78288D6AD2B5 | B10: 도어록 설치 / 일반도어록 합성수지창호 | C10: 재료비 별도 | D10: 개소 | E10: =일위대가!F26 -> 0 | F10: =일위대가!H26 -> 5978 | G10: =일위대가!J26 -> 119 | H10: =E10+F10+G10 -> 6097 | I10: 호표 7
A11: 53308299ACCC42A2484D2986CAE024 | B11: 강제문 철거 | C11: 외여닫이문(기존문틀재사용) | D11: 개소 | E11: =일위대가!F31 -> 631 | F11: =일위대가!H31 -> 21052 | G11: =일위대가!J31 -> 0 | H11: =E11+F11+G11 -> 21683 | I11: 호표 8
A12: 533112B936CA2EBF4EEE2C81AD5B8A | B12: 수밀코킹 | C12: 재료비 별도 | D12: M | E12: =일위대가!F55 -> 0 | F12: =일위대가!H55 -> 5120 | G12: =일위대가!J55 -> 0 | H12: =E12+F12+G12 -> 5120 | I12: 호표 9
A13: 533152D91419C6AD419D2D8E858C23 | B13: 강재창호 설치 / 여닫이(기준문틀 60%) | C13: 창호면적 m2, 1.0 ~ 3.0 이하 | D13: 개소 | E13: =일위대가!F61 -> 0 | F13: =일위대가!H61 -> 74889 | G13: =일위대가!J61 -> 2246 | H13: =E13+F13+G13 -> 77135 | I13: 호표 10

Sheet 일위대가
A1: [ 하의중고 기숙사 출입문 교체공사 ]
A2: 품 명 | B2: 규 격 | C2: 단위 | D2: 수량 | E2: 재 료 비 | G2: 노 무 비 | I2: 경 비 | K2: 합 계 | M2: 비 고 | N2: 일위대가 | O2: 품목코드 | P2: 일위 | Q2: 단산 | R2: 자재 | S2: 손료적용 | T2: 손료저장 | U2: 적용율 | V2: JUK1 | W2: JUK2 | X2: JUK3 | Y2: JUK4 | Z2: JUK5 | AA2: JUK6 | AB2: JUK7 | AC2: JUK8 | AD2: JUK9 | AE2: JUK10 | AF2: JUK11 | AG2: JUK12 | AH2: JUK13 | AI2: JUK14 | AJ2: JUK15 | AK2: JUK16 | AL2: JUK17 | AM2: JUK18 | AN2: JUK19 | AO2: JUK20 | AP2: 할증적용 | AQ2: 할증저장 | AR2: 할증율 | AS2: HAL1 | AT2: HAL2 | AU2: HAL3 | AV2: 자재구분 | AW2: 일위대가+자재 | AX2: 장비일위 | AY2: 설정 | AZ2: 할증체크
E3: 단 가 | F3: 금 액 | G3: 단 가 | H3: 금 액 | I3: 단 가 | J3: 금 액 | K3: 단 가 | L3: 금 액
A4: 건축물현장정리 보통인부 (비품정리 및 준공청소 포함) 인 ( 호표 3 ) | N4: 533182090671827945B82E8C8D8A3D
A5: 보통인부 | B5: 일반공사 직종 | C5: 인 | D5: 1 | E5: =단가대비표!O27 -> 0 | F5: =TRUNC(E5*D5,1) -> 0 | G5: =단가대비표!P27 -> 167081 | H5: =TRUNC(G5*D5,1) -> 167081 | I5: =단가대비표!V27 -> 0 | J5: =TRUNC(I5*D5,1) -> 0 | K5: =TRUNC(E5+G5+I5,1) -> 167081 | L5: =TRUNC(F5+H5+J5,1) -> 167081 | N5: 533182090671827945B82E8C8D8A3D | O5: 53E732995C7D49F4463428879566D81369A6D2 | P5: F | Q5: F | R5: T | AW5: 533182090671827945B82E8C8D8A3D53E732995C7D49F4463428879566D81369A6D2
A6: [ 합 계 ] | F6: =TRUNC(SUMIF(N5:N5, N4, F5:F5),0) -> 0 | H6: =TRUNC(SUMIF(N5:N5, N4, H5:H5),0) -> 167081 | J6: =TRUNC(SUMIF(N5:N5, N4, J5:J5),0) -> 0 | L6: =F6+H6+J6 -> 167081 | N6: TOTAL | O6: TOTAL
A8: FSD-1 제작설치(단열제품,기존문틀) 0.9 Χ 2.1, 기성품 개소 ( 호표 23 ) | N8: 533152D9F3EABE064B9C2F8D2A6318
A9: 단열 방화문(or 철문/기존문틀) | B9: 0.9*2.1 기준 | C9: 조 | D9: 1 | E9: =단가대비표!O7 -> 474000 | F9: =TRUNC(E9*D9,1) -> 474000 | G9: =단가대비표!P7 -> 0 | H9: =TRUNC(G9*D9,1) -> 0 | I9: =단가대비표!V7 -> 0 | J9: =TRUNC(I9*D9,1) -> 0 | K9: =TRUNC(E9+G9+I9,1) -> 474000 | L9: =TRUNC(F9+H9+J9,1) -> 474000 | N9: 533152D9F3EABE064B9C2F8D2A6318 | O9: 541C82B9BEFB8B314B77248BDB0CC7CD94720A | P9: F | Q9: F | R9: T | AW9: 533152D9F3EABE064B9C2F8D2A6318541C82B9BEFB8B314B77248BDB0CC7CD94720A
A10: 강재창호 설치 / 여닫이(기준문틀 60%) | B10: 창호면적 m2, 1.0 ~ 3.0 이하 | C10: 개소 | D10: 1 | E10: =일위대가목록!E13 -> 0 | F10: =TRUNC(E10*D10,1) -> 0 | G10: =일위대가목록!F13 -> 74889 | H10: =TRUNC(G10*D10,1) -> 74889 | I10: =일위대가목록!G13 -> 2246 | J10: =TRUNC(I10*D10,1) -> 2246 | K10: =TRUNC(E10+G10+I10,1) -> 77135 | L10: =TRUNC(F10+H10+J10,1) -> 77135 | N10: 533152D9F3EABE064B9C2F8D2A6318 | O10: 533152D91419C6AD419D2D8E858C23 | P10: T | Q10: F | R10: F | AW10: 533152D9F3EABE064B9C2F8D2A6318533152D91419C6AD419D2D8E858C23
A11: [ 합 계 ] | F11: =TRUNC(SUMIF(N9:N10, N8, F9:F10),0) -> 474000 | H11: =TRUNC(SUMIF(N9:N10, N8, H9:H10),0) -> 74889 | J11: =TRUNC(SUMIF(N9:N10, N8, J9:J10),0) -> 2246 | L11: =F11+H11+J11 -> 551135 | N11: TOTAL | O11: TOTAL
A12: 도어체크 설치 재료비 별도 개소 ( 호표 29 ) | N12: 533152D96C39054D4D37278CED10A5
A13: 창호공 | B13: 일반공사 직종 | C13: 인 | D13: 0.062 | E13: =단가대비표!O31 -> 0 | F13: =TRUNC(E13*D13,1) -> 0 | G13: =단가대비표!P31 -> 249088 | H13: =TRUNC(G13*D13,1) -> 15443.4 | I13: =단가대비표!V31 -> 0 | J13: =TRUNC(I13*D13,1) -> 0 | K13: =TRUNC(E13+G13+I13,1) -> 249088 | L13: =TRUNC(F13+H13+J13,1) -> 15443.4 | N13: 533152D96C39054D4D37278CED10A5 | O13: 53E732995C7D49F4463428879566D81369A427 | P13: F | Q13: F | R13: T | V13: 1 | AW13: 533152D96C39054D4D37278CED10A553E732995C7D49F4463428879566D81369A427
A14: 보통인부 | B14: 일반공사 직종 | C14: 인 | D14: 0.031 | E14: =단가대비표!O27 -> 0 | F14: =TRUNC(E14*D14,1) -> 0 | G14: =단가대비표!P27 -> 167081 | H14: =TRUNC(G14*D14,1) -> 5179.5 | I14: =단가대비표!V27 -> 0 | J14: =TRUNC(I14*D14,1) -> 0 | K14: =TRUNC(E14+G14+I14,1) -> 167081 | L14: =TRUNC(F14+H14+J14,1) -> 5179.5 | N14: 533152D96C39054D4D37278CED10A5 | O14: 53E732995C7D49F4463428879566D81369A6D2 | P14: F | Q14: F | R14: T | V14: 1 | AW14: 533152D96C39054D4D37278CED10A553E732995C7D49F4463428879566D81369A6D2
A15: 공구손료 | B15: 인력품의 2% | C15: 식 | D15: 1 | E15: 0 | F15: =TRUNC(E15*D15,1) -> 0 | G15: 0 | H15: =TRUNC(G15*D15,1) -> 0 | I15: =TRUNC(SUMIF(V13:V15, RIGHTB(O15, 1), H13:H15)*U15, 2) -> 412.45 | J15: =TRUNC(I15*D15,1) -> 412.4 | K15: =TRUNC(E15+G15+I15,1) -> 412.4 | L15: =TRUNC(F15+H15+J15,1) -> 412.4 | N15: 533152D96C39054D4D37278CED10A5 | O15: 52256269F0638FB345052289E5DC001 | P15: F | Q15: F | R15: F | S15: 1 | T15: 2 | U15: 0.02 | AW15: 533152D96C39054D4D37278CED10A552256269F0638FB345052289E5DC001
A16: [ 합 계 ] | F16: =TRUNC(SUMIF(N13:N15, N12, F13:F15),0) -> 0 | H16: =TRUNC(SUMIF(N13:N15, N12, H13:H15),0) -> 20622 | J16: =TRUNC(SUMIF(N13:N15, N12, J13:J15),0) -> 412 | L16: =F16+H16+J16 -> 21034 | N16: TOTAL | O16: TOTAL
A18: 도어록 설치 / 디지탈도어록 강재창호 재료비 별도 개소 ( 호표 30 ) | N18: 533152D96C395D7F4F792983B7EAB7
A19: 창호공 | B19: 일반공사 직종 | C19: 인 | D19: 0.043 | E19: =단가대비표!O31 -> 0 | F19: =TRUNC(E19*D19,1) -> 0 | G19: =단가대비표!P31 -> 249088 | H19: =TRUNC(G19*D19,1) -> 10710.7 | I19: =단가대비표!V31 -> 0 | J19: =TRUNC(I19*D19,1) -> 0 | K19: =TRUNC(E19+G19+I19,1) -> 249088 | L19: =TRUNC(F19+H19+J19,1) -> 10710.7 | N19: 533152D96C395D7F4F792983B7EAB7 | O19: 53E732995C7D49F4463428879566D81369A427 | P19: F | Q19: F | R19: T | V19: 1 | AW19: 533152D96C395D7F4F792983B7EAB753E732995C7D49F4463428879566D81369A427
A20: 공구손료 | B20: 인력품의 2% | C20: 식 | D20: 1 | E20: 0 | F20: =TRUNC(E20*D20,1) -> 0 | G20: 0 | H20: =TRUNC(G20*D20,1) -> 0 | I20: =TRUNC(SUMIF(V19:V20, RIGHTB(O20, 1), H19:H20)*U20, 2) -> 214.21 | J20: =TRUNC(I20*D20,1) -> 214.2 | K20: =TRUNC(E20+G20+I20,1) -> 214.2 | L20: =TRUNC(F20+H20+J20,1) -> 214.2 | N20: 533152D96C395D7F4F792983B7EAB7 | O20: 52256269F0638FB345052289E5DC001 | P20: F | Q20: F | R20: F | S20: 1 | T20: 2 | U20: 0.02 | AW20: 533152D96C395D7F4F792983B7EAB752256269F0638FB345052289E5DC001
A21: [ 합 계 ] | F21: =TRUNC(SUMIF(N19:N20, N18, F19:F20),0) -> 0 | H21: =TRUNC(SUMIF(N19:N20, N18, H19:H20),0) -> 10710 | J21: =TRUNC(SUMIF(N19:N20, N18, J19:J20),0) -> 214 | L21: =F21+H21+J21 -> 10924 | N21: TOTAL | O21: TOTAL
A23: 도어록 설치 / 일반도어록 합성수지창호 재료비 별도 개소 ( 호표 31 ) | N23: 533152D96C395D7F4F78288D6AD2B5
A24: 창호공 | B24: 일반공사 직종 | C24: 인 | D24: 0.024 | E24: =단가대비표!O31 -> 0 | F24: =TRUNC(E24*D24,1) -> 0 | G24: =단가대비표!P31 -> 249088 | H24: =TRUNC(G24*D24,1) -> 5978.1 | I24: =단가대비표!V31 -> 0 | J24: =TRUNC(I24*D24,1) -> 0 | K24: =TRUNC(E24+G24+I24,1) -> 249088 | L24: =TRUNC(F24+H24+J24,1) -> 5978.1 | N24: 533152D96C395D7F4F78288D6AD2B5 | O24: 53E732995C7D49F4463428879566D81369A427 | P24: F | Q24: F | R24: T | V24: 1 | AW24: 533152D96C395D7F4F78288D6AD2B553E732995C7D49F4463428879566D81369A427
A25: 공구손료 | B25: 인력품의 2% | C25: 식 | D25: 1 | E25: 0 | F25: =TRUNC(E25*D25,1) -> 0 | G25: 0 | H25: =TRUNC(G25*D25,1) -> 0 | I25: =TRUNC(SUMIF(V24:V25, RIGHTB(O25, 1), H24:H25)*U25, 2) -> 119.56 | J25: =TRUNC(I25*D25,1) -> 119.5 | K25: =TRUNC(E25+G25+I25,1) -> 119.5 | L25: =TRUNC(F25+H25+J25,1) -> 119.5 | N25: 533152D96C395D7F4F78288D6AD2B5 | O25: 52256269F0638FB345052289E5DC001 | P25: F | Q25: F | R25: F | S25: 1 | T25: 2 | U25: 0.02 | AW25: 533152D96C395D7F4F78288D6AD2B552256269F0638FB345052289E5DC001
A26: [ 합 계 ] | F26: =TRUNC(SUMIF(N24:N25, N23, F24:F25),0) -> 0 | H26: =TRUNC(SUMIF(N24:N25, N23, H24:H25),0) -> 5978 | J26: =TRUNC(SUMIF(N24:N25, N23, J24:J25),0) -> 119 | L26: =F26+H26+J26 -> 6097 | N26: TOTAL | O26: TOTAL
A28: 강제문 철거 외여닫이문(기존문틀재사용) 개소 ( 호표 57 ) | N28: 53308299ACCC42A2484D2986CAE024
A29: 보통인부 | B29: 일반공사 직종 | C29: 인 | D29: 0.126 | E29: =단가대비표!O27 -> 0 | F29: =TRUNC(E29*D29,1) -> 0 | G29: =단가대비표!P27 -> 167081 | H29: =TRUNC(G29*D29,1) -> 21052.2 | I29: =단가대비표!V27 -> 0 | J29: =TRUNC(I29*D29,1) -> 0 | K29: =TRUNC(E29+G29+I29,1) -> 167081 | L29: =TRUNC(F29+H29+J29,1) -> 21052.2 | N29: 53308299ACCC42A2484D2986CAE024 | O29: 53E732995C7D49F4463428879566D81369A6D2 | P29: F | Q29: F | R29: T | V29: 1 | AW29: 53308299ACCC42A2484D2986CAE02453E732995C7D49F4463428879566D81369A6D2
A30: 공구손료 | B30: 인력품의 3% | C30: 식 | D30: 1 | E30: =TRUNC(SUMIF(V29:V30, RIGHTB(O30, 1), H29:H30)*U30, 2) -> 631.56 | F30: =TRUNC(E30*D30,1) -> 631.5 | G30: 0 | H30: =TRUNC(G30*D30,1) -> 0 | I30: 0 | J30: =TRUNC(I30*D30,1) -> 0 | K30: =TRUNC(E30+G30+I30,1) -> 631.5 | L30: =TRUNC(F30+H30+J30,1) -> 631.5 | N30: 53308299ACCC42A2484D2986CAE024 | O30: 52256269F0638FB345052289E5DC001 | P30: F | Q30: F | R30: F | S30: 1 | T30: 0 | U30: 0.03 | AW30: 53308299ACCC42A2484D2986CAE02452256269F0638FB345052289E5DC001
A31: [ 합 계 ] | F31: =TRUNC(SUMIF(N29:N30, N28, F29:F30),0) -> 631 | H31: =TRUNC(SUMIF(N29:N30, N28, H29:H30),0) -> 21052 | J31: =TRUNC(SUMIF(N29:N30, N28, J29:J30),0) -> 0 | L31: =F31+H31+J31 -> 21683 | N31: TOTAL | O31: TOTAL
A33: 건설폐기물상차비-불연성 TON ( 호표 59 ) | N33: 533182090671BFA24A462A8F522C24
A34: 건설폐기물상차비 - 불연성 | B34: 15톤덤프트럭(10m3) | C34: TON | D34: 1 | E34: =단가대비표!O25 -> 0 | F34: =TRUNC(E34*D34,1) -> 0 | G34: =단가대비표!P25 -> 0 | H34: =TRUNC(G34*D34,1) -> 0 | I34: =단가대비표!V25 -> 3520 | J34: =TRUNC(I34*D34,1) -> 3520 | K34: =TRUNC(E34+G34+I34,1) -> 3520 | L34: =TRUNC(F34+H34+J34,1) -> 3520 | N34: 533182090671BFA24A462A8F522C24 | O34: 533182090671BFA24B6A2E855E6370 | P34: F | Q34: F | R34: T | AW34: 533182090671BFA24A462A8F522C24533182090671BFA24B6A2E855E6370
A35: [ 합 계 ] | F35: =TRUNC(SUMIF(N34:N34, N33, F34:F34),0) -> 0 | H35: =TRUNC(SUMIF(N34:N34, N33, H34:H34),0) -> 0 | J35: =TRUNC(SUMIF(N34:N34, N33, J34:J34),0) -> 3520 | L35: =F35+H35+J35 -> 3520 | N35: TOTAL | O35: TOTAL
A37: 건설폐기물 -중간처리 건설(건축)폐자재 TON ( 호표 60 ) | N37: 533182090671BFB340AE2C80A521ED
A38: 건설폐재류 | B38: 가연성이 제거된 재활용이 가능한 혼합물 | C38: TON | D38: 1 | E38: =단가대비표!O22 -> 0 | F38: =TRUNC(E38*D38,1) -> 0 | G38: =단가대비표!P22 -> 0 | H38: =TRUNC(G38*D38,1) -> 0 | I38: =단가대비표!V22 -> 47205 | J38: =TRUNC(I38*D38,1) -> 47205 | K38: =TRUNC(E38+G38+I38,1) -> 47205 | L38: =TRUNC(F38+H38+J38,1) -> 47205 | N38: 533182090671BFB340AE2C80A521ED | O38: 533182090671BFB340AE2C837B4EBF | P38: F | Q38: F | R38: T | AW38: 533182090671BFB340AE2C80A521ED533182090671BFB340AE2C837B4EBF
A39: [ 합 계 ] | F39: =TRUNC(SUMIF(N38:N38, N37, F38:F38),0) -> 0 | H39: =TRUNC(SUMIF(N38:N38, N37, H38:H38),0) -> 0 | J39: =TRUNC(SUMIF(N38:N38, N37, J38:J38),0) -> 47205 | L39: =F39+H39+J39 -> 47205 | N39: TOTAL | O39: TOTAL
A41: 건설폐기물 -중간처리 불연+가연성 건설폐기물(소각 5%이하) TON ( 호표 61 ) | N41: 533182090671BFB343632A8AE52A1B
A42: 혼합건설폐기물 | B42: 불연성 건설폐기물에 가연성 5% 이하 혼합 | C42: TON | D42: 1 | E42: =단가대비표!O24 -> 0 | F42: =TRUNC(E42*D42,1) -> 0 | G42: =단가대비표!P24 -> 0 | H42: =TRUNC(G42*D42,1) -> 0 | I42: =단가대비표!V24 -> 166426 | J42: =TRUNC(I42*D42,1) -> 166426 | K42: =TRUNC(E42+G42+I42,1) -> 166426 | L42: =TRUNC(F42+H42+J42,1) -> 166426 | N42: 533182090671BFB343632A8AE52A1B | O42: 533182090671BFB340AE2C84032669 | P42: F | Q42: F | R42: T | AW42: 533182090671BFB343632A8AE52A1B533182090671BFB340AE2C84032669
A43: [ 합 계 ] | F43: =TRUNC(SUMIF(N42:N42, N41, F42:F42),0) -> 0 | H43: =TRUNC(SUMIF(N42:N42, N41, H42:H42),0) -> 0 | J43: =TRUNC(SUMIF(N42:N42, N41, J42:J42),0) -> 166426 | L43: =F43+H43+J43 -> 166426 | N43: TOTAL | O43: TOTAL
A45: 건설폐기물운반비-불연성 24톤덤프, 30km TON ( 호표 62 ) | N45: 533182090671BFA24A462A8F522FF9
A46: 건설폐기물운반비 - 불연성 | B46: 15톤덤프트럭 - 30km | C46: TON | D46: 1 | E46: =단가대비표!O26 -> 0 | F46: =TRUNC(E46*D46,1) -> 0 | G46: =단가대비표!P26 -> 0 | H46: =TRUNC(G46*D46,1) -> 0 | I46: =단가대비표!V26 -> 15990 | J46: =TRUNC(I46*D46,1) -> 15990 | K46: =TRUNC(E46+G46+I46,1) -> 15990 | L46: =TRUNC(F46+H46+J46,1) -> 15990 | N46: 533182090671BFA24A462A8F522FF9 | O46: 533182090671BFA24B6A2E87090B52 | P46: F | Q46: F | R46: T | AW46: 533182090671BFA24A462A8F522FF9533182090671BFA24B6A2E87090B52
A47: [ 합 계 ] | F47: =TRUNC(SUMIF(N46:N46, N45, F46:F46),0) -> 0 | H47: =TRUNC(SUMIF(N46:N46, N45, H46:H46),0) -> 0 | J47: =TRUNC(SUMIF(N46:N46, N45, J46:J46),0) -> 15990 | L47: =F47+H47+J47 -> 15990 | N47: TOTAL | O47: TOTAL
A49: 건설폐기물 -중간처리 건설폐재류에 가연성 5% 이하 혼합 TON ( 호표 63 ) | N49: 533182090671BFB343632A8AE40371
...

Sheet 단가대비표
A1: 단 가 대 비 표
A2: [ 하의중고 기숙사 출입문 교체공사 ]
A3: 코 드 | B3: 품 명 | C3: 규격 | D3: 단위 | E3: 재 료 비 | P3: 노 무 비 | Q3: 경 비 | W3: 번 호 | X3: 비 고 | Y3: 품목구분 | Z3: 노임구분 | AA3: 소수점처리 | AB3: 자재구분
E4: 조달청가격 | F4: PAGE | G4: 거래가격 | H4: PAGE | I4: 유통물가 | J4: PAGE | K4: 물가자료 | L4: PAGE | M4: 조사가격 | N4: PAGE | O4: 적용단가 | Q4: 조달청가격 | R4: 거래가격 | S4: 유통물가 | T4: 물가자료 | U4: 조사가격 | V4: 적용단가
A5: 543F4289904CEAFF41E6208EE9DF3AB89A3E18 | B5: 철강설(철거발생,경량A) | C5: 철강설, 강설, 작업설부산물 | D5: kg | E5: 0 | G5: 360 | H5: 1472 | I5: 0 | K5: 0 | L5: -47(350) | M5: 0 | O5: =SMALL(E5:M5,COUNTIF(E5:M5,0)+1) -> 360 | P5: 0 | Q5: 0 | R5: 0 | S5: 0 | T5: 0 | U5: 0 | V5: 0 | W5: 자재 5 | X5: 수집상차도
A6: 541C82B9BEFB8B3148BB248E0D99716D880B55 | B6: 도어클로저 | C6: 도어클로저, K-2840, KS4호, 고급방화, 60∼85kg | D6: 조 | E6: 100000 | G6: 101000 | H6: 658 | I6: 0 | K6: 0 | M6: 0 | O6: =SMALL(E6:M6,COUNTIF(E6:M6,0)+1) -> 100000 | P6: 0 | Q6: 0 | R6: 0 | S6: 0 | T6: 0 | U6: 0 | V6: 0 | W6: 자재 32
A7: 541C82B9BEFB8B314B77248BDB0CC7CD94720A | B7: 단열 방화문(or 철문/기존문틀) | C7: 0.9*2.1 기준 | D7: 조 | E7: 0 | G7: 474000 | H7: 654 | I7: 0 | K7: 0 | M7: 0 | O7: =SMALL(E7:M7,COUNTIF(E7:M7,0)+1) -> 474000 | P7: 0 | Q7: 0 | R7: 0 | S7: 0 | T7: 0 | U7: 0 | V7: 0 | W7: 자재 33
A8: 541C924908A2264B4ADA2A8B9E4D2406292E16 | B8: 도어힌지 | C8: 도어힌지, 황동, 베어링2개, 101.6*2.7mm | D8: 개 | E8: 0 | G8: 0 | I8: 0 | K8: 8400 | L8: 577 | M8: 0 | O8: =SMALL(E8:M8,COUNTIF(E8:M8,0)+1) -> 8400 | P8: 0 | Q8: 0 | R8: 0 | S8: 0 | T8: 0 | U8: 0 | V8: 0 | W8: 자재 50
A9: 541C924908A2264B4ADA2A8B9E4D22482DFBB4 | B9: 피벗힌지 | C9: 피벗힌지, 100kg, 방화문용 | D9: 조 | E9: 70000 | G9: 70000 | H9: 661 | I9: 70000 | J9: 454 | K9: 0 | M9: 0 | O9: =SMALL(E9:M9,COUNTIF(E9:M9,0)+1) -> 70000 | P9: 0 | Q9: 0 | R9: 0 | S9: 0 | T9: 0 | U9: 0 | V9: 0 | W9: 자재 51
A10: 541C924908A22681450B288A305386B0012325 | B10: 도어핸들 | C10: 도어핸들, 9000PB, 레바형 | D10: 조 | E10: 0 | G10: 0 | I10: 0 | K10: 28000 | L10: 577 | M10: 0 | O10: =SMALL(E10:M10,COUNTIF(E10:M10,0)+1) -> 28000 | P10: 0 | Q10: 0 | R10: 0 | S10: 0 | T10: 0 | U10: 0 | V10: 0 | W10: 자재 52
A11: 541C924908A22681450B288A305BDED490C252 | B11: 도어스톱 | C11: 도어스톱, 일자형 120mm | D11: 개 | E11: 0 | G11: 2200 | H11: 657 | I11: 1800 | J11: 455 | K11: 1800 | L11: 577 | M11: 0 | O11: =SMALL(E11:M11,COUNTIF(E11:M11,0)+1) -> 1800 | P11: 0 | Q11: 0 | R11: 0 | S11: 0 | T11: 0 | U11: 0 | V11: 0 | W11: 자재 53
A12: 541C924908A22681450B288A3171484439408B | B12: 디지털도어록 | C12: 디지털도어록, 터치패드+카드키 | D12: 조 | E12: 0 | G12: 0 | I12: 0 | K12: 194000 | L12: 573 | M12: 0 | O12: =SMALL(E12:M12,COUNTIF(E12:M12,0)+1) -> 194000 | P12: 0 | Q12: 0 | R12: 0 | S12: 0 | T12: 0 | U12: 0 | V12: 0 | W12: 자재 54
A13: 541C9249085BF33A44AA2084D9C6FB5439900A | B13: 연마지 | C13: 연마지, #120~180, 230*280mm | D13: 장 | E13: 217 | G13: 230 | H13: 1337 | I13: 385 | J13: 1168 | K13: 0 | M13: 0 | O13: =SMALL(E13:M13,COUNTIF(E13:M13,0)+1) -> 217 | P13: 0 | Q13: 0 | R13: 0 | S13: 0 | T13: 0 | U13: 0 | V13: 0 | W13: 자재 55
A14: 541C9249341BAD164F2C27879245EF6C952931 | B14: 초산비닐계접착제 | C14: 초산비닐계접착제, 벽지용 | D14: kg | E14: 1556 | G14: 2666.66 | H14: 692 | I14: 0 | K14: 0 | M14: 0 | O14: =SMALL(E14:M14,COUNTIF(E14:M14,0)+1) -> 1556 | P14: 0 | Q14: 0 | R14: 0 | S14: 0 | T14: 0 | U14: 0 | V14: 0 | W14: 자재 56
A15: 541C9249341BAD164F292A83330ADF8860C7F1 | B15: 고무접착제 | C15: 고무접착제, 건설용고무풀 | D15: kg | E15: 0 | G15: 11000 | H15: 147 | I15: 0 | K15: 0 | M15: 0 | O15: =SMALL(E15:M15,COUNTIF(E15:M15,0)+1) -> 11000 | P15: 0 | Q15: 0 | R15: 0 | S15: 0 | T15: 0 | U15: 0 | V15: 0 | W15: 자재 57
A16: 541C9249341BAD164F28298866E252724FC514 | B16: 퍼티 | C16: 퍼티, 319퍼티, 회색 | D16: kg | E16: 3125.16 | G16: 0 | I16: 0 | K16: 0 | M16: 0 | O16: =SMALL(E16:M16,COUNTIF(E16:M16,0)+1) -> 3125.16 | P16: 0 | Q16: 0 | R16: 0 | S16: 0 | T16: 0 | U16: 0 | V16: 0 | W16: 자재 58 | X16: 1L=1.55kg
A17: 541C9249341BAD164F2A248ABD322C4DB987AD | B17: 에폭시접착제 | C17: 에폭시접착제, 세라믹타일용 | D17: kg | E17: 2644 | G17: 3100 | H17: 147 | I17: 0 | K17: 0 | M17: 0 | O17: =SMALL(E17:M17,COUNTIF(E17:M17,0)+1) -> 2644 | P17: 0 | Q17: 0 | R17: 0 | S17: 0 | T17: 0 | U17: 0 | V17: 0 | W17: 자재 59
A18: 541C924934095FEF4EE3278085AEF8F3004E30 | B18: 수성페인트 | C18: 수성페인트, 친환경(POP 1급), 내부 | D18: L | E18: 0 | G18: 6250 | H18: 619 | I18: 0 | K18: 6250 | L18: 590 | M18: 0 | O18: =SMALL(E18:M18,COUNTIF(E18:M18,0)+1) -> 6250 | P18: 0 | Q18: 0 | R18: 0 | S18: 0 | T18: 0 | U18: 0 | V18: 0 | W18: 자재 60
A19: 541C924934095FEF4EE929890ACE480C4BC8DE | B19: 아크릴수지페인트 | C19: 아크릴수지페인트, KSM6020-2종1급, 흑색 | D19: L | E19: 3727 | F19: KSM6020-2종2급 | G19: 0 | I19: 0 | K19: 0 | M19: 0 | O19: =SMALL(E19:M19,COUNTIF(E19:M19,0)+1) -> 3727 | P19: 0 | Q19: 0 | R19: 0 | S19: 0 | T19: 0 | U19: 0 | V19: 0 | W19: 자재 61 | X19: 전라남도교육청단가없음
A20: 541C924934095FC341B1258541458AE01FB251 | B20: 실링재 | C20: 실링재, 실리콘, 비초산, 유리용, 창호주위 | D20: L | E20: 12783 | G20: 18500 | H20: 607 | I20: 0 | K20: 0 | M20: 0 | O20: =SMALL(E20:M20,COUNTIF(E20:M20,0)+1) -> 12783 | P20: 0 | Q20: 0 | R20: 0 | S20: 0 | T20: 0 | U20: 0 | V20: 0 | W20: 자재 62
A21: 541C924934095F3D44A92D81D81BCAFCEC01D0 | B21: 시너 | C21: 시너, KSM6060, 1종 | D21: L | E21: 0 | G21: 3494.44 | H21: 615 | I21: 3722.22 | J21: 466 | K21: 0 | M21: 0 | O21: =SMALL(E21:M21,COUNTIF(E21:M21,0)+1) -> 3494.44 | P21: 0 | Q21: 0 | R21: 0 | S21: 0 | T21: 0 | U21: 0 | V21: 0 | W21: 자재 63
A22: 533182090671BFB340AE2C837B4EBF | B22: 건설폐재류 | C22: 가연성이 제거된 재활용이 가능한 혼합물 | D22: TON | E22: 0 | G22: 0 | I22: 0 | K22: 0 | L22: -151 | M22: 0 | O22: 0 | P22: 0 | Q22: 0 | R22: 0 | S22: 0 | T22: 47205 | U22: 0 | V22: =SMALL(Q22:U22,COUNTIF(Q22:U22,0)+1) -> 47205 | W22: 자재 64 | Y22: C
A23: 533182090671BFB340AE2C837C548A | B23: 혼합건설폐기물 | C23: 건설폐재류에 가연성 5% 이하 혼합 | D23: TON | E23: 0 | G23: 0 | I23: 0 | K23: 0 | L23: -151 | M23: 0 | O23: 0 | P23: 0 | Q23: 0 | R23: 0 | S23: 0 | T23: 68359 | U23: 0 | V23: =SMALL(Q23:U23,COUNTIF(Q23:U23,0)+1) -> 68359 | W23: 자재 65 | Y23: C
A24: 533182090671BFB340AE2C84032669 | B24: 혼합건설폐기물 | C24: 불연성 건설폐기물에 가연성 5% 이하 혼합 | D24: TON | E24: 0 | G24: 0 | I24: 0 | K24: 0 | L24: -151 | M24: 0 | O24: 0 | P24: 0 | Q24: 0 | R24: 0 | S24: 0 | T24: 166426 | U24: 0 | V24: =SMALL(Q24:U24,COUNTIF(Q24:U24,0)+1) -> 166426 | W24: 자재 66 | Y24: C
A25: 533182090671BFA24B6A2E855E6370 | B25: 건설폐기물상차비 - 불연성 | C25: 15톤덤프트럭(10m3) | D25: TON | E25: 0 | G25: 0 | I25: 0 | K25: 0 | L25: -150 | M25: 0 | O25: 0 | P25: 0 | Q25: 0 | R25: 0 | S25: 0 | T25: 3520 | U25: 0 | V25: =SMALL(Q25:U25,COUNTIF(Q25:U25,0)+1) -> 3520 | W25: 자재 67
A26: 533182090671BFA24B6A2E87090B52 | B26: 건설폐기물운반비 - 불연성 | C26: 15톤덤프트럭 - 30km | D26: TON | E26: 0 | G26: 0 | I26: 0 | K26: 0 | L26: -150 | M26: 0 | O26: 0 | P26: 0 | Q26: 0 | R26: 0 | S26: 0 | T26: 15990 | U26: 0 | V26: =SMALL(Q26:U26,COUNTIF(Q26:U26,0)+1) -> 15990 | W26: 자재 68
A27: 53E732995C7D49F4463428879566D81369A6D2 | B27: 보통인부 | C27: 일반공사 직종 | D27: 인 | E27: 0 | G27: 0 | I27: 0 | K27: 0 | M27: 0 | O27: 0 | P27: 167081 | Q27: 0 | R27: 0 | S27: 0 | T27: 0 | U27: 0 | V27: 0 | W27: 노임 1 | Y27: B
A28: 53E732995C7D49F4463428879566D81369A6D6 | B28: 비계공 | C28: 일반공사 직종 | D28: 인 | E28: 0 | G28: 0 | I28: 0 | K28: 0 | M28: 0 | O28: 0 | P28: 282352 | Q28: 0 | R28: 0 | S28: 0 | T28: 0 | U28: 0 | V28: 0 | W28: 노임 2 | Y28: B
A29: 53E732995C7D49F4463428879566D81369A422 | B29: 조적공 | C29: 일반공사 직종 | D29: 인 | E29: 0 | G29: 0 | I29: 0 | K29: 0 | M29: 0 | O29: 0 | P29: 269836 | Q29: 0 | R29: 0 | S29: 0 | T29: 0 | U29: 0 | V29: 0 | W29: 노임 3 | Y29: B
A30: 53E732995C7D49F4463428879566D81369A420 | B30: 건축목공 | C30: 일반공사 직종 | D30: 인 | E30: 0 | G30: 0 | I30: 0 | K30: 0 | M30: 0 | O30: 0 | P30: 279267 | Q30: 0 | R30: 0 | S30: 0 | T30: 0 | U30: 0 | V30: 0 | W30: 노임 4 | Y30: B
A31: 53E732995C7D49F4463428879566D81369A427 | B31: 창호공 | C31: 일반공사 직종 | D31: 인 | E31: 0 | G31: 0 | I31: 0 | K31: 0 | M31: 0 | O31: 0 | P31: 249088 | Q31: 0 | R31: 0 | S31: 0 | T31: 0 | U31: 0 | V31: 0 | W31: 노임 5 | Y31: B
A32: 53E732995C7D49F4463428879566D81369A425 | B32: 방수공 | C32: 일반공사 직종 | D32: 인 | E32: 0 | G32: 0 | I32: 0 | K32: 0 | M32: 0 | O32: 0 | P32: 219996 | Q32: 0 | R32: 0 | S32: 0 | T32: 0 | U32: 0 | V32: 0 | W32: 노임 6 | Y32: B
A33: 53E732995C7D49F4463428879566D81369A424 | B33: 미장공 | C33: 일반공사 직종 | D33: 인 | E33: 0 | G33: 0 | I33: 0 | K33: 0 | M33: 0 | O33: 0 | P33: 274502 | Q33: 0 | R33: 0 | S33: 0 | T33: 0 | U33: 0 | V33: 0 | W33: 노임 7 | Y33: B
A34: 53E732995C7D49F4463428879566D81369A42B | B34: 타일공 | C34: 일반공사 직종 | D34: 인 | E34: 0 | G34: 0 | I34: 0 | K34: 0 | M34: 0 | O34: 0 | P34: 279575 | Q34: 0 | R34: 0 | S34: 0 | T34: 0 | U34: 0 | V34: 0 | W34: 노임 8 | Y34: B
A35: 53E732995C7D49F4463428879566D81369A42A | B35: 도장공 | C35: 일반공사 직종 | D35: 인 | E35: 0 | G35: 0 | I35: 0 | K35: 0 | M35: 0 | O35: 0 | P35: 256854 | Q35: 0 | R35: 0 | S35: 0 | T35: 0 | U35: 0 | V35: 0 | W35: 노임 9 | Y35: B
A36: 53E732995C7D49F4463428879566D81369A5CA | B36: 내장공 | C36: 일반공사 직종 | D36: 인 | E36: 0 | G36: 0 | I36: 0 | K36: 0 | M36: 0 | O36: 0 | P36: 245524 | Q36: 0 | R36: 0 | S36: 0 | T36: 0 | U36: 0 | V36: 0 | W36: 노임 10 | Y36: B
A37: 53E732995C7D49F4463428879566D81369A5CB | B37: 도배공 | C37: 일반공사 직종 | D37: 인 | E37: 0 | G37: 0 | I37: 0 | K37: 0 | M37: 0 | O37: 0 | P37: 221362 | Q37: 0 | R37: 0 | S37: 0 | T37: 0 | U37: 0 | V37: 0 | W37: 노임 11 | Y37: B
A38: 53E732995C7D49F4463428879566D81369A5C9 | B38: 석공 | C38: 일반공사 직종 | D38: 인 | E38: 0 | G38: 0 | I38: 0 | K38: 0 | M38: 0 | O38: 0 | P38: 263972 | Q38: 0 | R38: 0 | S38: 0 | T38: 0 | U38: 0 | V38: 0 | W38: 노임 12 | Y38: B
... A41: 53E732995C7D49F44630228CA5BDD4675B1010 | B41: 코킹공 | C41: 기타 직종 | D41: 인 | E41: 0 | G41: 0 | I41: 0 | K41: 0 | M41: 0 | O41: 0 | P41: 204830 | Q41: 0 | R41: 0 | S41: 0 | T41: 0 | U41: 0 | V41: 0 | W41: 노임 15 | Y41: B
A42: 5282E289DC6E6B4547E02A877FDBB875CAA0B3 | B42: 기계설비공사 | D42: 식 | E42: 0 | G42: 0 | I42: 0 | K42: 0 | M42: 1741783 | O42: =SMALL(E42:M42,COUNTIF(E42:M42,0)+1) -> 1741783 | P42: 1422722 | Q42: 0 | R42: 0 | S42: 0 | T42: 0 | U42: 7042 | V42: =SMALL(Q42:U42,COUNTIF(Q42:U42,0)+1) -> 7042 | W42: 자재 69
...

Sheet  공사설정 
A1: 이 Sheet는 수정하지 마십시요
A2: 공사구분 | B2: A | C2: 타이틀
A3: 확정내역 | B3: 원내역
A4: 자재단가적용 | B4: 5
A5: 경비단가적용 | B5: 5
A6: 품목코드형식 | B6: XXXX-XXXX-XXXXXXXXX
A7: 내역금액소수점처리 | B7: C | C7: T
A8: 일위대가내역소수점처리 | B8: C | C8: 2
A9: 단가명 | B9: 조달청가격 | C9: 거래가격 | D9: 유통물가 | E9: 물가자료 | F9: 조사가격 | G9: TTTTT
A10: 환율 | B10: 1289 | C10: 0 | D10: 0
A11: 시간당작업량 | B11: R | C11: 4
A12: 1회 사이클시간 | B12: R | C12: 4
A13: 시간당 작업사이클 | B13: R | C13: 3
A14: 일반변수 | B14: R | C14: 5
A15: 시간당 노임산출 계수 | B15: A | C15: 1/8*16/12*25/20 | D15: 1/8*16/12*25/20 | E15: 1/8*16/12*25/20 | F15: 1
A16: 재료비 할증 계수 | B16: 1.11 | C16: 1.12
A17: 노무비 할증 계수 | B17: 1 | C17: 1.5 | D17: 1.16 | E17: 1.6 | F17: 1.6 | G17: 1.6 | H17: 1.94 | I17: 1.94 | J17: 1.94 | K17: 1 | L17: 1 | M17: 1
A18: 경비 할증 계수 | B18: 1.25 | C18: 1.071
A19: 내역,일위대가 품명,규격,단위 따로적용
A20: 내역단가 소수점처리 | B20: C | C20: 1
A21: 코드 | B21: 공종구분명 | C21: 원가비목코드
A22: 1 | B22: 작 업 부 산 물 | C22: A3
A23: 2 | B23: 운 반 비 | C23: C1
A24: 3 | B24: 도급자관급자재비 | C24: DJ
A25: 4 | B25: 사 급 자 재 비 | C25: D3
A26: 5 | B26: 품 질 시 험 비 | C26: C9
A27: 6 | B27: 건설폐기물처리비 | C27: D4
A28: 7 | B28: 관급자관급자재비 | C28: DK
A29: 8
A30: 9
A43: 단가 순서 | B43: 1234
