Workbook
Name ________________LP1: #REF!
Name ________________LP2: #REF!
Name ______________LP1: #REF!
Name ______________LP2: #REF!
Name ____________LP1: #REF!
Name ____________LP2: #REF!
Name ____________LPB1: [1]부하계산서!#REF!
Name ____________LPK1: [1]부하계산서!#REF!
Name ____________LU1: '[2]부하(성남)'!#REF!
Name ____________LU2: '[2]부하(성남)'!#REF!
Name ____________LV01: '[2]부하(성남)'!#REF!
Name ____________UP1: [1]부하계산서!#REF!
Name ____________UP2: [1]부하계산서!#REF!
Name ___________LPB1: [1]부하계산서!#REF!
Name ___________LPK1: [1]부하계산서!#REF!
Name ___________LU1: '[2]부하(성남)'!#REF!
Name ___________LU2: '[2]부하(성남)'!#REF!
Name ___________LV01: '[2]부하(성남)'!#REF!
Name ___________UP1: [1]부하계산서!#REF!
Name ___________UP2: [1]부하계산서!#REF!
Name __________LP1: #REF!
Name __________LP2: #REF!
Name __________LPB1: [1]부하계산서!#REF!
Name __________LPK1: [1]부하계산서!#REF!
Name __________LU1: '[2]부하(성남)'!#REF!
Name __________LU2: '[2]부하(성남)'!#REF!
Name __________LV01: '[2]부하(성남)'!#REF!
Name __________UP1: [1]부하계산서!#REF!
Name __________UP2: [1]부하계산서!#REF!
Name _________LPB1: [1]부하계산서!#REF!
Name _________LPK1: [1]부하계산서!#REF!
Name _________LU1: '[2]부하(성남)'!#REF!
Name _________LU2: '[2]부하(성남)'!#REF!
Name _________LV01: '[2]부하(성남)'!#REF!
Name _________UP1: [1]부하계산서!#REF!
Name _________UP2: [1]부하계산서!#REF!
Name ________LP1: #REF!
Name ________LP2: #REF!
Name ________LPB1: [1]부하계산서!#REF!
Name ________LPK1: [1]부하계산서!#REF!
Name ________LU1: '[2]부하(성남)'!#REF!
Name ________LU2: '[2]부하(성남)'!#REF!
Name ________LV01: '[2]부하(성남)'!#REF!
Name ________UP1: [1]부하계산서!#REF!
Name ________UP2: [1]부하계산서!#REF!
Name _______LP1: #REF!
Name _______LP2: #REF!
Name _______LPB1: [1]부하계산서!#REF!
Name _______LPK1: [1]부하계산서!#REF!
Name _______LU1: '[2]부하(성남)'!#REF!
Name _______LU2: '[2]부하(성남)'!#REF!
Name _______LV01: '[2]부하(성남)'!#REF!
Name _______UP1: [1]부하계산서!#REF!
Name _______UP2: [1]부하계산서!#REF!
Name ______A99999: [3]총괄!#REF!
Name ______DOG1: #REF!
Name ______DOG2: #REF!
Name ______DOG3: #REF!
Name ______DOG4: #REF!
Name ______DP2: [4]FB25JN!$L$3:$M$3

Sheet 표지
B3: 적정 공사기간 확보를 위한 가이드라인 (국토교통부 고시 제2024-1021호) 기준
B5: 공사기간 산정 검토 보고서
B9: ='1. 기본정보'!C3 -> 신안교육지원청사 이설공사
B14: 착수 예정일 | E14: ='1. 기본정보'!C8 -> 46388
B15: 총 공사비 | E15: ='1. 기본정보'!C4 -> 111
B16: 시설물 유형 | E16: ='1. 기본정보'!C9 -> 청사
B17: 공사 지역 | E17: ='1. 기본정보'!C10 -> 전남·광주
B18: 총 공사기간 | E18: ='2-1. 공사기간 검토결과'!C45 -> 377일 (약 12.6개월)
B25: ="작성일: "&TEXT(TODAY(),"yyyy. mm. dd")&"" -> 작성일: 2026. 07. 09
B31: ="© "&TEXT(TODAY(),"yyyy")&" 전라rhkdwnxmr남도교육청 · 신안교육지원청. 본 보고서의 무단 전재·복제를 금합니다." -> © 2026 전라rhkdwnxmr남도교육청 · 신안교육지원청. 본 보고서의 무단 전재·복제를 금합니다.

Sheet 1. 기본정보
B1: 공사 기본정보 입력
B2: ※ 노란색 셀에 입력하십시오. 드롭다운이 있는 항목은 목록에서 선택하십시오.
B3: 공사명 | C3: 신안교육지원청사 이설공사 | D3: 해당 공사의 정식 공사명을 입력
B4: 총공사비 (억원) | C4: 111 | D4: 추정금액 기준 (부가세·관급자재 포함)
B5: 연면적(㎡) | C5: 3669.46 | D5: 연면적 직접 입력 (㎡)
B6: 규모(지하/지상) | C6: 0/4 | D6: 지하/지상 층수 (예: 1/5 = 지하·1·지상·5)
B7: 지붕형태 | C7: 콘크리트 평지붕 | D7: 지붕형태 선택 (드롭다운)
B8: 착수 예정일 | C8: 46388 | D8: 공사 착수 예정일 (YYYY-MM-DD)
B9: 시설물 유형 | C9: 청사 | D9: 학교시설이나 총사업비 200억이상이경우, 기타시설물적용
B10: 공사 지역 | C10: 전남·광주 | D10: 기상 비작업일수 산정 기준 지역
B11: 기상 지점 | C11: 목포 | D11: 혹서기, 동절기, 강우, 바람 지역 선정
B12: 도서지역 할증 | C12: 해당없음 | D12: 도서지역 할증 등급 선택 (해당 시)
B13: 건물철거면적(㎡) | C13: 0 | D13: 건축철거 해당 시 작성
B14: 석면해체제거면적(㎡) | C14: 0 | D14: 석면면적 해당 시 작성
B15: 토목공사 | C15: 해당 | D15: 해당될 경우 작성
B16: 조경공사 | C16: 해당 | D16: 해당될 경우 작성
B17: 주공정 공종 | C17: 철근콘크리트공사 | D17: 비작업일수 산정 기준 공종
B19: 기상조건 선택 (적용할 조건에 ☑ 체크)
B20: 기상조건 | C20: 선택 | D20: 세부 기준
B21: 혹서기 | C21: TRUE | D21: 체감온도 33℃ 이상
C22: FALSE | D22: 체감온도 35℃ 이상
C23: FALSE | D23: 일최고기온 33℃ 이상
C24: FALSE | D24: 일최고기온 35℃ 이상
B25: 동절기 | C25: TRUE | D25: 일최고기온 0℃ 이하
C26: FALSE | D26: 일최심신적설 5cm 이상
C27: FALSE | D27: 일최고기온 0℃ 이하 또는 신적설 5cm
C28: FALSE | D28: 일최저기온 -12℃ 이하
B29: 강우 | C29: FALSE | D29: 일강수량 3mm 이상
C30: TRUE | D30: 일강수량 5mm 이상
C31: FALSE | D31: 일강수량 10mm 이상
C32: FALSE | D32: 일강수량 20mm 이상
B33: 바람 | C33: FALSE | D33: 일최대순간풍속 15m/s 이상
B35: 산정 기준 · 법적 근거 · 출처
B37: 1. 법적 근거
B38: 「건설기술 진흥법」 제45조의2 | C38: 공사기간 산정기준 (발주청의 적정 공사기간 산정 의무)
B39: 「공공 건설공사의 공사기간 산정기준」 | C39: 국토교통부고시 제2024-1021호 (시행 2025.1.6.)
B40: 적정 공사기간 확보를 위한 가이드라인 | C40: 국토교통부·한국건설기술연구원, 2026년판
B41: 「건설기술 진흥법 시행령」 제17~19조 | C41: 총공사비 100억(시·군·구 50억) 이상 공사기간 적정성 심의
B43: 2. 산정 체계
B44: 공사기간 = ① 준비기간 + ② 작업일수 + ③ 비작업일수 + ④ 정리기간 공사기간 = 준비기간 + Σ(CP 공종별 공사기간 = 작업일수 + 비작업일수) + 정리기간 ※ 작업일수 = 공종별 물량÷1일작업량(부록4) ※ 준비·정리기간에는 비작업일수 미계상
...

Sheet 2. 요약 보고서
B2: 공사기간 산정 검토 요약 보고서
B4: 1. 공사 개요
B5: 공사명 | C5: ='1. 기본정보'!C3&" " -> 신안교육지원청사 이설공사
B6: 총공사비 | C6: ='1. 기본정보'!C4&" 억원" -> 111 억원 | E6: 연면적 | F6: ='1. 기본정보'!C5 -> 3669.46
B7: 규모(지하/지상) | C7: ='1. 기본정보'!C6 -> 0/4 | E7: 착수예정일 | F7: =TEXT('1. 기본정보'!C8,"yyyy.mm.dd") -> 2027.01.01
B8: 시설물 유형 | C8: ='1. 기본정보'!C9 -> 청사 | E8: 공사 지역 | F8: ='1. 기본정보'!C10 -> 전남·광주
B9: 지붕형태 | C9: ='1. 기본정보'!C7 -> 콘크리트 평지붕 | E9: 주공정 공종 | F9: ='1. 기본정보'!C17 -> 철근콘크리트공사
B10: 도서지역 할증 | C10: ='1. 기본정보'!C12 -> 해당없음 | E10: 철거(㎡) / 석면(㎡) | F10: =TEXT('1. 기본정보'!C13,"#,##0")&" / "&TEXT('1. 기본정보'!C14,"#,##0") -> 0 / 0
B12: 1-1. 공사기간 검토 기준
B13: 구분 | C13: 산정 기준 (근거) | E13: 세부 내용 (공사기간 구성)
B14: 검토1안 표준품셈 방식 | C14: 표준품셈 작업일수 기준 산정 (주공정 CP 순작업일수) | E14: 준비 + 비작업일수 + 작업일수(순) + 정리
B15: 검토2안 표준공기 방식 | C15: 국토부 고시 표준공기(기준일) 적용 | E15: 공사준비 + 본공사 + 준공 + 정리
B16: 검토3안 시설물별 산정공식 | C16: 시설물별 산정공식 회귀식 산출 | E16: 산정공식 결과(Y) + 준비 + 정리
B18: 2. 공사기간 검토 결과
B19: 검토1안 · 표준품셈 | D19: 검토2안 · 표준공기 | F19: 검토3안 · 산정공식
B20: =TEXT('2-1. 공사기간 검토결과'!C17,"#,##0")&"일" -> 607일 | D20: =TEXT('2-1. 공사기간 검토결과'!D17,"#,##0")&"일" -> 377일 | F20: =TEXT('2-1. 공사기간 검토결과'!E17,"#,##0")&"일" -> 742일
B21: ="("&TEXT('2-1. 공사기간 검토결과'!C18,"0.0")&"개월)" -> (20.2개월) | D21: ="("&TEXT('2-1. 공사기간 검토결과'!D18,"0.0")&"개월)" -> (12.6개월) | F21: ="("&TEXT('2-1. 공사기간 검토결과'!E18,"0.0")&"개월)" -> (24.7개월)
B23: 3. 검토 결론 및 채택안
B24: 채택 검토안 | C24: ='2-1. 공사기간 검토결과'!C44 -> 검토2안 (총 공사기간 최소안)
B25: 총 공사기간 | C25: ='2-1. 공사기간 검토결과'!C45 -> 377일 (약 12.6개월)
B26: 채택 사유 | C26: ='2-1. 공사기간 검토결과'!C46 -> 3개 검토안 중 총 공사기간이 가장 짧아, 적정 공기 확보와 과다 산정 방지 측면에서 유리하여 채택함.
B28: 4. 세부 공사일수
B29: 총 공사기간 | E29: 작업일수
B30: =MIN('2-1. 공사기간 검토결과'!$C$17:$E$17) -> 377 | E30: =INDEX('2-1. 공사기간 검토결과'!$C$14:$E$14,MATCH(MIN('2-1. 공사기간 검토결과'!$C$17:$E$17),'2-1. 공사기간 검토결과'!$C$17:$E$17,0)) -> 282
B31: ="약 "&TEXT(MIN('2-1. 공사기간 검토결과'!$C$17:$E$17)/30,"0.0")&"개월" -> 약 12.6개월 | E31: ="전체의 "&TEXT($E$30/$B$30,"0.0%") -> 전체의 74.8%
B32: =$B$30/$B$30 -> 1 | E32: =$E$30/$B$30 -> 0.74801061
B33: 비작업일수 | E33: 준비 + 정리
B34: =INDEX('2-1. 공사기간 검토결과'!$C$13:$E$13,MATCH(MIN('2-1. 공사기간 검토결과'!$C$17:$E$17),'2-1. 공사기간 검토결과'!$C$17:$E$17,0)) -> 포함 | E34: =INDEX('2-1. 공사기간 검토결과'!$C$12:$E$12,MATCH(MIN('2-1. 공사기간 검토결과'!$C$17:$E$17),'2-1. 공사기간 검토결과'!$C$17:$E$17,0))+INDEX('2-1. 공사기간 검토결과'!$C$15:$E$15,MATCH(MIN('2-1. 공사기간 검토결과'!$C$17:$E$17),'2-1. 공사기간 검토결과'!$C$17:$E$17,0)) -> 95
B35: =IF(ISNUMBER($B$34),"전체의 "&TEXT($B$34/$B$30,"0.0%"),"작업일수에 포함") -> 작업일수에 포함 | E35: ="전체의 "&TEXT($E$34/$B$30,"0.0%") -> 전체의 25.2%
B36: =IF(ISNUMBER($B$34),$B$34/$B$30,0) -> 0 | E36: =$E$34/$B$30 -> 0.25198939

Sheet 2-1. 공사기간 검토결과
B1: 공사기간산정 검토(안)
B2: 「공공 건설공사의 공사기간 산정기준」(국토교통부고시 제2024-1021호) · 2026년 가이드라인 적용
B3: 1. 공사 개요
B4: 공사명 | C4: ='1. 기본정보'!C3 -> 신안교육지원청사 이설공사
B5: 총공사비 (억원) | C5: ='1. 기본정보'!C4 -> 111
B6: 착수 예정일 | C6: ='1. 기본정보'!C8 -> 46388
B7: 시설물 유형 | C7: ='1. 기본정보'!C9 -> 청사
B8: 공사 지역 | C8: ='1. 기본정보'!C10 -> 전남·광주
B10: 2. 공사기간 구성 요약 (검토안별 비교)
B11: 구분 | C11: 검토1안 | D11: 검토2안 | E11: 검토3안 | F11: 비고
B12: ① 준비기간 | C12: ='(검토1안) 표준품셈 작업일수'!G41 -> 60 | D12: ='(검토2안) 공사기간'!G44 -> 65 | E12: ='(검토3안) 시설물별'!D28 -> 60
B13: ② 비작업일수 | C13: ='(검토1안) 표준품셈 작업일수'!G42 -> 118 | D13: 포함 | E13: 포함
B14: ③ 작업일수 | C14: ='(검토1안) 표준품셈 작업일수'!G43 -> 398.9 | D14: ='(검토2안) 공사기간'!G45 -> 282 | E14: ='(검토3안) 시설물별'!D27 -> 652
B15: ④ 정리기간 | C15: ='(검토1안) 표준품셈 작업일수'!G44 -> 30 | D15: ='(검토2안) 공사기간'!G46 -> 30 | E15: ='(검토3안) 시설물별'!D29 -> 30
B16: ⑤ 도서벽지 할증 | C16: - | D16: ='(검토2안) 공사기간'!G47 -> 0 | E16: -
B17: 총 공사기간 | C17: ='(검토1안) 표준품셈 작업일수'!G45 -> 606.9 | D17: ='(검토2안) 공사기간'!G48 -> 377 | E17: ='(검토3안) 시설물별'!D30 -> 742
B18: ( 개월 환산 ) | C18: =ROUND(C17/30,1) -> 20.2 | D18: =ROUND(D17/30,1) -> 12.6 | E18: =ROUND(E17/30,1) -> 24.7 | F18: 총 ÷ 30
B20: 🔗 ① 검토1안 — 표준품셈 방식
B21: 구분 | C21: 내용 | D21: 일수 (일) | E21: 비율 (%) | F21: 비고
B22: ① 준비기간 | C22: 설계도서 검토, 착공준비 등 | D22: ='(검토1안) 표준품셈 작업일수'!G41 -> 60 | E22: =D22/$D$26 -> 0.098863075 | F22: 「참고1」
B23: ② 비작업일수 | C23: 법정공휴일 + 기상조건 비작업일 | D23: ='(검토1안) 표준품셈 작업일수'!G42 -> 118 | E23: =D23/$D$26 -> 0.19443071 | F23: 「참고2」
B24: ③ 작업일수(순) | C24: 주공정(CP) 기준 순작업일수 | D24: ='(검토1안) 표준품셈 작업일수'!G43 -> 398.9 | E24: =D24/$D$26 -> 0.65727467
B25: ④ 정리기간 | C25: 준공검사 준비, 현장정리 등 | D25: ='(검토1안) 표준품셈 작업일수'!G44 -> 30 | E25: =D25/$D$26 -> 0.049431537 | F25: 「참고1」
B26: 총 공사기간 | D26: ='(검토1안) 표준품셈 작업일수'!G45 -> 606.9 | E26: =ROUND(D26/30,1) -> 20.2 | F26: 준비+비작업+작업(순)+정리
B28: 🔗 ② 검토2안 — 표준공기(기준일) 방식
B29: 구분 | C29: 내용 | D29: 일수 (일) | E29: 비율 (%) | F29: 비고
B30: ① 준비기간 | C30: 공사준비 (착공) | D30: ='(검토2안) 공사기간'!G44 -> 65 | E30: =D30/$D$34 -> 0.17241379
B31: ② 작업일수(본공사) | C31: 토목·골조·마감·철거 등 | D31: ='(검토2안) 공사기간'!G45 -> 282 | E31: =D31/$D$34 -> 0.74801061
B32: ③ 정리기간 | C32: 준공 (준공검사 등) | D32: ='(검토2안) 공사기간'!G46 -> 30 | E32: =D32/$D$34 -> 0.079575597
B33: ④ 도서벽지 할증 | C33: 도서·벽지 지역 추가일수 | D33: ='(검토2안) 공사기간'!G47 -> 0 | E33: =D33/$D$34 -> 0
B34: 총 공사기간 | D34: ='(검토2안) 공사기간'!G48 -> 377 | E34: =ROUND(D34/30,1) -> 12.6 | F34: 준비+본공사+정리+할증
B36: 🔗 ③ 검토3안 — 시설물별 산정공식(부록5) 방식
B37: 구분 | C37: 내용 | D37: 일수 (일) | E37: 비율 (%) | F37: 비고
B38: ① 산정공식 결과(Y) | C38: 시설물별 회귀식 산출 | D38: ='(검토3안) 시설물별'!D27 -> 652 | E38: =D38/$D$41 -> 0.8787062 | F38: 비작업일 포함
B39: ② 준비기간 | C39: 설계도서 검토, 착공준비 등 | D39: ='(검토3안) 시설물별'!D28 -> 60 | E39: =D39/$D$41 -> 0.080862534
B40: ③ 정리기간 | C40: 준공검사 준비, 현장정리 등 | D40: ='(검토3안) 시설물별'!D29 -> 30 | E40: =D40/$D$41 -> 0.040431267
B41: 총 공사기간 | D41: ='(검토3안) 시설물별'!D30 -> 742 | E41: =ROUND(D41/30,1) -> 24.7 | F41: 산정공식(Y) + 준비 + 정리
B43: 3. 검토 결론 및 채택안
B44: 채택 검토안 | C44: =INDEX(C11:E11,MATCH(MIN(C17:E17),C17:E17,0))&" (총 공사기간 최소안)" -> 검토2안 (총 공사기간 최소안)
B45: 총 공사기간 | C45: =TEXT(MIN(C17:E17),"#,##0")&"일 (약 "&TEXT(MIN(C17:E17)/30,"0.0")&"개월)" -> 377일 (약 12.6개월)
...

Sheet (검토1안) 표준품셈 작업일수
A1: [검토1안] 표준품셈 작업일수
A2: 공종을 드롭박스에서 선택하면 세부공종 목록이 자동 연동되고, 세부공종 선택 시 단위·표준 1일작업량·근거가 부록4에서 자동 반영됩니다. 소요일수 = ( 물량 ÷ (표준 1일작업량 × 투입조수) ). 순작업일수(②) = 주공정(CP=Y) 소요일수 합계.
A3: 순번 | B3: 공 종(A) | C3: 세부공종(B) | D3: 물 량 | E3: 단위 | F3: 표준 1일작업량 | G3: 투입 조수 | H3: 적용 1일작업량 | I3: 소요일수 (일) | J3: 주공정 (CP) | K3: CP반영 일수 | L3: 근거 (부록4 작업조건)
A4: =IF(T_검토1안작업일수[[#This Row],[세부공종(B)]]="","",ROW()-ROW(T_검토1안작업일수[[#Headers],[순번]])) -> 1 | B4: 가설공사 | C4: 콘테이너형 가설건축물 설치 | D4: 7 | E4: =IF($C4="","",IFERROR(VLOOKUP(SUBSTITUTE($C4,"~","~~"),'(참고1)_1일작업량'!$B:$E,2,0),"")) -> 개 | F4: =IF($C4="","",IFERROR(VLOOKUP(SUBSTITUTE($C4,"~","~~"),'(참고1)_1일작업량'!$B:$E,3,0),"")) -> 8 | G4: 1 | H4: =IF(OR($F4="",$G4=""),"",$F4*$G4) -> 8 | I4: =IF(OR($H4="",$H4=0,$D4=""),"",ROUNDUP($D4/$H4,0)) -> 1 | J4: Y | K4: =IF($I4="","",IF($J4="Y",$I4,0)) -> 1 | L4: =IF($C4="","",IFERROR(IF(VLOOKUP(SUBSTITUTE($C4,"~","~~"),'(참고1)_1일작업량'!$B:$E,4,0)=0,"",VLOOKUP(SUBSTITUTE($C4,"~","~~"),'(참고1)_1일작업량'!$B:$E,4,0)),"")) -> 콘테이너 9m×3m, 비계공4·특별2·크레인10t
A5: =IF(T_검토1안작업일수[[#This Row],[세부공종(B)]]="","",ROW()-ROW(T_검토1안작업일수[[#Headers],[순번]])) -> 2 | B5: 가설공사 | C5: 가설울타리(EGI휀스) 설치 | D5: 430 | E5: =IF($C5="","",IFERROR(VLOOKUP(SUBSTITUTE($C5,"~","~~"),'(참고1)_1일작업량'!$B:$E,2,0),"")) -> m | F5: =IF($C5="","",IFERROR(VLOOKUP(SUBSTITUTE($C5,"~","~~"),'(참고1)_1일작업량'!$B:$E,3,0),"")) -> 115 | G5: 1 | H5: =IF(OR($F5="",$G5=""),"",$F5*$G5) -> 115 | I5: =IF(OR($H5="",$H5=0,$D5=""),"",ROUNDUP($D5/$H5,0)) -> 4 | J5: Y | K5: =IF($I5="","",IF($J5="Y",$I5,0)) -> 4 | L5: =IF($C5="","",IFERROR(IF(VLOOKUP(SUBSTITUTE($C5,"~","~~"),'(참고1)_1일작업량'!$B:$E,4,0)=0,"",VLOOKUP(SUBSTITUTE($C5,"~","~~"),'(참고1)_1일작업량'!$B:$E,4,0)),"")) -> 높이3.0m이하, 비계공3·보통1
A6: =IF(T_검토1안작업일수[[#This Row],[세부공종(B)]]="","",ROW()-ROW(T_검토1안작업일수[[#Headers],[순번]])) -> 3 | B6: 가설공사 | C6: 시스템비계 설치·해체 | D6: =1787+2004 -> 3791 | E6: =IF($C6="","",IFERROR(VLOOKUP(SUBSTITUTE($C6,"~","~~"),'(참고1)_1일작업량'!$B:$E,2,0),"")) -> ㎡ | F6: =IF($C6="","",IFERROR(VLOOKUP(SUBSTITUTE($C6,"~","~~"),'(참고1)_1일작업량'!$B:$E,3,0),"")) -> 100 | G6: 2 | H6: =IF(OR($F6="",$G6=""),"",$F6*$G6) -> 200 | I6: =IF(OR($H6="",$H6=0,$D6=""),"",ROUNDUP($D6/$H6,0)) -> 19 | J6: Y | K6: =IF($I6="","",IF($J6="Y",$I6,0)) -> 19 | L6: =IF($C6="","",IFERROR(IF(VLOOKUP(SUBSTITUTE($C6,"~","~~"),'(참고1)_1일작업량'!$B:$E,4,0)=0,"",VLOOKUP(SUBSTITUTE($C6,"~","~~"),'(참고1)_1일작업량'!$B:$E,4,0)),"")) -> 10m이하, 비계공4·보통1
A7: =IF(T_검토1안작업일수[[#This Row],[세부공종(B)]]="","",ROW()-ROW(T_검토1안작업일수[[#Headers],[순번]])) -> 4 | B7: 가설공사 | C7: 강관동바리 설치·해체(건축) | D7: 9637 | E7: =IF($C7="","",IFERROR(VLOOKUP(SUBSTITUTE($C7,"~","~~"),'(참고1)_1일작업량'!$B:$E,2,0),"")) -> ㎡ | F7: =IF($C7="","",IFERROR(VLOOKUP(SUBSTITUTE($C7,"~","~~"),'(참고1)_1일작업량'!$B:$E,3,0),"")) -> 100 | G7: 4 | H7: =IF(OR($F7="",$G7=""),"",$F7*$G7) -> 400 | I7: =IF(OR($H7="",$H7=0,$D7=""),"",ROUNDUP($D7/$H7,0)) -> 25 | J7: Y | K7: =IF($I7="","",IF($J7="Y",$I7,0)) -> 25 | L7: =IF($C7="","",IFERROR(IF(VLOOKUP(SUBSTITUTE($C7,"~","~~"),'(참고1)_1일작업량'!$B:$E,4,0)=0,"",VLOOKUP(SUBSTITUTE($C7,"~","~~"),'(참고1)_1일작업량'!$B:$E,4,0)),"")) -> 높이3.5m이하, 형틀목공5·보통1
A8: =IF(T_검토1안작업일수[[#This Row],[세부공종(B)]]="","",ROW()-ROW(T_검토1안작업일수[[#Headers],[순번]])) -> 5 | B8: 토공사 | C8: 터파기(굴삭기1.0㎥·보통) | D8: =1073+2211 -> 3284 | E8: =IF($C8="","",IFERROR(VLOOKUP(SUBSTITUTE($C8,"~","~~"),'(참고1)_1일작업량'!$B:$E,2,0),"")) -> ㎥ | F8: =IF($C8="","",IFERROR(VLOOKUP(SUBSTITUTE($C8,"~","~~"),'(참고1)_1일작업량'!$B:$E,3,0),"")) -> 514 | G8: 1 | H8: =IF(OR($F8="",$G8=""),"",$F8*$G8) -> 514 | I8: =IF(OR($H8="",$H8=0,$D8=""),"",ROUNDUP($D8/$H8,0)) -> 7 | J8: Y | K8: =IF($I8="","",IF($J8="Y",$I8,0)) -> 7 | L8: =IF($C8="","",IFERROR(IF(VLOOKUP(SUBSTITUTE($C8,"~","~~"),'(참고1)_1일작업량'!$B:$E,4,0)=0,"",VLOOKUP(SUBSTITUTE($C8,"~","~~"),'(참고1)_1일작업량'!$B:$E,4,0)),"")) -> 보통토사, 난이도 보통, 굴삭기1.0㎥ 1대
A9: =IF(T_검토1안작업일수[[#This Row],[세부공종(B)]]="","",ROW()-ROW(T_검토1안작업일수[[#Headers],[순번]])) -> 6 | B9: 철근공사 | C9: 철근 현장조립(건축 TypeⅡ) | D9: =94+156 -> 250 | E9: =IF($C9="","",IFERROR(VLOOKUP(SUBSTITUTE($C9,"~","~~"),'(참고1)_1일작업량'!$B:$E,2,0),"")) -> ton | F9: =IF($C9="","",IFERROR(VLOOKUP(SUBSTITUTE($C9,"~","~~"),'(참고1)_1일작업량'!$B:$E,3,0),"")) -> 3 | G9: 4 | H9: =IF(OR($F9="",$G9=""),"",$F9*$G9) -> 12 | I9: =IF(OR($H9="",$H9=0,$D9=""),"",ROUNDUP($D9/$H9,0)) -> 21 | J9: Y | K9: =IF($I9="","",IF($J9="Y",$I9,0)) -> 21 | L9: =IF($C9="","",IFERROR(IF(VLOOKUP(SUBSTITUTE($C9,"~","~~"),'(참고1)_1일작업량'!$B:$E,4,0)=0,"",VLOOKUP(SUBSTITUTE($C9,"~","~~"),'(참고1)_1일작업량'!$B:$E,4,0)),"")) -> φ13이하 50%이상, 철근공6·보통2
A10: =IF(T_검토1안작업일수[[#This Row],[세부공종(B)]]="","",ROW()-ROW(T_검토1안작업일수[[#Headers],[순번]])) -> 7 | B10: 거푸집공사 | C10: 유로폼 설치(보통) | D10: =3161+6291 -> 9452 | E10: =IF($C10="","",IFERROR(VLOOKUP(SUBSTITUTE($C10,"~","~~"),'(참고1)_1일작업량'!$B:$E,2,0),"")) -> ㎡ | F10: =IF($C10="","",IFERROR(VLOOKUP(SUBSTITUTE($C10,"~","~~"),'(참고1)_1일작업량'!$B:$E,3,0),"")) -> 50 | G10: 6 | H10: =IF(OR($F10="",$G10=""),"",$F10*$G10) -> 300 | I10: =IF(OR($H10="",$H10=0,$D10=""),"",ROUNDUP($D10/$H10,0)) -> 32 | J10: Y | K10: =IF($I10="","",IF($J10="Y",$I10,0)) -> 32 | L10: =IF($C10="","",IFERROR(IF(VLOOKUP(SUBSTITUTE($C10,"~","~~"),'(참고1)_1일작업량'!$B:$E,4,0)=0,"",VLOOKUP(SUBSTITUTE($C10,"~","~~"),'(참고1)_1일작업량'!$B:$E,4,0)),"")) -> 수직고7m이하, 형틀목공4·보통1
A11: =IF(T_검토1안작업일수[[#This Row],[세부공종(B)]]="","",ROW()-ROW(T_검토1안작업일수[[#Headers],[순번]])) -> 8 | B11: 거푸집공사 | C11: 합판거푸집 설치(보통) | D11: =1521+2936 -> 4457 | E11: =IF($C11="","",IFERROR(VLOOKUP(SUBSTITUTE($C11,"~","~~"),'(참고1)_1일작업량'!$B:$E,2,0),"")) -> ㎡ | F11: =IF($C11="","",IFERROR(VLOOKUP(SUBSTITUTE($C11,"~","~~"),'(참고1)_1일작업량'!$B:$E,3,0),"")) -> 60 | G11: 4 | H11: =IF(OR($F11="",$G11=""),"",$F11*$G11) -> 240 | I11: =IF(OR($H11="",$H11=0,$D11=""),"",ROUNDUP($D11/$H11,0)) -> 19 | J11: Y | K11: =IF($I11="","",IF($J11="Y",$I11,0)) -> 19 | L11: =IF($C11="","",IFERROR(IF(VLOOKUP(SUBSTITUTE($C11,"~","~~"),'(참고1)_1일작업량'!$B:$E,4,0)=0,"",VLOOKUP(SUBSTITUTE($C11,"~","~~"),'(참고1)_1일작업량'!$B:$E,4,0)),"")) -> 내수합판12mm, 형틀목공5·보통2
A12: =IF(T_검토1안작업일수[[#This Row],[세부공종(B)]]="","",ROW()-ROW(T_검토1안작업일수[[#Headers],[순번]])) -> 9 | B12: 콘크리트공사 | C12: 펌프카 타설(TypeⅡ/Ⅰ) | D12: =469+687+80+671+1370 -> 3277 | E12: =IF($C12="","",IFERROR(VLOOKUP(SUBSTITUTE($C12,"~","~~"),'(참고1)_1일작업량'!$B:$E,2,0),"")) -> ㎥ | F12: =IF($C12="","",IFERROR(VLOOKUP(SUBSTITUTE($C12,"~","~~"),'(참고1)_1일작업량'!$B:$E,3,0),"")) -> 182 | G12: 1 | H12: =IF(OR($F12="",$G12=""),"",$F12*$G12) -> 182 | I12: =IF(OR($H12="",$H12=0,$D12=""),"",ROUNDUP($D12/$H12,0)) -> 19 | J12: Y | K12: =IF($I12="","",IF($J12="Y",$I12,0)) -> 19 | L12: =IF($C12="","",IFERROR(IF(VLOOKUP(SUBSTITUTE($C12,"~","~~"),'(참고1)_1일작업량'!$B:$E,4,0)=0,"",VLOOKUP(SUBSTITUTE($C12,"~","~~"),'(참고1)_1일작업량'!$B:$E,4,0)),"")) -> 슬럼프15 시설Type-Ⅱ/현장Type-Ⅰ, 펌프차1대
A13: =IF(T_검토1안작업일수[[#This Row],[세부공종(B)]]="","",ROW()-ROW(T_검토1안작업일수[[#Headers],[순번]])) -> 10 | B13: 콘크리트공사 | C13: 펌프카 타설(무근구조물) | D13: =82+105 -> 187 | E13: =IF($C13="","",IFERROR(VLOOKUP(SUBSTITUTE($C13,"~","~~"),'(참고1)_1일작업량'!$B:$E,2,0),"")) -> ㎥ | F13: =IF($C13="","",IFERROR(VLOOKUP(SUBSTITUTE($C13,"~","~~"),'(참고1)_1일작업량'!$B:$E,3,0),"")) -> 189 | G13: 1 | H13: =IF(OR($F13="",$G13=""),"",$F13*$G13) -> 189 | I13: =IF(OR($H13="",$H13=0,$D13=""),"",ROUNDUP($D13/$H13,0)) -> 1 | J13: Y | K13: =IF($I13="","",IF($J13="Y",$I13,0)) -> 1 | L13: =IF($C13="","",IFERROR(IF(VLOOKUP(SUBSTITUTE($C13,"~","~~"),'(참고1)_1일작업량'!$B:$E,4,0)=0,"",VLOOKUP(SUBSTITUTE($C13,"~","~~"),'(참고1)_1일작업량'!$B:$E,4,0)),"")) -> 펌프차80㎥/hr↑ 슬럼프15, 콘크리트공4·특별2·보통1
A14: =IF(T_검토1안작업일수[[#This Row],[세부공종(B)]]="","",ROW()-ROW(T_검토1안작업일수[[#Headers],[순번]])) -> 11 | B14: 철골공사 | C14: 철골 현장세우기 | D14: 3 | E14: =IF($C14="","",IFERROR(VLOOKUP(SUBSTITUTE($C14,"~","~~"),'(참고1)_1일작업량'!$B:$E,2,0),"")) -> ton | F14: =IF($C14="","",IFERROR(VLOOKUP(SUBSTITUTE($C14,"~","~~"),'(참고1)_1일작업량'!$B:$E,3,0),"")) -> 11.3 | G14: 1 | H14: =IF(OR($F14="",$G14=""),"",$F14*$G14) -> 11.3 | I14: =IF(OR($H14="",$H14=0,$D14=""),"",ROUNDUP($D14/$H14,0)) -> 1 | J14: Y | K14: =IF($I14="","",IF($J14="Y",$I14,0)) -> 1 | L14: =IF($C14="","",IFERROR(IF(VLOOKUP(SUBSTITUTE($C14,"~","~~"),'(참고1)_1일작업량'!$B:$E,4,0)=0,"",VLOOKUP(SUBSTITUTE($C14,"~","~~"),'(참고1)_1일작업량'!$B:$E,4,0)),"")) -> 20층미만, 가공완료 철골 현장설치, 철골공5·비계공2·특별1·크레인1대
A15: =IF(T_검토1안작업일수[[#This Row],[세부공종(B)]]="","",ROW()-ROW(T_검토1안작업일수[[#Headers],[순번]])) -> 12 | B15: 조적공사 | C15: 벽돌쌓기(0.5B) | D15: =220+5+8+98+11+370 -> 712 | E15: =IF($C15="","",IFERROR(VLOOKUP(SUBSTITUTE($C15,"~","~~"),'(참고1)_1일작업량'!$B:$E,2,0),"")) -> ㎡ | F15: =IF($C15="","",IFERROR(VLOOKUP(SUBSTITUTE($C15,"~","~~"),'(참고1)_1일작업량'!$B:$E,3,0),"")) -> 27 | G15: 1 | H15: =IF(OR($F15="",$G15=""),"",$F15*$G15) -> 27 | I15: =IF(OR($H15="",$H15=0,$D15=""),"",ROUNDUP($D15/$H15,0)) -> 27 | J15: Y | K15: =IF($I15="","",IF($J15="Y",$I15,0)) -> 27 | L15: =IF($C15="","",IFERROR(IF(VLOOKUP(SUBSTITUTE($C15,"~","~~"),'(참고1)_1일작업량'!$B:$E,4,0)=0,"",VLOOKUP(SUBSTITUTE($C15,"~","~~"),'(참고1)_1일작업량'!$B:$E,4,0)),"")) -> 시멘트벽돌(19×9×5.7), 3.6m이하, 조적공3·보통1
A16: =IF(T_검토1안작업일수[[#This Row],[세부공종(B)]]="","",ROW()-ROW(T_검토1안작업일수[[#Headers],[순번]])) -> 13 | B16: 미장공사 | C16: 시멘트 모르타르 바름 | D16: =652+115+37+754+1882+128 -> 3568 | E16: =IF($C16="","",IFERROR(VLOOKUP(SUBSTITUTE($C16,"~","~~"),'(참고1)_1일작업량'!$B:$E,2,0),"")) -> ㎡ | F16: =IF($C16="","",IFERROR(VLOOKUP(SUBSTITUTE($C16,"~","~~"),'(참고1)_1일작업량'!$B:$E,3,0),"")) -> 42 | G16: 4 | H16: =IF(OR($F16="",$G16=""),"",$F16*$G16) -> 168 | I16: =IF(OR($H16="",$H16=0,$D16=""),"",ROUNDUP($D16/$H16,0)) -> 22 | J16: Y | K16: =IF($I16="","",IF($J16="Y",$I16,0)) -> 22 | L16: =IF($C16="","",IFERROR(IF(VLOOKUP(SUBSTITUTE($C16,"~","~~"),'(참고1)_1일작업량'!$B:$E,4,0)=0,"",VLOOKUP(SUBSTITUTE($C16,"~","~~"),'(참고1)_1일작업량'!$B:$E,4,0)),"")) -> 24mm이하/2회 쇠흙손, 미장공3·보통1
A17: =IF(T_검토1안작업일수[[#This Row],[세부공종(B)]]="","",ROW()-ROW(T_검토1안작업일수[[#Headers],[순번]])) -> 14 | B17: 미장공사 | C17: 콘크리트면 마무리 | D17: =160+57+624+172 -> 1013 | E17: =IF($C17="","",IFERROR(VLOOKUP(SUBSTITUTE($C17,"~","~~"),'(참고1)_1일작업량'!$B:$E,2,0),"")) -> ㎡ | F17: =IF($C17="","",IFERROR(VLOOKUP(SUBSTITUTE($C17,"~","~~"),'(참고1)_1일작업량'!$B:$E,3,0),"")) -> 17 | G17: 2 | H17: =IF(OR($F17="",$G17=""),"",$F17*$G17) -> 34 | I17: =IF(OR($H17="",$H17=0,$D17=""),"",ROUNDUP($D17/$H17,0)) -> 30 | J17: Y | K17: =IF($I17="","",IF($J17="Y",$I17,0)) -> 30 | L17: =IF($C17="","",IFERROR(IF(VLOOKUP(SUBSTITUTE($C17,"~","~~"),'(참고1)_1일작업량'!$B:$E,4,0)=0,"",VLOOKUP(SUBSTITUTE($C17,"~","~~"),'(참고1)_1일작업량'!$B:$E,4,0)),"")) -> 연마기 면정리, 미장공3·견출1·보통1
A18: =IF(T_검토1안작업일수[[#This Row],[세부공종(B)]]="","",ROW()-ROW(T_검토1안작업일수[[#Headers],[순번]])) -> 15 | B18: 방수공사 | C18: 시멘트 액체방수 | D18: =331+163+623+218 -> 1335 | E18: =IF($C18="","",IFERROR(VLOOKUP(SUBSTITUTE($C18,"~","~~"),'(참고1)_1일작업량'!$B:$E,2,0),"")) -> ㎡ | F18: =IF($C18="","",IFERROR(VLOOKUP(SUBSTITUTE($C18,"~","~~"),'(참고1)_1일작업량'!$B:$E,3,0),"")) -> 40 | G18: 2 | H18: =IF(OR($F18="",$G18=""),"",$F18*$G18) -> 80 | I18: =IF(OR($H18="",$H18=0,$D18=""),"",ROUNDUP($D18/$H18,0)) -> 17 | J18: Y | K18: =IF($I18="","",IF($J18="Y",$I18,0)) -> 17 | L18: =IF($C18="","",IFERROR(IF(VLOOKUP(SUBSTITUTE($C18,"~","~~"),'(참고1)_1일작업량'!$B:$E,4,0)=0,"",VLOOKUP(SUBSTITUTE($C18,"~","~~"),'(참고1)_1일작업량'!$B:$E,4,0)),"")) -> 시멘트페이스트 1·2차 바닥, 방수공3·보통1
A19: =IF(T_검토1안작업일수[[#This Row],[세부공종(B)]]="","",ROW()-ROW(T_검토1안작업일수[[#Headers],[순번]])) -> 16 | B19: 방수공사 | C19: 도막방수 | D19: =669+764 -> 1433 | E19: =IF($C19="","",IFERROR(VLOOKUP(SUBSTITUTE($C19,"~","~~"),'(참고1)_1일작업량'!$B:$E,2,0),"")) -> ㎡ | F19: =IF($C19="","",IFERROR(VLOOKUP(SUBSTITUTE($C19,"~","~~"),'(참고1)_1일작업량'!$B:$E,3,0),"")) -> 200 | G19: 1 | H19: =IF(OR($F19="",$G19=""),"",$F19*$G19) -> 200 | I19: =IF(OR($H19="",$H19=0,$D19=""),"",ROUNDUP($D19/$H19,0)) -> 8 | J19: Y | K19: =IF($I19="","",IF($J19="Y",$I19,0)) -> 8 | L19: =IF($C19="","",IFERROR(IF(VLOOKUP(SUBSTITUTE($C19,"~","~~"),'(참고1)_1일작업량'!$B:$E,4,0)=0,"",VLOOKUP(SUBSTITUTE($C19,"~","~~"),'(참고1)_1일작업량'!$B:$E,4,0)),"")) -> 도막 1회 바닥, 방수공3·보통1
A20: =IF(T_검토1안작업일수[[#This Row],[세부공종(B)]]="","",ROW()-ROW(T_검토1안작업일수[[#Headers],[순번]])) -> 17 | B20: 타일공사 | C20: 압착붙이기(바닥) | D20: =166+133 -> 299 | E20: =IF($C20="","",IFERROR(VLOOKUP(SUBSTITUTE($C20,"~","~~"),'(참고1)_1일작업량'!$B:$E,2,0),"")) -> ㎡ | F20: =IF($C20="","",IFERROR(VLOOKUP(SUBSTITUTE($C20,"~","~~"),'(참고1)_1일작업량'!$B:$E,3,0),"")) -> 27 | G20: 1 | H20: =IF(OR($F20="",$G20=""),"",$F20*$G20) -> 27 | I20: =IF(OR($H20="",$H20=0,$D20=""),"",ROUNDUP($D20/$H20,0)) -> 12 | J20: Y | K20: =IF($I20="","",IF($J20="Y",$I20,0)) -> 12 | L20: =IF($C20="","",IFERROR(IF(VLOOKUP(SUBSTITUTE($C20,"~","~~"),'(참고1)_1일작업량'!$B:$E,4,0)=0,"",VLOOKUP(SUBSTITUTE($C20,"~","~~"),'(참고1)_1일작업량'!$B:$E,4,0)),"")) -> 0.11~0.20㎡ 바닥, 타일공3·보통1·줄눈1
A21: =IF(T_검토1안작업일수[[#This Row],[세부공종(B)]]="","",ROW()-ROW(T_검토1안작업일수[[#Headers],[순번]])) -> 18 | B21: 타일공사 | C21: 떠붙이기(벽) | D21: =280+382 -> 662 | E21: =IF($C21="","",IFERROR(VLOOKUP(SUBSTITUTE($C21,"~","~~"),'(참고1)_1일작업량'!$B:$E,2,0),"")) -> ㎡ | F21: =IF($C21="","",IFERROR(VLOOKUP(SUBSTITUTE($C21,"~","~~"),'(참고1)_1일작업량'!$B:$E,3,0),"")) -> 21 | G21: 2 | H21: =IF(OR($F21="",$G21=""),"",$F21*$G21) -> 42 | I21: =IF(OR($H21="",$H21=0,$D21=""),"",ROUNDUP($D21/$H21,0)) -> 16 | J21: Y | K21: =IF($I21="","",IF($J21="Y",$I21,0)) -> 16 | L21: =IF($C21="","",IFERROR(IF(VLOOKUP(SUBSTITUTE($C21,"~","~~"),'(참고1)_1일작업량'!$B:$E,4,0)=0,"",VLOOKUP(SUBSTITUTE($C21,"~","~~"),'(참고1)_1일작업량'!$B:$E,4,0)),"")) -> 0.11~0.20㎡ 벽면, 타일공3·보통1·줄눈1
A22: =IF(T_검토1안작업일수[[#This Row],[세부공종(B)]]="","",ROW()-ROW(T_검토1안작업일수[[#Headers],[순번]])) -> 19 | B22: 창호유리공사 | C22: 창호유리 설치 | D22: =24+312+101+8+95+263+22+16 -> 841 | E22: =IF($C22="","",IFERROR(VLOOKUP(SUBSTITUTE($C22,"~","~~"),'(참고1)_1일작업량'!$B:$E,2,0),"")) -> ㎡ | F22: =IF($C22="","",IFERROR(VLOOKUP(SUBSTITUTE($C22,"~","~~"),'(참고1)_1일작업량'!$B:$E,3,0),"")) -> 42 | G22: 1 | H22: =IF(OR($F22="",$G22=""),"",$F22*$G22) -> 42 | I22: =IF(OR($H22="",$H22=0,$D22=""),"",ROUNDUP($D22/$H22,0)) -> 21 | J22: Y | K22: =IF($I22="","",IF($J22="Y",$I22,0)) -> 21 | L22: =IF($C22="","",IFERROR(IF(VLOOKUP(SUBSTITUTE($C22,"~","~~"),'(참고1)_1일작업량'!$B:$E,4,0)=0,"",VLOOKUP(SUBSTITUTE($C22,"~","~~"),'(참고1)_1일작업량'!$B:$E,4,0)),"")) -> 복층유리 18mm이하, 유리공5·보통1
A23: =IF(T_검토1안작업일수[[#This Row],[세부공종(B)]]="","",ROW()-ROW(T_검토1안작업일수[[#Headers],[순번]])) -> 20 | B23: 수장공사 | C23: 칸막이벽틀 | D23: =541+4+5+11+529+147+4+5+31+163+31 -> 1471 | E23: =IF($C23="","",IFERROR(VLOOKUP(SUBSTITUTE($C23,"~","~~"),'(참고1)_1일작업량'!$B:$E,2,0),"")) -> ㎡ | F23: =IF($C23="","",IFERROR(VLOOKUP(SUBSTITUTE($C23,"~","~~"),'(참고1)_1일작업량'!$B:$E,3,0),"")) -> 20 | G23: 4 | H23: =IF(OR($F23="",$G23=""),"",$F23*$G23) -> 80 | I23: =IF(OR($H23="",$H23=0,$D23=""),"",ROUNDUP($D23/$H23,0)) -> 19 | J23: Y | K23: =IF($I23="","",IF($J23="Y",$I23,0)) -> 19 | L23: =IF($C23="","",IFERROR(IF(VLOOKUP(SUBSTITUTE($C23,"~","~~"),'(참고1)_1일작업량'!$B:$E,4,0)=0,"",VLOOKUP(SUBSTITUTE($C23,"~","~~"),'(참고1)_1일작업량'!$B:$E,4,0)),"")) -> 틀간격450~600mm, 건축목공2·보통1
A24: =IF(T_검토1안작업일수[[#This Row],[세부공종(B)]]="","",ROW()-ROW(T_검토1안작업일수[[#Headers],[순번]])) -> 21 | B24: 수장공사 | C24: 목재데크틀 설치 | D24: 156 | E24: =IF($C24="","",IFERROR(VLOOKUP(SUBSTITUTE($C24,"~","~~"),'(참고1)_1일작업량'!$B:$E,2,0),"")) -> ton | F24: =IF($C24="","",IFERROR(VLOOKUP(SUBSTITUTE($C24,"~","~~"),'(참고1)_1일작업량'!$B:$E,3,0),"")) -> 0.9 | G24: 1 | H24: =IF(OR($F24="",$G24=""),"",$F24*$G24) -> 0.9 | I24: =IF(OR($C24="",$F24=""),"",$F24) -> 0.9 | J24: Y | K24: =IF($I24="","",IF($J24="Y",$I24,0)) -> 0.9 | L24: =IF($C24="","",IFERROR(IF(VLOOKUP(SUBSTITUTE($C24,"~","~~"),'(참고1)_1일작업량'!$B:$E,4,0)=0,"",VLOOKUP(SUBSTITUTE($C24,"~","~~"),'(참고1)_1일작업량'!$B:$E,4,0)),"")) -> 각관·형강 평구조, 철공8·용접공1·보통4
A25: =IF(T_검토1안작업일수[[#This Row],[세부공종(B)]]="","",ROW()-ROW(T_검토1안작업일수[[#Headers],[순번]])) -> 22 | B25: 수장공사 | C25: 목재데크 설치 | D25: 156 | E25: =IF($C25="","",IFERROR(VLOOKUP(SUBSTITUTE($C25,"~","~~"),'(참고1)_1일작업량'!$B:$E,2,0),"")) -> ㎡ | F25: =IF($C25="","",IFERROR(VLOOKUP(SUBSTITUTE($C25,"~","~~"),'(참고1)_1일작업량'!$B:$E,3,0),"")) -> 17 | G25: 1 | H25: =IF(OR($F25="",$G25=""),"",$F25*$G25) -> 17 | I25: =IF(OR($H25="",$H25=0,$D25=""),"",ROUNDUP($D25/$H25,0)) -> 10 | J25: Y | K25: =IF($I25="","",IF($J25="Y",$I25,0)) -> 10 | L25: =IF($C25="","",IFERROR(IF(VLOOKUP(SUBSTITUTE($C25,"~","~~"),'(참고1)_1일작업량'!$B:$E,4,0)=0,"",VLOOKUP(SUBSTITUTE($C25,"~","~~"),'(참고1)_1일작업량'!$B:$E,4,0)),"")) -> 볼트고정 평구조, 건축목공3·보통1
A26: =IF(T_검토1안작업일수[[#This Row],[세부공종(B)]]="","",ROW()-ROW(T_검토1안작업일수[[#Headers],[순번]])) -> 23 | B26: 수장공사 | C26: 석고판 설치(천장) | D26: =321+190 -> 511 | E26: =IF($C26="","",IFERROR(VLOOKUP(SUBSTITUTE($C26,"~","~~"),'(참고1)_1일작업량'!$B:$E,2,0),"")) -> ㎡ | F26: =IF($C26="","",IFERROR(VLOOKUP(SUBSTITUTE($C26,"~","~~"),'(참고1)_1일작업량'!$B:$E,3,0),"")) -> 45 | G26: 1 | H26: =IF(OR($F26="",$G26=""),"",$F26*$G26) -> 45 | I26: =IF(OR($H26="",$H26=0,$D26=""),"",ROUNDUP($D26/$H26,0)) -> 12 | J26: Y | K26: =IF($I26="","",IF($J26="Y",$I26,0)) -> 12 | L26: =IF($C26="","",IFERROR(IF(VLOOKUP(SUBSTITUTE($C26,"~","~~"),'(참고1)_1일작업량'!$B:$E,4,0)=0,"",VLOOKUP(SUBSTITUTE($C26,"~","~~"),'(참고1)_1일작업량'!$B:$E,4,0)),"")) -> 나사고정 천장1겹, 내장공2·보통1
A27: =IF(T_검토1안작업일수[[#This Row],[세부공종(B)]]="","",ROW()-ROW(T_검토1안작업일수[[#Headers],[순번]])) -> 24 | B27: 도배바닥재 | C27: 바닥재 깔기(타일형) | D27: =754+2547 -> 3301 | E27: =IF($C27="","",IFERROR(VLOOKUP(SUBSTITUTE($C27,"~","~~"),'(참고1)_1일작업량'!$B:$E,2,0),"")) -> ㎡ | F27: =IF($C27="","",IFERROR(VLOOKUP(SUBSTITUTE($C27,"~","~~"),'(참고1)_1일작업량'!$B:$E,3,0),"")) -> 40 | G27: 3 | H27: =IF(OR($F27="",$G27=""),"",$F27*$G27) -> 120 | I27: =IF(OR($H27="",$H27=0,$D27=""),"",ROUNDUP($D27/$H27,0)) -> 28 | J27: Y | K27: =IF($I27="","",IF($J27="Y",$I27,0)) -> 28 | L27: =IF($C27="","",IFERROR(IF(VLOOKUP(SUBSTITUTE($C27,"~","~~"),'(참고1)_1일작업량'!$B:$E,4,0)=0,"",VLOOKUP(SUBSTITUTE($C27,"~","~~"),'(참고1)_1일작업량'!$B:$E,4,0)),"")) -> PVC계 타일형, 내장공2·보통1
A28: =IF(T_검토1안작업일수[[#This Row],[세부공종(B)]]="","",ROW()-ROW(T_검토1안작업일수[[#Headers],[순번]])) -> 25 | B28: 도배바닥재 | C28: 바닥재 깔기(마루) | D28: =23+47 -> 70 | E28: =IF($C28="","",IFERROR(VLOOKUP(SUBSTITUTE($C28,"~","~~"),'(참고1)_1일작업량'!$B:$E,2,0),"")) -> ㎡ | F28: =IF($C28="","",IFERROR(VLOOKUP(SUBSTITUTE($C28,"~","~~"),'(참고1)_1일작업량'!$B:$E,3,0),"")) -> 50 | G28: 1 | H28: =IF(OR($F28="",$G28=""),"",$F28*$G28) -> 50 | I28: =IF(OR($H28="",$H28=0,$D28=""),"",ROUNDUP($D28/$H28,0)) -> 2 | J28: Y | K28: =IF($I28="","",IF($J28="Y",$I28,0)) -> 2 | L28: =IF($C28="","",IFERROR(IF(VLOOKUP(SUBSTITUTE($C28,"~","~~"),'(참고1)_1일작업량'!$B:$E,4,0)=0,"",VLOOKUP(SUBSTITUTE($C28,"~","~~"),'(참고1)_1일작업량'!$B:$E,4,0)),"")) -> 플로어링 마루, 내장공2·보통1
A29: =IF(T_검토1안작업일수[[#This Row],[세부공종(B)]]="","",ROW()-ROW(T_검토1안작업일수[[#Headers],[순번]])) -> 26 | B29: 기계설비 | C29: 스테인리스강관(50mm·TIG) | D29: =316+122+263+112+38+52+31+25 -> 959 | E29: =IF($C29="","",IFERROR(VLOOKUP(SUBSTITUTE($C29,"~","~~"),'(참고1)_1일작업량'!$B:$E,2,0),"")) -> m | F29: =IF($C29="","",IFERROR(VLOOKUP(SUBSTITUTE($C29,"~","~~"),'(참고1)_1일작업량'!$B:$E,3,0),"")) -> 25.3 | G29: 2 | H29: =IF(OR($F29="",$G29=""),"",$F29*$G29) -> 50.6 | I29: =IF(OR($H29="",$H29=0,$D29=""),"",ROUNDUP($D29/$H29,0)) -> 19 | J29: Y | K29: =IF($I29="","",IF($J29="Y",$I29,0)) -> 19 | L29: =IF($C29="","",IFERROR(IF(VLOOKUP(SUBSTITUTE($C29,"~","~~"),'(참고1)_1일작업량'!$B:$E,4,0)=0,"",VLOOKUP(SUBSTITUTE($C29,"~","~~"),'(참고1)_1일작업량'!$B:$E,4,0)),"")) -> TIG용접, 배관공2·용접1·보통1
A30: =IF(T_검토1안작업일수[[#This Row],[세부공종(B)]]="","",ROW()-ROW(T_검토1안작업일수[[#Headers],[순번]])) -> 27 | B30: 조경공사 | C30: 식재(흉고8~9) | D30: 100 | E30: =IF($C30="","",IFERROR(VLOOKUP(SUBSTITUTE($C30,"~","~~"),'(참고1)_1일작업량'!$B:$E,2,0),"")) -> 주 | F30: =IF($C30="","",IFERROR(VLOOKUP(SUBSTITUTE($C30,"~","~~"),'(참고1)_1일작업량'!$B:$E,3,0),"")) -> 17 | G30: 1 | H30: =IF(OR($F30="",$G30=""),"",$F30*$G30) -> 17 | I30: =IF(OR($H30="",$H30=0,$D30=""),"",ROUNDUP($D30/$H30,0)) -> 6 | J30: Y | K30: =IF($I30="","",IF($J30="Y",$I30,0)) -> 6 | L30: =IF($C30="","",IFERROR(IF(VLOOKUP(SUBSTITUTE($C30,"~","~~"),'(참고1)_1일작업량'!$B:$E,4,0)=0,"",VLOOKUP(SUBSTITUTE($C30,"~","~~"),'(참고1)_1일작업량'!$B:$E,4,0)),"")) -> 근원9~11, 조경공3·보통1·굴삭기0.4
A31: =IF(T_검토1안작업일수[[#This Row],[세부공종(B)]]="","",ROW()-ROW(T_검토1안작업일수[[#Headers],[순번]])) | E31: =IF($C31="","",IFERROR(VLOOKUP(SUBSTITUTE($C31,"~","~~"),'(참고1)_1일작업량'!$B:$E,2,0),"")) | F31: =IF($C31="","",IFERROR(VLOOKUP(SUBSTITUTE($C31,"~","~~"),'(참고1)_1일작업량'!$B:$E,3,0),"")) | G31: 1 | H31: =IF(OR($F31="",$G31=""),"",$F31*$G31) | I31: =IF(OR($H31="",$H31=0,$D31=""),"",ROUNDUP($D31/$H31,0)) | K31: =IF($I31="","",IF($J31="Y",$I31,0)) | L31: =IF($C31="","",IFERROR(IF(VLOOKUP(SUBSTITUTE($C31,"~","~~"),'(참고1)_1일작업량'!$B:$E,4,0)=0,"",VLOOKUP(SUBSTITUTE($C31,"~","~~"),'(참고1)_1일작업량'!$B:$E,4,0)),""))
A32: =IF(T_검토1안작업일수[[#This Row],[세부공종(B)]]="","",ROW()-ROW(T_검토1안작업일수[[#Headers],[순번]])) | E32: =IF($C32="","",IFERROR(VLOOKUP(SUBSTITUTE($C32,"~","~~"),'(참고1)_1일작업량'!$B:$E,2,0),"")) | F32: =IF($C32="","",IFERROR(VLOOKUP(SUBSTITUTE($C32,"~","~~"),'(참고1)_1일작업량'!$B:$E,3,0),"")) | H32: =IF(OR($F32="",$G32=""),"",$F32*$G32) | I32: =IF(OR($H32="",$H32=0,$D32=""),"",ROUNDUP($D32/$H32,0)) | K32: =IF($I32="","",IF($J32="Y",$I32,0)) | L32: =IF($C32="","",IFERROR(IF(VLOOKUP(SUBSTITUTE($C32,"~","~~"),'(참고1)_1일작업량'!$B:$E,4,0)=0,"",VLOOKUP(SUBSTITUTE($C32,"~","~~"),'(참고1)_1일작업량'!$B:$E,4,0)),""))
A33: 순작업일수 ( 작업일수 = 주공정 CP 반영 소요일수 합계) | K33: =SUM(T_검토1안작업일수[CP반영 일수]) -> 398.9
A34: ※ 공종(A) 드롭박스 선택 → 세부공종(B) 연동 드롭박스 목록 자동 변경(공종값 기준)/ 세부공종 선택 → 단위·표준1일작업량·근거 자동 반영 ※ 주공정(CP)=Y 공종만 순작업일수에 합산(병행공종 미포함) /빈 행은 추가 입력으로 가능 /물량·투입조수는 노란셀 입력 ※ 부록4 미수록 공종(도장.전기·통신·소방 등)은 필요 시 표준품셈 별도 산정 ※ 공사기간 = 준비기간 + Σ(CP 공종별 공사기간=작업일수+비작업일수) + 정리기간 (가이드라인 본문 산정식)
A39: 표준품셈 방식 총 공사기간 산정표 (준비·정리기간 합산)
A40: 구분 | C40: 내용 | G40: 일수 (일) | I40: 비율 (%) | K40: 비고
A41: ① 준비기간 | C41: 설계도서 검토, 착공준비, 자재·장비 조달 등 | G41: =부록1_준비·정리기간!C5 -> 60 | I41: =IF($G$45=0,"",G41/$G$45) -> 0.098863075 | K41: 「부록1」 연동 · 고시 제7조
A42: ② 비작업일수 | C42: 법정공휴일 + 기상조건 비작업일 | G42: ='부록3 비작업일수'!N55 -> 118 | I42: =IF($G$45=0,"",G42/$G$45) -> 0.19443071 | K42: 「부록3」 연동 (공사기간 내 비작업일수 합계)
A43: ③ 작업일수 (순작업일수) | C43: 주공정(CP) 반영 소요일수 합계 | G43: =K33 -> 398.9 | I43: =IF($G$45=0,"",G43/$G$45) -> 0.65727467 | K43: 본 시트연동 (주공정 CP)
A44: ④ 정리기간 | C44: 준공검사 준비, 시설물 인수, 현장정리 등 | G44: =부록1_준비·정리기간!C10 -> 30 | I44: =IF($G$45=0,"",G44/$G$45) -> 0.049431537 | K44: 「부록1」 연동 · 고시 제12조
...

Sheet (검토1안-1)대시보드
B2: 공사기간 산정 검토 요약 대시보드(검토1안 전용)
B4: 총 공사기간 | F4: 작업일수 | J4: 비작업일수 | N4: 준비 + 정리
B5: ='(검토1안) 표준품셈 작업일수'!G45 -> 606.9 | F5: ='(검토1안) 표준품셈 작업일수'!G43 -> 398.9 | J5: ='(검토1안) 표준품셈 작업일수'!G42 -> 118 | N5: ='(검토1안) 표준품셈 작업일수'!G41+'(검토1안) 표준품셈 작업일수'!G44 -> 90
B6: ="약 "&TEXT('(검토1안) 표준품셈 작업일수'!I45,"0.0")&"개월" -> 약 20.2개월 | F6: ="전체의 "&TEXT('(검토1안) 표준품셈 작업일수'!G43/'(검토1안) 표준품셈 작업일수'!G45,"0.0%") -> 전체의 65.7% | J6: ="전체의 "&TEXT('(검토1안) 표준품셈 작업일수'!G42/'(검토1안) 표준품셈 작업일수'!G45,"0.0%") -> 전체의 19.4% | N6: ="전체의 "&TEXT(('(검토1안) 표준품셈 작업일수'!G41+'(검토1안) 표준품셈 작업일수'!G44)/'(검토1안) 표준품셈 작업일수'!G45,"0.0%") -> 전체의 14.8%
B7: ='(검토1안) 표준품셈 작업일수'!G45/'(검토1안) 표준품셈 작업일수'!G45 -> 1 | F7: ='(검토1안) 표준품셈 작업일수'!G43/'(검토1안) 표준품셈 작업일수'!G45 -> 0.65727467 | J7: ='(검토1안) 표준품셈 작업일수'!G42/'(검토1안) 표준품셈 작업일수'!G45 -> 0.19443071 | N7: =('(검토1안) 표준품셈 작업일수'!G41+'(검토1안) 표준품셈 작업일수'!G44)/'(검토1안) 표준품셈 작업일수'!G45 -> 0.14829461
B9: 공사기간 구성 비율
C11: 작업일수
C13: ="준비기간 "&TEXT('(검토1안) 표준품셈 작업일수'!G41,"#,##0")&"일" -> 준비기간 60일 | G13: ="작업일수 "&TEXT('(검토1안) 표준품셈 작업일수'!G43,"#,##0")&"일" -> 작업일수 399일 | K13: ="비작업일수 "&TEXT('(검토1안) 표준품셈 작업일수'!G42,"#,##0")&"일" -> 비작업일수 118일 | O13: ="정리기간 "&TEXT('(검토1안) 표준품셈 작업일수'!G44,"#,##0")&"일" -> 정리기간 30일
B16: 작업일수 — 공종별 산정 (주공정 기준)
B18: 공종별 작업일수 내역 | J18: 공종별 작업일수 비율
B19: 공종명 | F19: 수량 | G19: 1일작업량 | H19: 작업일수
B20: =IF('(검토1안) 표준품셈 작업일수'!C4="",'(검토1안) 표준품셈 작업일수'!B4,'(검토1안) 표준품셈 작업일수'!C4) -> 콘테이너형 가설건축물 설치 | F20: =TEXT('(검토1안) 표준품셈 작업일수'!D4,"#,##0")&" "&'(검토1안) 표준품셈 작업일수'!E4 -> 7 개 | G20: =TEXT('(검토1안) 표준품셈 작업일수'!H4,"#,##0")&" "&'(검토1안) 표준품셈 작업일수'!E4 -> 8 개 | H20: ='(검토1안) 표준품셈 작업일수'!I4 -> 1
B21: =IF('(검토1안) 표준품셈 작업일수'!C5="",'(검토1안) 표준품셈 작업일수'!B5,'(검토1안) 표준품셈 작업일수'!C5) -> 가설울타리(EGI휀스) 설치 | F21: =TEXT('(검토1안) 표준품셈 작업일수'!D5,"#,##0")&" "&'(검토1안) 표준품셈 작업일수'!E5 -> 430 m | G21: =TEXT('(검토1안) 표준품셈 작업일수'!H5,"#,##0")&" "&'(검토1안) 표준품셈 작업일수'!E5 -> 115 m | H21: ='(검토1안) 표준품셈 작업일수'!I5 -> 4
B22: =IF('(검토1안) 표준품셈 작업일수'!C6="",'(검토1안) 표준품셈 작업일수'!B6,'(검토1안) 표준품셈 작업일수'!C6) -> 시스템비계 설치·해체 | F22: =TEXT('(검토1안) 표준품셈 작업일수'!D6,"#,##0")&" "&'(검토1안) 표준품셈 작업일수'!E6 -> 3,791 ㎡ | G22: =TEXT('(검토1안) 표준품셈 작업일수'!H6,"#,##0")&" "&'(검토1안) 표준품셈 작업일수'!E6 -> 200 ㎡ | H22: ='(검토1안) 표준품셈 작업일수'!I6 -> 19
B23: =IF('(검토1안) 표준품셈 작업일수'!C7="",'(검토1안) 표준품셈 작업일수'!B7,'(검토1안) 표준품셈 작업일수'!C7) -> 강관동바리 설치·해체(건축) | F23: =TEXT('(검토1안) 표준품셈 작업일수'!D7,"#,##0")&" "&'(검토1안) 표준품셈 작업일수'!E7 -> 9,637 ㎡ | G23: =TEXT('(검토1안) 표준품셈 작업일수'!H7,"#,##0")&" "&'(검토1안) 표준품셈 작업일수'!E7 -> 400 ㎡ | H23: ='(검토1안) 표준품셈 작업일수'!I7 -> 25
B24: =IF('(검토1안) 표준품셈 작업일수'!C8="",'(검토1안) 표준품셈 작업일수'!B8,'(검토1안) 표준품셈 작업일수'!C8) -> 터파기(굴삭기1.0㎥·보통) | F24: =TEXT('(검토1안) 표준품셈 작업일수'!D8,"#,##0")&" "&'(검토1안) 표준품셈 작업일수'!E8 -> 3,284 ㎥ | G24: =TEXT('(검토1안) 표준품셈 작업일수'!H8,"#,##0")&" "&'(검토1안) 표준품셈 작업일수'!E8 -> 514 ㎥ | H24: ='(검토1안) 표준품셈 작업일수'!I8 -> 7
B25: =IF('(검토1안) 표준품셈 작업일수'!C9="",'(검토1안) 표준품셈 작업일수'!B9,'(검토1안) 표준품셈 작업일수'!C9) -> 철근 현장조립(건축 TypeⅡ) | F25: =TEXT('(검토1안) 표준품셈 작업일수'!D9,"#,##0")&" "&'(검토1안) 표준품셈 작업일수'!E9 -> 250 ton | G25: =TEXT('(검토1안) 표준품셈 작업일수'!H9,"#,##0")&" "&'(검토1안) 표준품셈 작업일수'!E9 -> 12 ton | H25: ='(검토1안) 표준품셈 작업일수'!I9 -> 21
B26: =IF('(검토1안) 표준품셈 작업일수'!C10="",'(검토1안) 표준품셈 작업일수'!B10,'(검토1안) 표준품셈 작업일수'!C10) -> 유로폼 설치(보통) | F26: =TEXT('(검토1안) 표준품셈 작업일수'!D10,"#,##0")&" "&'(검토1안) 표준품셈 작업일수'!E10 -> 9,452 ㎡ | G26: =TEXT('(검토1안) 표준품셈 작업일수'!H10,"#,##0")&" "&'(검토1안) 표준품셈 작업일수'!E10 -> 300 ㎡ | H26: ='(검토1안) 표준품셈 작업일수'!I10 -> 32
B27: =IF('(검토1안) 표준품셈 작업일수'!C11="",'(검토1안) 표준품셈 작업일수'!B11,'(검토1안) 표준품셈 작업일수'!C11) -> 합판거푸집 설치(보통) | F27: =TEXT('(검토1안) 표준품셈 작업일수'!D11,"#,##0")&" "&'(검토1안) 표준품셈 작업일수'!E11 -> 4,457 ㎡ | G27: =TEXT('(검토1안) 표준품셈 작업일수'!H11,"#,##0")&" "&'(검토1안) 표준품셈 작업일수'!E11 -> 240 ㎡ | H27: ='(검토1안) 표준품셈 작업일수'!I11 -> 19
B28: =IF('(검토1안) 표준품셈 작업일수'!C12="",'(검토1안) 표준품셈 작업일수'!B12,'(검토1안) 표준품셈 작업일수'!C12) -> 펌프카 타설(TypeⅡ/Ⅰ) | F28: =TEXT('(검토1안) 표준품셈 작업일수'!D12,"#,##0")&" "&'(검토1안) 표준품셈 작업일수'!E12 -> 3,277 ㎥ | G28: =TEXT('(검토1안) 표준품셈 작업일수'!H12,"#,##0")&" "&'(검토1안) 표준품셈 작업일수'!E12 -> 182 ㎥ | H28: ='(검토1안) 표준품셈 작업일수'!I12 -> 19
B29: =IF('(검토1안) 표준품셈 작업일수'!C13="",'(검토1안) 표준품셈 작업일수'!B13,'(검토1안) 표준품셈 작업일수'!C13) -> 펌프카 타설(무근구조물) | F29: =TEXT('(검토1안) 표준품셈 작업일수'!D13,"#,##0")&" "&'(검토1안) 표준품셈 작업일수'!E13 -> 187 ㎥ | G29: =TEXT('(검토1안) 표준품셈 작업일수'!H13,"#,##0")&" "&'(검토1안) 표준품셈 작업일수'!E13 -> 189 ㎥ | H29: ='(검토1안) 표준품셈 작업일수'!I13 -> 1
B30: =IF('(검토1안) 표준품셈 작업일수'!C14="",'(검토1안) 표준품셈 작업일수'!B14,'(검토1안) 표준품셈 작업일수'!C14) -> 철골 현장세우기 | F30: =TEXT('(검토1안) 표준품셈 작업일수'!D14,"#,##0")&" "&'(검토1안) 표준품셈 작업일수'!E14 -> 3 ton | G30: =TEXT('(검토1안) 표준품셈 작업일수'!H14,"#,##0")&" "&'(검토1안) 표준품셈 작업일수'!E14 -> 11 ton | H30: ='(검토1안) 표준품셈 작업일수'!I14 -> 1
B31: =IF('(검토1안) 표준품셈 작업일수'!C15="",'(검토1안) 표준품셈 작업일수'!B15,'(검토1안) 표준품셈 작업일수'!C15) -> 벽돌쌓기(0.5B) | F31: =TEXT('(검토1안) 표준품셈 작업일수'!D15,"#,##0")&" "&'(검토1안) 표준품셈 작업일수'!E15 -> 712 ㎡ | G31: =TEXT('(검토1안) 표준품셈 작업일수'!H15,"#,##0")&" "&'(검토1안) 표준품셈 작업일수'!E15 -> 27 ㎡ | H31: ='(검토1안) 표준품셈 작업일수'!I15 -> 27
... B41: =IF('(검토1안) 표준품셈 작업일수'!C25="",'(검토1안) 표준품셈 작업일수'!B25,'(검토1안) 표준품셈 작업일수'!C25) -> 목재데크 설치 | F41: =TEXT('(검토1안) 표준품셈 작업일수'!D25,"#,##0")&" "&'(검토1안) 표준품셈 작업일수'!E25 -> 156 ㎡ | G41: =TEXT('(검토1안) 표준품셈 작업일수'!H25,"#,##0")&" "&'(검토1안) 표준품셈 작업일수'!E25 -> 17 ㎡ | H41: ='(검토1안) 표준품셈 작업일수'!I25 -> 10
B43: 비작업일수 — 월별 산정 (전남·광주 기준)
B45: 비작업일수 구성 (전체 공사기간) | J45: 월별 비작업일수 (연간 프로파일 · 전남·광주) | Q45: 구성 | R45: 일수 | T45: ▼비작업 구성(공사기간 내)
Q46: 법정공휴일 | R46: =$T$46 -> 77 | T46: {=ROUND(SUMPRODUCT(((0*12+(COLUMN('부록3 비작업일수'!$C$10:$N$10)-2)-MONTH('부록3 비작업일수'!$C$3))>=0)*((0*12+(COLUMN('부록3 비작업일수'!$C$10:$N$10)-2)-MONTH('부록3 비작업일수'!$C$3))<'부록3 비작업일수'!$C$4)*'부록3 비작업일수'!$C$10:$N$10)+SUMPRODUCT(((1*12+(COLUMN('부록3 비작업일수'!$C$19:$N$19)-2)-MONTH('부록3 비작업일수'!$C$3))>=0)*((1*12+(COLUMN('부록3 비작업일수'!$C$19:$N$19)-2)-MONTH('부록3 비작업일수'!$C$3))<'부록3 비작업일수'!$C$4)*'부록3 비작업일수'!$C$19:$N$19)+SUMPRODUCT(((2*12+(COLUMN('부록3 비작업일수'!$C$28:$N$28)-2)-MONTH('부록3 비작업일수'!$C$3))>=0)*((2*12+(COLUMN('부록3 비작업일수'!$C$28:$N$28)-2)-MONTH('부록3 비작업일수'!$C$3))<'부록3 비작업일수'!$C$4)*'부록3 비작업일수'!$C$28:$N$28)+SUMPRODUCT(((3*12+(COLUMN('부록3 비작업일수'!$C$37:$N$37)-2)-MONTH('부록3 비작업일수'!$C$3))>=0)*((3*12+(COLUMN('부록3 비작업일수'!$C$37:$N$37)-2)-MONTH('부록3 비작업일수'!$C$3))<'부록3 비작업일수'!$C$4)*'부록3 비작업일수'!$C$37:$N$37)+SUMPRODUCT(((4*12+(COLUMN('부록3 비작업일수'!$C$46:$N$46)-2)-MONTH('부록3 비작업일수'!$C$3))>=0)*((4*12+(COLUMN('부록3 비작업일수'!$C$46:$N$46)-2)-MONTH('부록3 비작업일수'!$C$3))<'부록3 비작업일수'!$C$4)*'부록3 비작업일수'!$C$46:$N$46),0)} -> 77
E47: ■ 법정공휴일 | G47: =$T$46 -> 77 | Q47: 기상 비작업 | R47: =$T$47 -> 30 | T47: {=ROUND(SUMPRODUCT(((0*12+(COLUMN('부록3 비작업일수'!$C$11:$N$11)-2)-MONTH('부록3 비작업일수'!$C$3))>=0)*((0*12+(COLUMN('부록3 비작업일수'!$C$11:$N$11)-2)-MONTH('부록3 비작업일수'!$C$3))<'부록3 비작업일수'!$C$4)*'부록3 비작업일수'!$C$11:$N$11)+SUMPRODUCT(((1*12+(COLUMN('부록3 비작업일수'!$C$20:$N$20)-2)-MONTH('부록3 비작업일수'!$C$3))>=0)*((1*12+(COLUMN('부록3 비작업일수'!$C$20:$N$20)-2)-MONTH('부록3 비작업일수'!$C$3))<'부록3 비작업일수'!$C$4)*'부록3 비작업일수'!$C$20:$N$20)+SUMPRODUCT(((2*12+(COLUMN('부록3 비작업일수'!$C$29:$N$29)-2)-MONTH('부록3 비작업일수'!$C$3))>=0)*((2*12+(COLUMN('부록3 비작업일수'!$C$29:$N$29)-2)-MONTH('부록3 비작업일수'!$C$3))<'부록3 비작업일수'!$C$4)*'부록3 비작업일수'!$C$29:$N$29)+SUMPRODUCT(((3*12+(COLUMN('부록3 비작업일수'!$C$38:$N$38)-2)-MONTH('부록3 비작업일수'!$C$3))>=0)*((3*12+(COLUMN('부록3 비작업일수'!$C$38:$N$38)-2)-MONTH('부록3 비작업일수'!$C$3))<'부록3 비작업일수'!$C$4)*'부록3 비작업일수'!$C$38:$N$38)+SUMPRODUCT(((4*12+(COLUMN('부록3 비작업일수'!$C$47:$N$47)-2)-MONTH('부록3 비작업일수'!$C$3))>=0)*((4*12+(COLUMN('부록3 비작업일수'!$C$47:$N$47)-2)-MONTH('부록3 비작업일수'!$C$3))<'부록3 비작업일수'!$C$4)*'부록3 비작업일수'!$C$47:$N$47),0)} -> 30
T48: {=ROUND(SUMPRODUCT(((0*12+(COLUMN('부록3 비작업일수'!$C$12:$N$12)-2)-MONTH('부록3 비작업일수'!$C$3))>=0)*((0*12+(COLUMN('부록3 비작업일수'!$C$12:$N$12)-2)-MONTH('부록3 비작업일수'!$C$3))<'부록3 비작업일수'!$C$4)*'부록3 비작업일수'!$C$12:$N$12)+SUMPRODUCT(((1*12+(COLUMN('부록3 비작업일수'!$C$21:$N$21)-2)-MONTH('부록3 비작업일수'!$C$3))>=0)*((1*12+(COLUMN('부록3 비작업일수'!$C$21:$N$21)-2)-MONTH('부록3 비작업일수'!$C$3))<'부록3 비작업일수'!$C$4)*'부록3 비작업일수'!$C$21:$N$21)+SUMPRODUCT(((2*12+(COLUMN('부록3 비작업일수'!$C$30:$N$30)-2)-MONTH('부록3 비작업일수'!$C$3))>=0)*((2*12+(COLUMN('부록3 비작업일수'!$C$30:$N$30)-2)-MONTH('부록3 비작업일수'!$C$3))<'부록3 비작업일수'!$C$4)*'부록3 비작업일수'!$C$30:$N$30)+SUMPRODUCT(((3*12+(COLUMN('부록3 비작업일수'!$C$39:$N$39)-2)-MONTH('부록3 비작업일수'!$C$3))>=0)*((3*12+(COLUMN('부록3 비작업일수'!$C$39:$N$39)-2)-MONTH('부록3 비작업일수'!$C$3))<'부록3 비작업일수'!$C$4)*'부록3 비작업일수'!$C$39:$N$39)+SUMPRODUCT(((4*12+(COLUMN('부록3 비작업일수'!$C$48:$N$48)-2)-MONTH('부록3 비작업일수'!$C$3))>=0)*((4*12+(COLUMN('부록3 비작업일수'!$C$48:$N$48)-2)-MONTH('부록3 비작업일수'!$C$3))<'부록3 비작업일수'!$C$4)*'부록3 비작업일수'!$C$48:$N$48),0)} -> 5
E49: ■ 기상 비작업 | G49: =$T$47 -> 30
E51: ■ 중복 차감 | G51: =-$T$48 -> -5
E53: ■ 적용(순) | G53: ='부록3 비작업일수'!N55 -> 118
E55: 고시 제8~10조 · 주40시간 하한 적용
B56: 산정 공식 (고시 제8조①) 비작업일수 = A(기상) + B(법정공휴일) − C(중복일수) ※ 월별 비작업일수 ≥ 주40시간 근무제(월 8일)
B57: ="A(기상) "&TEXT($T$47,"#,##0")&"일 + B(법정공휴일) "&TEXT($T$46,"#,##0")&"일 − C(중복) "&TEXT($T$48,"#,##0")&"일 → 적용(주40H 하한 반영) "&TEXT('부록3 비작업일수'!N55,"#,##0")&"일 · 전체 공사기간 "&TEXT('부록3 비작업일수'!C4,"0.0")&"개월" -> A(기상) 30일 + B(법정공휴일) 77일 − C(중복) 5일 → 적용(주40H 하한 반영) 118일 · 전체 공사기간 12.6개월
B58: ▼ 차트 데이터 — 공종별 작업일수 집계 (SUMIF)
B59: 공종 | C59: 작업일수 | E59: 공종 (작업일수 5일 이상 · 전체) | F59: 작업일수
B60: 기계설비 | C60: =SUMIF('(검토1안) 표준품셈 작업일수'!$B$4:$B$25,B60,'(검토1안) 표준품셈 작업일수'!$I$4:$I$25) -> 0 | E60: {=_xlfn._xlws.SORT(_xlfn._xlws.FILTER(V60:W85,(W60:W85>=5)*(V60:V85<>"")),2,-1)} -> 미장공사 | F60: 52 | V60: {=_xlfn.UNIQUE(_xlfn._xlws.FILTER('(검토1안) 표준품셈 작업일수'!$B$4:$B$38,'(검토1안) 표준품셈 작업일수'!$B$4:$B$38<>""))} -> 가설공사 | W60: {=SUMIF('(검토1안) 표준품셈 작업일수'!$B$4:$B$38,_xlfn.ANCHORARRAY(V60),'(검토1안) 표준품셈 작업일수'!$I$4:$I$38)} -> 49
B61: 거푸집공사 | C61: =SUMIF('(검토1안) 표준품셈 작업일수'!$B$4:$B$25,B61,'(검토1안) 표준품셈 작업일수'!$I$4:$I$25) -> 51 | E61: 거푸집공사 | F61: 51 | V61: 토공사 | W61: 7
B62: 타일공사 | C62: =SUMIF('(검토1안) 표준품셈 작업일수'!$B$4:$B$25,B62,'(검토1안) 표준품셈 작업일수'!$I$4:$I$25) -> 28 | E62: 가설공사 | F62: 49 | V62: 철근공사 | W62: 21
...

Sheet (검토2안) 공사기간
A1: [검토2안] 공사기간(작업일수) 산정
A2: ※ 노란색 셀에 입력하십시오.
A3: 구분 | D3: 공종 | F3: 기준 | G3: 기준 (일) | H3: 해당여부 | I3: 공사기간(일) | J3: 비고
A4: 공사준비 | D4: 착공 등 | F4: 10억원 미만 | G4: 10 | H4: =IF('1. 기본정보'!$C$4<10,"O","X") -> X | I4: =IF(H4="O",G4,0) -> 0
F5: 10억원 이상 | G5: 20 | H5: =IF('1. 기본정보'!$C$4>=10,"O","X") -> O | I5: =IF(H5="O",G5,0) -> 20
F6: 안전관리계획서 제출 대상 | G6: 45 | H6: O | I6: =IF(H6="O",G6,0) -> 45
A7: 토목공사 | D7: 터파기 | F7: 지하1층당 | G7: 10 | H7: X | I7: =IF(H7="O",G7,0) -> 0
D8: 흙막이 | F8: 자립식, 1층당 | G8: 10 | H8: X | I8: =IF(H8="O",G8,0) -> 0
F9: 어스앵커, 1층당 | G9: 20 | H9: X | I9: =IF(H9="O",G9,0) -> 0
A10: 건축 | B10: 기초공사 | D10: 파일기초 | F10: 깊이15m 이하 선굴착말뚝공법 | G10: 40 | H10: X | I10: =IF(H10="O",G10,0) -> 0
F11: 깊이15m 이상 선굴착말뚝공법 | G11: 80 | H11: X | I11: =IF(H11="O",G11,0) -> 0
D12: 지지력시험 | G12: 11 | H12: O | I12: =IF(H12="O",G12,0) -> 11
B13: 골 조 공 사 | C13: 지 하 층 | D13: 지하층 | F13: 지하1층당 | G13: 31 | H13: =VALUE(LEFT('1. 기본정보'!$C$6,FIND("/",'1. 기본정보'!$C$6)-1))&"층" -> 0층 | I13: =IFERROR(G13*VALUE(SUBSTITUTE(H13,"층","")),0) -> 0
D14: 지하주차장 | F14: 1개층 주차대수 150대 미만 | G14: 10 | H14: X | I14: =IF(H14="O",G14,0) -> 0
F15: 1개층 주차대수 150대 이상 | G15: 20 | H15: X | I15: =IF(H15="O",G15,0) -> 0
C16: 지 상 층 | D16: 골조 | E16: 1층 | F16: 1층 | G16: 30 | H16: =IF(VALUE(MID('1. 기본정보'!$C$6,FIND("/",'1. 기본정보'!$C$6)+1,10))>=1,"1층","-") -> 1층 | I16: =IF(H16="1층",G16,0) -> 30
E17: 2층이상 | F17: 2층이상 | G17: 21 | H17: =VALUE(MID('1. 기본정보'!$C$6,FIND("/",'1. 기본정보'!$C$6)+1,10))&"층" -> 4층 | I17: =IFERROR(G17*(VALUE(SUBSTITUTE(H17,"층",""))-1),0) -> 63
E18: 동절기보정 | F18: 층당 | G18: 1 | H18: =VALUE(MID('1. 기본정보'!$C$6,FIND("/",'1. 기본정보'!$C$6)+1,10))&"층" -> 4층 | I18: =IFERROR(G18*VALUE(SUBSTITUTE(H18,"층","")),0) -> 4
D19: 지붕 | F19: 콘크리트 경사지붕 | G19: 15 | H19: =IF('1. 기본정보'!$C$7=F19,"O","X") -> X | I19: =IF(H19="O",G19,0) -> 0
F20: 콘크리트 평지붕 | G20: 12 | H20: =IF('1. 기본정보'!$C$7=F20,"O","X") -> O | I20: =IF(H20="O",G20,0) -> 12
F21: 철골경사지붕 | G21: 10 | H21: =IF('1. 기본정보'!$C$7=F21,"O","X") -> X | I21: =IF(H21="O",G21,0) -> 0
B22: 마감공사 | F22: 조적공사, 층당 | G22: 5 | H22: =VALUE(MID('1. 기본정보'!$C$6,FIND("/",'1. 기본정보'!$C$6)+1,10))&"층" -> 4층 | I22: =IFERROR(G22*VALUE(SUBSTITUTE(H22,"층","")),0) -> 20
F23: 미장공사, 층당 | G23: 7 | H23: =VALUE(MID('1. 기본정보'!$C$6,FIND("/",'1. 기본정보'!$C$6)+1,10))&"층" -> 4층 | I23: =IFERROR(G23*VALUE(SUBSTITUTE(H23,"층","")),0) -> 28
F24: 창호공사, 층당 | G24: 6 | H24: =VALUE(MID('1. 기본정보'!$C$6,FIND("/",'1. 기본정보'!$C$6)+1,10))&"층" -> 4층 | I24: =IFERROR(G24*VALUE(SUBSTITUTE(H24,"층","")),0) -> 24
F25: 방수공사, 층당 | G25: 3 | H25: =VALUE(MID('1. 기본정보'!$C$6,FIND("/",'1. 기본정보'!$C$6)+1,10))&"층" -> 4층 | I25: =IFERROR(G25*VALUE(SUBSTITUTE(H25,"층","")),0) -> 12
F26: 타일공사, 층당 | G26: 2 | H26: =VALUE(MID('1. 기본정보'!$C$6,FIND("/",'1. 기본정보'!$C$6)+1,10))&"층" -> 4층 | I26: =IFERROR(G26*VALUE(SUBSTITUTE(H26,"층","")),0) -> 8
F27: 내장공사, 층당 | G27: 7 | H27: =VALUE(MID('1. 기본정보'!$C$6,FIND("/",'1. 기본정보'!$C$6)+1,10))&"층" -> 4층 | I27: =IFERROR(G27*VALUE(SUBSTITUTE(H27,"층","")),0) -> 28
F28: 도장공사, 층당 | G28: 3 | H28: =VALUE(MID('1. 기본정보'!$C$6,FIND("/",'1. 기본정보'!$C$6)+1,10))&"층" -> 4층 | I28: =IFERROR(G28*VALUE(SUBSTITUTE(H28,"층","")),0) -> 12
A29: 토목, 조경공사 | F29: 토목공사: 건축공사 완료 후 | G29: 15 | H29: ='1. 기본정보'!$C$15 -> 해당 | I29: =IF(H29="해당",G29,0) -> 15
F30: 조경공사: 토목공사 완료 후 | G30: 15 | H30: ='1. 기본정보'!$C$16 -> 해당 | I30: =IF(H30="해당",G30,0) -> 15
A31: 철거공사 | F31: 건물철거, 90㎡ 당 | G31: 1 | H31: =IF(IFERROR(VALUE('1. 기본정보'!$C$13),0)>0,"O","X") -> X | I31: =IF(H31="O",G31*ROUNDUP(IFERROR(VALUE('1. 기본정보'!$C$13),0)/90,0),0) -> 0
F32: 마감재철거, 90㎡ 당 | G32: 1 | H32: =IF(IFERROR(VALUE('1. 기본정보'!$C$13),0)>0,"O","X") -> X | I32: =IF(H32="O",G32*ROUNDUP(IFERROR(VALUE('1. 기본정보'!$C$13),0)/90,0),0) -> 0
F33: 석면철거, 400㎡ 당 | G33: 7 | H33: =IF(IFERROR(VALUE('1. 기본정보'!$C$14),0)>0,"O","X") -> X | I33: =IF(H33="O",G33+MAX(ROUNDUP(IFERROR(VALUE('1. 기본정보'!$C$14),0)/400,0)-1,0),0) -> 0
A34: 정리기간 | E34: 준공 등 | F34: 10억원 미만 | G34: 15 | H34: =IF('1. 기본정보'!$C$4<10,"O","X") -> X | I34: =IF(H34="O",G34,0) -> 0
F35: 10억원 이상 | G35: 30 | H35: =IF('1. 기본정보'!$C$4>=10,"O","X") -> O | I35: =IF(H35="O",G35,0) -> 30
A36: 도서벽지 할증 | F36: 등급 '가' 지역 | G36: 60 | H36: =IF('1. 기본정보'!$C$12=F36,"O","X") -> X | I36: =IF(H36="O",G36,0) -> 0
F37: 등급 '나' 지역 | G37: 45 | H37: =IF('1. 기본정보'!$C$12=F37,"O","X") -> X | I37: =IF(H37="O",G37,0) -> 0
F38: 등급 '다' 지역 | G38: 30 | H38: =IF('1. 기본정보'!$C$12=F38,"O","X") -> X | I38: =IF(H38="O",G38,0) -> 0
F39: 등급 '라' 지역 | G39: 15 | H39: =IF('1. 기본정보'!$C$12=F39,"O","X") -> X | I39: =IF(H39="O",G39,0) -> 0
A40: 계 | I40: =SUM(I4:I39) -> 377
...

Sheet (검토3안) 시설물별
B1: [검토3안] 표준공기 산정
B3: 시설물별 공사기간 산정공식
B4: 건축물 유형 | C4: 산정공식 | D4: 변수 정의 | E4: 적용범위 | F4: 산정 결과
B5: 학교 | C5: Y = 129.06 × X^0.2557 | D5: Y = 공사기간(일) X = 총공사비(억원) | E5: 총공사비 200억원 미만 (200억↑ 기타건축물) | F5: =IF(AND('1. 기본정보'!$C$9="학교",'1. 기본정보'!$C$4>=0,'1. 기본정보'!$C$4<200),ROUND(129.06*'1. 기본정보'!$C$4^0.2557,0),"")
B6: 청사 | C6: Y = 155.94 × ln(X) − 82.355 | E6: 500억원 이하 | F6: =IF(AND('1. 기본정보'!$C$9="청사",'1. 기본정보'!$C$4<=500),ROUND(155.94*LN('1. 기본정보'!$C$4)-82.355,0),"") -> 652
B7: 의료시설 | C7: Y = -0.0385X² + 8.9084X + 140.87 | E7: 200억원 이하 | F7: =IF(AND('1. 기본정보'!$C$9="의료시설",'1. 기본정보'!$C$4<=200),ROUND(-0.0385*'1. 기본정보'!$C$4^2+8.9084*'1. 기본정보'!$C$4+140.87,0),"")
B8: 경찰서 | C8: Y = -0.0154X² + 7.9986X + 145.51 | E8: 300억원 이하 | F8: =IF(AND('1. 기본정보'!$C$9="경찰서",'1. 기본정보'!$C$4<=300),ROUND(-0.0154*'1. 기본정보'!$C$4^2+7.9986*'1. 기본정보'!$C$4+145.51,0),"")
B9: 대학·연구시설 | C9: Y = 201.62 × ln(X) − 175.51 | E9: 5억원 이상, 300억원 이하 | F9: =IF(AND('1. 기본정보'!$C$9="대학·연구시설",'1. 기본정보'!$C$4>=5,'1. 기본정보'!$C$4<=300),ROUND(201.62*LN('1. 기본정보'!$C$4)-175.51,0),"")
B10: 공연·전시시설 | C10: Y = -205.7 × ln(X) + 1,375.4 | E10: 5억원 이상, 300억원 이하 | F10: =IF(AND('1. 기본정보'!$C$9="공연·전시시설 (도서관 포함)",'1. 기본정보'!$C$4>=5,'1. 기본정보'!$C$4<=300),ROUND(-205.7*LN('1. 기본정보'!$C$4)+1375.4,0),"")
B11: 기숙사 | C11: Y = -0.0204X² + 6.6742X + 166.51 | E11: 200억원 이하 | F11: =IF(AND('1. 기본정보'!$C$9="기숙사",'1. 기본정보'!$C$4<=200),ROUND(-0.0204*'1. 기본정보'!$C$4^2+6.6742*'1. 기본정보'!$C$4+166.51,0),"")
B12: 공장, 창고 | C12: Y = -0.0271X² + 6.9664X + 146.97 | E12: 200억원 이하 | F12: =IF(AND('1. 기본정보'!$C$9="공장·창고",'1. 기본정보'!$C$4<=200),ROUND(-0.0271*'1. 기본정보'!$C$4^2+6.9664*'1. 기본정보'!$C$4+146.97,0),"")
B13: 체육시설 | C13: Y = 112.19 × X^0.3719 | E13: 300억원 이하 | F13: =IF(AND('1. 기본정보'!$C$9="체육시설",'1. 기본정보'!$C$4<=300),ROUND(112.19*'1. 기본정보'!$C$4^0.3719,0),"")
B14: 소방시설 | C14: Y = -0.0497X² + 10.744X + 114.94 | E14: 200억원 이하 | F14: =IF(AND('1. 기본정보'!$C$9="소방시설",'1. 기본정보'!$C$4<=200),ROUND(-0.0497*'1. 기본정보'!$C$4^2+10.744*'1. 기본정보'!$C$4+114.94,0),"")
B15: 공동주택 | C15: Y = -21.674 + 7.953×G + 116.835×ln(C) | D15: Y = 공사기간(일) C = 총공사비(억원) A = 연면적(100㎡) G = 지상층수(층) B = 지하층수(층) | E15: 10억원 이상 | F15: =IF(AND('1. 기본정보'!$C$9="공동주택",'1. 기본정보'!$C$4>=10),ROUND(-21.674+7.953*$C$21+116.835*LN('1. 기본정보'!$C$4),0),"")
B16: 체육시설 | C16: Y = -278.109 + 189.438×ln(C) | F16: =IF(AND('1. 기본정보'!$C$9="체육시설",'1. 기본정보'!$C$4>=10),ROUND(-278.109+189.438*LN('1. 기본정보'!$C$4),0),"")
B17: 기타 건축물 | C17: Y = -68.550 + 18.192×B + 12.079×G 5.25×ln(A) + 167.632×ln(C) | F17: =IF(AND(OR('1. 기본정보'!$C$9="기타 건축물",AND('1. 기본정보'!$C$9="학교",'1. 기본정보'!$C$4>=200)),'1. 기본정보'!$C$4>=10,$C$20>0,$C$21>0),ROUND(-68.55+18.192*$C$22+12.079*$C$21-5.25*LN($C$20)+167.632*LN('1. 기본정보'!$C$4),0),"")
B18: ※ 산정공식 결과(Y)에는 비작업일수가 포함되어 있으므로 준비기간·정리기간만 추가합니다. (참고1)
B19: 다변수 공식 변수
B20: 연면적 A | C20: ='1. 기본정보'!$C$5/100 -> 36.6946 | D20: 「1. 기본정보」 연면적 ÷ 100 자동작성 (1,000단위)
B21: 지상층수 G | C21: =IFERROR(VALUE(TRIM(MID('1. 기본정보'!$C$6,FIND("/",'1. 기본정보'!$C$6)+1,20))),0) -> 4 | D21: 「1. 기본정보」 규모 → 지상층수 자동작성 (층 단위)
B22: 지하층수 B | C22: =IFERROR(VALUE(TRIM(LEFT('1. 기본정보'!$C$6,FIND("/",'1. 기본정보'!$C$6)-1))),0) -> 0 | D22: 「1. 기본정보」 규모 → 지하층수 자동작성 (층 단위)
B23: ※ 총공사비·연면적·규모는 「1. 기본정보」에서 자동 연동됩니다.
B24: 표준공기 산정방식에 의한 공사기간 산정표
B25: 구분 | C25: 내용 · 근거 | D25: 일수 (일) | E25: 비고
B26: 적용 시설물 유형 | C26: ='1. 기본정보'!C9 -> 청사 | D26: —
B27: 산정공식 결과 (Y) | C27: Y = 공사기간 (비작업일수 포함) | D27: =SUM(F5:F17) -> 652
B28: 준비기간 | C28: 설계도서 검토, 착공준비, 자재·장비 조달 등 | D28: =부록1_준비·정리기간!C5 -> 60 | E28: 「부록1」 연동 · 고시 제7조
B29: 정리기간 | C29: 준공검사 준비, 시설물 인수, 현장정리 등 | D29: =부록1_준비·정리기간!C10 -> 30 | E29: 「부록1」 연동 · 고시 제12조
B30: Y + 준비기간 + 정리기간 | D30: =D27+D28+D29 -> 742 | E30: ="약 "&TEXT(D30/30,"0.0")&"개월" -> 약 24.7개월

Sheet (참고1)_1일작업량
A1: 참고1 공종별 1일 작업량 (건축분야)
A2: '공종별_작업일수' 시트의 공종·세부공종 드롭박스와 1일작업량·단위·근거가 이 표를 참조합니다. 표준값은 단일 작업조(1조) 기준.
A3: 공종그룹 | B3: 세부공종 | C3: 단위 | D3: 1일 작업량 | E3: 작업조건 / 산출근거
A4: 가설공사 | B4: 콘테이너형 가설건축물 설치 | C4: 개 | D4: 8 | E4: 콘테이너 9m×3m, 비계공4·특별2·크레인10t
A5: 가설공사 | B5: 강관지주 설치 | C5: m | D5: 100 | E5: 지주높이3.5m이하 간격2.0m, 비계공3·보통1·굴삭기0.2
A6: 가설공사 | B6: 가설울타리(EGI휀스) 설치 | C6: m | D6: 115 | E6: 높이3.0m이하, 비계공3·보통1
A7: 가설공사 | B7: 강관비계 설치 | C7: ㎡ | D7: 60 | E7: 높이10m이하 쌍줄비계, 비계공3·보통1
A8: 가설공사 | B8: 시스템비계 설치·해체 | C8: ㎡ | D8: 100 | E8: 10m이하, 비계공4·보통1
A9: 가설공사 | B9: 강관동바리 설치·해체(건축) | C9: ㎡ | D9: 100 | E9: 높이3.5m이하, 형틀목공5·보통1
A10: 토공사 | B10: 터파기(굴삭기0.6㎥) | C10: ㎥ | D10: 560 | E10: 모래·보통토 자연상태, 굴삭기0.6㎥ 1대
A11: 토공사 | B11: 터파기(굴삭기1.0㎥·양호) | C11: ㎥ | D11: 950 | E11: 모래·보통토 자연상태, 굴삭기1.0㎥ 1대
A12: 토공사 | B12: 터파기(굴삭기1.0㎥·보통) | C12: ㎥ | D12: 514 | E12: 보통토사, 난이도 보통, 굴삭기1.0㎥ 1대
A13: 토공사 | B13: 터파기(굴삭기1.0㎥·불량) | C13: ㎥ | D13: 380 | E13: 지장물 발생, 굴삭기1.0㎥ 1대
A14: 토공사 | B14: 기초지정(모래지정) | C14: ㎥ | D14: 65 | E14: 굴삭기0.2+플레이트콤팩터, 보통인부1
A15: 기초공사 | B15: 수평지보공(H-Beam) 설치 | C15: 본 | D15: 10 | E15: H=500이하 9~11m, 철골2·용접4·크레인25t
... A102: 철거공사 | B102: 콘크리트구조물 헐기 | C102: ㎥ | D102: 50 | E102: 특별인부2, 보통인부1, 굴착기+압쇄기 1대, 굴착기 1대
A103: 도서할증 | B103: 가'등급 | C103: 1식 | D103: 60
A104: 도서할증 | B104: 나'등급 | C104: 1식 | D104: 45
A105: 도서할증 | B105: 다'등급 | C105: 1식 | D105: 30
A106: 도서할증 | B106: 라'등급 | C106: 1식 | D106: 15
A107: 도서할증 | B107: 해당없음 | C107: - | D107: 0 | E107: 도서지역 할증 미해당 (할증 0%)

Sheet 부록1_준비·정리기간
B1: 부록1 준비기간 및 정리기간 산정 (고시 제7조, 제12조)
B3: 준비기간 (비작업일수 미계상)
B4: 준비기간 내용 | C4: 설계도서 검토, 안전관리계획 승인, 하도급업체 선정, 측량, 가설건물 설치, 주요 자재·장비 조달 등 | E4: 고시 제2조제6호 참조
B5: 준비기간 (일) | C5: 60 | E5: 직접 입력
B6: 산정 근거 메모 | C6: 공연·전시시설 준비기간 적용
B8: 정리기간 (비작업일수 미계상)
B9: 정리기간 내용 | C9: 준공검사 준비, 시설물 인수 행정절차, 청소 등 현장정리 | E9: 고시 제2조제8호 참조
B10: 정리기간 (일) | C10: 30 | E10: 직접 입력
B11: 산정 근거 메모 | C11: 준공 전 1개월 적용 | E11: 참고용
B13: 참고: 건설공사 유형별 준비기간 예시 (2026년 가이드라인)
B14: 공동주택 | C14: 45일 | D14: 고속도로공사 | E14: 180일
B15: 철도공사 | C15: 90일 | D15: 포장공사(신설) | E15: 50일
B16: 포장공사(수선) | C16: 60일 | D16: 공동구공사 | E16: 80일
B17: 상수도공사 | C17: 60일 | D17: 하천공사 | E17: 40일
B18: 항만공사 | C18: 40일 | D18: 강교가설공사 | E18: 90일
B19: PC교량공사 | C19: 70일 | D19: 교량보수공사 | E19: 60일

Sheet 부록2 법정공휴일
B1: 부록2 법정공휴일수 (2026~2040년)
B2: 연도 | C2: 1월 | D2: 2월 | E2: 3월 | F2: 4월 | G2: 5월 | H2: 6월 | I2: 7월 | J2: 8월 | K2: 9월 | L2: 10월 | M2: 11월 | N2: 12월 | O2: 합계
B3: 2026 | C3: 5 | D3: 7 | E3: 6 | F3: 4 | G3: 7 | H3: 5 | I3: 4 | J3: 7 | K3: 7 | L3: 7 | M3: 5 | N3: 5 | O3: =SUM(C3:N3) -> 69
B4: 2027 | C4: 6 | D4: 7 | E4: 5 | F4: 4 | G4: 7 | H4: 4 | I4: 4 | J4: 6 | K4: 7 | L4: 8 | M4: 4 | N4: 6 | O4: =SUM(C4:N4) -> 68
B5: 2028 | C5: 9 | D5: 4 | E5: 5 | F5: 5 | G5: 6 | H5: 5 | I5: 5 | J5: 5 | K5: 4 | L5: 10 | M5: 4 | N5: 6 | O5: =SUM(C5:N5) -> 68
B6: 2029 | C6: 5 | D6: 7 | E6: 5 | F6: 5 | G6: 7 | H6: 5 | I6: 5 | J6: 5 | K6: 8 | L6: 6 | M6: 4 | N6: 6 | O6: =SUM(C6:N6) -> 68
B7: 2030 | C7: 5 | D7: 7 | E7: 6 | F7: 4 | G7: 6 | H7: 6 | I7: 4 | J7: 5 | K7: 8 | L7: 6 | M7: 4 | N7: 6 | O7: =SUM(C7:N7) -> 67
B8: 2031 | C8: 8 | D8: 4 | E8: 7 | F8: 4 | G8: 6 | H8: 6 | I8: 4 | J8: 6 | K8: 5 | L8: 8 | M8: 5 | N8: 5 | O8: =SUM(C8:N8) -> 68
B9: 2032 | C9: 5 | D9: 8 | E9: 5 | F9: 4 | G9: 7 | H9: 4 | I9: 4 | J9: 6 | K9: 7 | L9: 8 | M9: 4 | N9: 6 | O9: =SUM(C9:N9) -> 68
B10: 2033 | C10: 7 | D10: 6 | E10: 5 | F10: 4 | G10: 7 | H10: 5 | I10: 5 | J10: 5 | K10: 7 | L10: 7 | M10: 4 | N10: 5 | O10: =SUM(C10:N10) -> 67
B11: 2034 | C11: 5 | D11: 7 | E11: 5 | F11: 5 | G11: 6 | H11: 5 | I11: 5 | J11: 5 | K11: 7 | L11: 7 | M11: 4 | N11: 6 | O11: =SUM(C11:N11) -> 67
B12: 2035 | C12: 5 | D12: 7 | E12: 5 | F12: 5 | G12: 7 | H12: 5 | I12: 5 | J12: 5 | K12: 8 | L12: 6 | M12: 4 | N12: 6 | O12: =SUM(C12:N12) -> 68
B13: 2036 | C13: 8 | D13: 4 | E13: 7 | F13: 4 | G13: 7 | H13: 6 | I13: 4 | J13: 6 | K13: 4 | L13: 9 | M13: 5 | N13: 5 | O13: =SUM(C13:N13) -> 69
B14: 2037 | C14: 5 | D14: 7 | E14: 6 | F14: 4 | G14: 7 | H14: 5 | I14: 4 | J14: 7 | K14: 7 | L14: 7 | M14: 5 | N14: 5 | O14: =SUM(C14:N14) -> 69
... B17: 2040 | C17: 5 | D17: 7 | E17: 5 | F17: 5 | G17: 7 | H17: 5 | I17: 5 | J17: 5 | K17: 8 | L17: 6 | M17: 4 | N17: 6 | O17: =SUM(C17:N17) -> 68
B18: ※ 「관공서의 공휴일에 관한 규정」에 따른 공휴일·대체공휴일 적용. 선거일 및 정부 수시 지정일 제외
B19: 법정공휴일수 산정 법적 기준
B20: 항목 | D20: 내용 | K20: 근거
B21: 적용 근거 | D21: 「관공서의 공휴일에 관한 규정」에 따른 공휴일 및 대체공휴일을 비작업일수에 포함하여 산정 | K21: 공사기간 산정기준 고시 · 가이드라인 부록1
B22: 공휴일 (제2조) | D22: 일요일, 국경일(3·1절·광복절·개천절·한글날), 1월 1일, 설날·추석 각 3일, 부처님오신날, 어린이날, 현충일, 성탄절 등 | K22: 관공서 공휴일 규정 제2조
B23: 대체공휴일 (제3조) | D23: 3·1절·광복절·개천절·한글날·어린이날·부처님오신날·성탄절이 토·일요일과 겹치거나, 설날·추석이 일요일·다른 공휴일과 겹치면 다음 첫 비공휴일을 대체 지정 | K23: 관공서 공휴일 규정 제3조
B24: 제외 대상 | D24: 공직선거법상 선거일 및 정부가 수시 지정하는 임시공휴일은 산정에서 제외 | K24: 가이드라인
B25: 데이터 기간 | D25: 2026~2035년은 가이드라인 부록1 공식 수치, 2036~2040년은 동일 규정에 따른 산출값 | K25: 가이드라인 부록1 / 관공서 공휴일 규정
B26: 산정 반영 | D26: 법정공휴일수(A)는 기상 비작업일수(B)와 합산 후 중복일수(C)를 차감하여 월별 비작업일수 산정 | K26: 공사기간 산정기준 고시
B27: ※ 출처: 국가법령정보센터 「관공서의 공휴일에 관한 규정」 제2조·제3조, 「공공 건설공사의 공사기간 산정기준」(국토교통부고시 제2024-1021호, 2025.1.6. 시행)

Sheet 부록3 비작업일수
B1: 부록3 비작업일수 산정
B2: 비작업일수 = A(기상) + B(법정공휴일) − C(중복일수) 단, 월별 비작업일수 ≥ 주40시간 근무제 비작업일수(월 8일)
B3: 착수 예정일 | C3: ='1. 기본정보'!C8 -> 46388
B4: 공사기간 (개월) | C4: =ROUND(MIN('2-1. 공사기간 검토결과'!$D$17:$E$17)/30,1) -> 12.6
B5: 공사 지역 | C5: ='1. 기본정보'!C10 -> 전남·광주
B7: 월별 비작업일수 산정표 (철근콘크리트공사 기준 — 기상조건: 동절기·강우·강풍·혹서기 적용)
B8: =YEAR($C$3)&"년" -> 2027년
B9: 구분 | C9: 1월 | D9: 2월 | E9: 3월 | F9: 4월 | G9: 5월 | H9: 6월 | I9: 7월 | J9: 8월 | K9: 9월 | L9: 10월 | M9: 11월 | N9: 12월 | O9: 소계
B10: 법정공휴일(B) | C10: {=IFERROR(INDEX('부록2 법정공휴일'!$C$3:$N$17,MATCH(LEFT($B$8,4)*1,'부록2 법정공휴일'!$B$3:$B$17,0),COLUMN()-2),0)} -> 6 | D10: {=IFERROR(INDEX('부록2 법정공휴일'!$C$3:$N$17,MATCH(LEFT($B$8,4)*1,'부록2 법정공휴일'!$B$3:$B$17,0),COLUMN()-2),0)} -> 7 | E10: {=IFERROR(INDEX('부록2 법정공휴일'!$C$3:$N$17,MATCH(LEFT($B$8,4)*1,'부록2 법정공휴일'!$B$3:$B$17,0),COLUMN()-2),0)} -> 5 | F10: {=IFERROR(INDEX('부록2 법정공휴일'!$C$3:$N$17,MATCH(LEFT($B$8,4)*1,'부록2 법정공휴일'!$B$3:$B$17,0),COLUMN()-2),0)} -> 4 | G10: {=IFERROR(INDEX('부록2 법정공휴일'!$C$3:$N$17,MATCH(LEFT($B$8,4)*1,'부록2 법정공휴일'!$B$3:$B$17,0),COLUMN()-2),0)} -> 7 | H10: {=IFERROR(INDEX('부록2 법정공휴일'!$C$3:$N$17,MATCH(LEFT($B$8,4)*1,'부록2 법정공휴일'!$B$3:$B$17,0),COLUMN()-2),0)} -> 4 | I10: {=IFERROR(INDEX('부록2 법정공휴일'!$C$3:$N$17,MATCH(LEFT($B$8,4)*1,'부록2 법정공휴일'!$B$3:$B$17,0),COLUMN()-2),0)} -> 4 | J10: {=IFERROR(INDEX('부록2 법정공휴일'!$C$3:$N$17,MATCH(LEFT($B$8,4)*1,'부록2 법정공휴일'!$B$3:$B$17,0),COLUMN()-2),0)} -> 6 | ... N10: {=IFERROR(INDEX('부록2 법정공휴일'!$C$3:$N$17,MATCH(LEFT($B$8,4)*1,'부록2 법정공휴일'!$B$3:$B$17,0),COLUMN()-2),0)} -> 6 | O10: =SUM(C10:N10) -> 68
B11: 기상비작업(A) | C11: ='부록4 기상비작업일수 산정'!D$24 -> 2.3 | D11: ='부록4 기상비작업일수 산정'!E$24 -> 1.3 | E11: ='부록4 기상비작업일수 산정'!F$24 -> 0 | F11: ='부록4 기상비작업일수 산정'!G$24 -> 0 | G11: ='부록4 기상비작업일수 산정'!H$24 -> 0 | H11: ='부록4 기상비작업일수 산정'!I$24 -> 0 | I11: ='부록4 기상비작업일수 산정'!J$24 -> 7.5 | J11: ='부록4 기상비작업일수 산정'!K$24 -> 13.8 | ... N11: ='부록4 기상비작업일수 산정'!O$24 -> 1.4 | O11: =SUM(C11:N11) -> 27.5
B12: 중복일수(C) | C12: =ROUND(C10*C11/DAY(EOMONTH(DATE(LEFT($B$8,4)*1,COLUMN()-2,1),0)),0) -> 0 | D12: =ROUND(D10*D11/DAY(EOMONTH(DATE(LEFT($B$8,4)*1,COLUMN()-2,1),0)),0) -> 0 | E12: =ROUND(E10*E11/DAY(EOMONTH(DATE(LEFT($B$8,4)*1,COLUMN()-2,1),0)),0) -> 0 | F12: =ROUND(F10*F11/DAY(EOMONTH(DATE(LEFT($B$8,4)*1,COLUMN()-2,1),0)),0) -> 0 | G12: =ROUND(G10*G11/DAY(EOMONTH(DATE(LEFT($B$8,4)*1,COLUMN()-2,1),0)),0) -> 0 | H12: =ROUND(H10*H11/DAY(EOMONTH(DATE(LEFT($B$8,4)*1,COLUMN()-2,1),0)),0) -> 0 | I12: =ROUND(I10*I11/DAY(EOMONTH(DATE(LEFT($B$8,4)*1,COLUMN()-2,1),0)),0) -> 1 | J12: =ROUND(J10*J11/DAY(EOMONTH(DATE(LEFT($B$8,4)*1,COLUMN()-2,1),0)),0) -> 3 | ... N12: =ROUND(N10*N11/DAY(EOMONTH(DATE(LEFT($B$8,4)*1,COLUMN()-2,1),0)),0) -> 0 | O12: =SUM(C12:N12) -> 4
B13: A+B-C | C13: =C11+C10-C12 -> 8.3 | D13: =D11+D10-D12 -> 8.3 | E13: =E11+E10-E12 -> 5 | F13: =F11+F10-F12 -> 4 | G13: =G11+G10-G12 -> 7 | H13: =H11+H10-H12 -> 4 | I13: =I11+I10-I12 -> 10.5 | J13: =J11+J10-J12 -> 16.8 | ... N13: =N11+N10-N12 -> 7.4 | O13: =SUM(C13:N13) -> 91.5
B14: 주40H 비작업 | C14: 8 | D14: 8 | E14: 8 | F14: 8 | G14: 8 | H14: 8 | I14: 8 | J14: 8 | K14: 8 | L14: 8 | M14: 8 | N14: 8 | O14: 96
B15: 적용일수 | C15: =MAX(C13,C14) -> 8.3 | D15: =MAX(D13,D14) -> 8.3 | E15: =MAX(E13,E14) -> 8 | F15: =MAX(F13,F14) -> 8 | G15: =MAX(G13,G14) -> 8 | H15: =MAX(H13,H14) -> 8 | I15: =MAX(I13,I14) -> 10.5 | J15: =MAX(J13,J14) -> 16.8 | ... N15: =MAX(N13,N14) -> 8 | O15: =SUM(C15:N15) -> 108.1
B16: ="▶ "&(YEAR($C$3)+0)&"년 연간 총 비작업일수 (적용일수 합계)" -> ▶ 2027년 연간 총 비작업일수 (적용일수 합계) | O16: =SUM(C15:N15) -> 108.1
B17: =(YEAR($C$3)+1)&"년" -> 2028년
B18: 구분 | C18: 1월 | D18: 2월 | E18: 3월 | F18: 4월 | G18: 5월 | H18: 6월 | I18: 7월 | J18: 8월 | K18: 9월 | L18: 10월 | M18: 11월 | N18: 12월 | O18: 소계
B19: 법정공휴일(B) | C19: {=IFERROR(INDEX('부록2 법정공휴일'!$C$3:$N$17,MATCH(LEFT($B$17,4)*1,'부록2 법정공휴일'!$B$3:$B$17,0),COLUMN()-2),0)} -> 9 | D19: {=IFERROR(INDEX('부록2 법정공휴일'!$C$3:$N$17,MATCH(LEFT($B$17,4)*1,'부록2 법정공휴일'!$B$3:$B$17,0),COLUMN()-2),0)} -> 4 | E19: {=IFERROR(INDEX('부록2 법정공휴일'!$C$3:$N$17,MATCH(LEFT($B$17,4)*1,'부록2 법정공휴일'!$B$3:$B$17,0),COLUMN()-2),0)} -> 5 | F19: {=IFERROR(INDEX('부록2 법정공휴일'!$C$3:$N$17,MATCH(LEFT($B$17,4)*1,'부록2 법정공휴일'!$B$3:$B$17,0),COLUMN()-2),0)} -> 5 | G19: {=IFERROR(INDEX('부록2 법정공휴일'!$C$3:$N$17,MATCH(LEFT($B$17,4)*1,'부록2 법정공휴일'!$B$3:$B$17,0),COLUMN()-2),0)} -> 6 | H19: {=IFERROR(INDEX('부록2 법정공휴일'!$C$3:$N$17,MATCH(LEFT($B$17,4)*1,'부록2 법정공휴일'!$B$3:$B$17,0),COLUMN()-2),0)} -> 5 | I19: {=IFERROR(INDEX('부록2 법정공휴일'!$C$3:$N$17,MATCH(LEFT($B$17,4)*1,'부록2 법정공휴일'!$B$3:$B$17,0),COLUMN()-2),0)} -> 5 | J19: {=IFERROR(INDEX('부록2 법정공휴일'!$C$3:$N$17,MATCH(LEFT($B$17,4)*1,'부록2 법정공휴일'!$B$3:$B$17,0),COLUMN()-2),0)} -> 5 | ... N19: {=IFERROR(INDEX('부록2 법정공휴일'!$C$3:$N$17,MATCH(LEFT($B$17,4)*1,'부록2 법정공휴일'!$B$3:$B$17,0),COLUMN()-2),0)} -> 6 | O19: =SUM(C19:N19) -> 68
B20: 기상비작업(A) | C20: ='부록4 기상비작업일수 산정'!D$24 -> 2.3 | D20: ='부록4 기상비작업일수 산정'!E$24 -> 1.3 | E20: ='부록4 기상비작업일수 산정'!F$24 -> 0 | F20: ='부록4 기상비작업일수 산정'!G$24 -> 0 | G20: ='부록4 기상비작업일수 산정'!H$24 -> 0 | H20: ='부록4 기상비작업일수 산정'!I$24 -> 0 | I20: ='부록4 기상비작업일수 산정'!J$24 -> 7.5 | J20: ='부록4 기상비작업일수 산정'!K$24 -> 13.8 | ... N20: ='부록4 기상비작업일수 산정'!O$24 -> 1.4 | O20: =SUM(C20:N20) -> 27.5
